Workbook
Name \a: Model!$A$1
Name \b: Model!$D$15
Name \p: Model!$A$1:$N$60
Name Print_Area_MI: Model!$A$1:$N$111
Name wrn.Model: Model!$A$1:$N$343
Name wrn.Summary: 'Summary_to delete'!$B$3:$K$32
Name Kestrel_EBITDA: Model!$E$85
Name Kestrel_Rev: Model!$E$75
Name Osprey_Rev: 'Summary_to delete'!$C$6:$K$6
Name Osprey_EBITDA: 'Summary_to delete'!$C$10:$K$10
Name TEV: Assump_CapStructure!$D$72
Name EqPP: Assump_CapStructure!$D$80
Name MinCash: Assump_CapStructure!$F$19
Name TaxRate: Assump_CapStructure!$F$23
Name SweepPct: Assump_CapStructure!$F$18
Name Case_Op: Assump_CapStructure!$K$5
Name Case_Fin: Assump_CapStructure!$K$15
Name IS_Rev: Model!$B$75:$M$75
Name IS_EBITDA: Model!$B$85:$M$85
Name IS_NI: Model!$F$110:$M$110
Name BS_Check: Model!$B$156:$M$156
Name CF_Cash: Model!$F$209:$M$209
Name Debt_Total: Model!$E$62:$M$62
Name Pfd_End: 'Debt Schedules'!$F$103:$M$103
Name IRR_Common: Model!$D$242:$H$242
Name IRR_Strip: Model!$D$282:$H$282
Name MoIC_Common: Model!$D$243:$H$243
Name Rollover: Model!$K$17
Name SponsorEq: Model!$K$20
Name TotalEq: Model!$E$331
Name Goodwill: Model!$D$325
Name NWC: Model!$B$306:$M$306
Name Capex_Row: Model!$B$35:$M$35
Name DA_Row: Model!$B$88:$M$88
Name Hist_Rev: Model!$B$75:$E$75
Name Proj_Rev: Model!$F$75:$M$75
Name FYE_Label: Assump_CapStructure!$F$9
Name Units: Assump_CapStructure!$F$11
Name Exit_Mults: Model!$D$214:$H$214
Name ExitEBITDA: Model!$D$213
Name Osprey_IRR: 'Summary_to delete'!$C$22

Sheet Notes
A1: =Assump_CapStructure!$F$7 -> Project Kestrel
B5: Model Notes
B7: ="(1) Equity amounts reflect the upsized sponsor equity ticket of $"&TEXT(Model!$K$18+Model!$K$19,"#,##0")&"k (90% preferred / 10% common) plus seller rollover." -> (1) Equity amounts reflect the upsized sponsor equity ticket of $14,239k (90% preferred / 10% common) plus seller rollover.
B8: ="(2) Debt amounts reflect full draw of the $"&TEXT(Model!$K$8,"#,##0")&"k term loan A at close; the $8.0M revolver is undrawn at close." -> (2) Debt amounts reflect full draw of the $23,607k term loan A at close; the $8.0M revolver is undrawn at close.
B9: (3) FY2026E reflects management estimates from the LOI; FY2026E is treated as a full year of ownership (closing 31-Jul-2026 stub period ignored).
B10: (4) Closing balance sheet reflects balances as of 31-Jul-2026 (sponsor estimate) adjusted for the transaction.
B11: (5) Although the Company is structured as a flow-through entity, taxes are reflected at 26% for conservatism ("No Taxes" operating cases switch the rate off).
B12: (6) Reflects 50% excess cash flow sweep (switch on Assump_CapStructure); sweep applied to revolver, then term loans, then mezzanine, then the seller note.
B13: (7) Equity returns are net of the 10% Management Equity Incentive Program (MEIP), which participates in common profits only.
B14: (8) Interest and preferred accretion are computed on beginning-of-period balances to avoid circular references (no iteration required).
B15: (9) Returns exhibits hold the entry multiple fixed (per tab) and vary the exit multiple; net debt at exit is the base-case net debt from the Model tab.
B16: (10) Preferred equity accretion is a memo item for returns and is not booked on the projected balance sheet; intangible assets are held flat pending PPA.
B17: (11) Sources and Uses-DETAIL / -SUMMARY carry a stale LTM 7/31/26 EBITDA input used only for the "x LTM EBITDA" column.
B20: Prepared by: Halvern Capital Partners - for internal discussion purposes only. All figures illustrative.

Sheet Sources and Uses-Live
A1: =Assump_CapStructure!$F$7 -> Project Kestrel
A2: ="Prepared by: "&Assump_CapStructure!$F$8 -> Prepared by: Halvern
A3: =Assump_CapStructure!$F$11 -> ($ in 000s)
B5: Transaction Summary
B6: =Assump_CapStructure!$F$11 -> ($ in 000s)
B8: Total Enterprise Value | E8: =Assump_CapStructure!$D$72 -> 55083 | I8: =E8/Model!$E$85 -> 7 | J8: x FY2025A Adj. EBITDA
B9: Investor Entry Multiple (FY2025A) | E9: =Assump_CapStructure!$D$73 -> 7
B10: Investor Entry Multiple (FY2026E) | E10: =Assump_CapStructure!$D$74 -> 6.2977588
B11: Operating Case: | E11: =CHOOSE(Assump_CapStructure!$K$5,"Management Case","Case II - No Growth, No Taxes","Case III - Downside Case, No Taxes","Upside Case","Flat Case") -> Management Case
B12: Financing Case: | E12: =CHOOSE(Assump_CapStructure!$K$15,"Base Case - Senior + Mezz","Senior Only","Senior + Seller Note Upsized","All Equity","Unitranche","Case 6","Case 7","Case 8","Case 9","Case 10") -> Base Case - Senior + Mezz | I12: NO | J12: Revolver drawn at close?
B13: Step Up in Basis | E13: =IF(Assump_CapStructure!$F$22=1,"Yes","No") -> Yes
B14: Rollover % of Proceeds | E14: =Model!$K$17/Assump_CapStructure!$D$80 -> 0.1834509
B15: Exit: | E15: 5 Years
B17: (1) Fixed Charge Coverage = (EBITDA - Mgmt Fee - Capex - Cash Taxes) / (Scheduled Principal + Cash Interest).
B19: Sources and Uses of Funds ($ in 000's)
B20: Uses | E20: Amount | F20: % of Total | G20: x FY2026E EBITDA | I20: Sources | L20: Amount | M20: % of Total | N20: x EBITDA | O20: Pricing
B21: Cash Consideration | E21: =Model!$D$7-Model!$K$13 -> 35472.8 | F21: =E21/$E$28 -> 0.60551354 | G21: =E21/Model!$F$85 -> 4.0556821 | I21: Revolver (undrawn) (1) | L21: =Model!$K$7 -> 0 | M21: =L21/$L$28 -> 0 | N21: =L21/Model!$F$85 -> 0 | O21: ="Base + "&TEXT(Assump_CapStructure!$U$36,"0.00%") -> Base + 3.00%
B22: Repay Existing Debt | E22: =Model!$D$8 -> 6842 | F22: =E22/$E$28 -> 0.11679156 | G22: =E22/Model!$F$85 -> 0.7822607 | I22: Term Loan A (2) | L22: =Model!$K$8 -> 23607 | M22: =L22/$L$28 -> 0.40296673 | N22: =L22/Model!$F$85 -> 2.6990395 | O22: ="Base + "&TEXT(Assump_CapStructure!$U$37,"0.00%") -> Base + 3.25%
B23: Seller Note | E23: =Model!$K$13 -> 4000 | F23: =E23/$E$28 -> 0.068279194 | G23: =E23/Model!$F$85 -> 0.45732867 | I23: Mezzanine Debt | L23: =Model!$K$12 -> 7869 | M23: =L23/$L$28 -> 0.13432224 | N23: =L23/Model!$F$85 -> 0.89967983 | O23: =TEXT(Assump_CapStructure!$U$41,"0.00%")&" cash + "&TEXT(Assump_CapStructure!$V$41,"0.00%")&" PIK" -> 11.00% cash + 2.00% PIK
B24: Rollover Equity | E24: =Model!$K$17 -> 8868.2 | F24: =E24/$E$28 -> 0.15137839 | G24: =E24/Model!$F$85 -> 1.0139205 | I24: Seller Note | L24: =Model!$K$13 -> 4000 | M24: =L24/$L$28 -> 0.068279194 | N24: =L24/Model!$F$85 -> 0.45732867 | O24: =TEXT(Assump_CapStructure!$V$42,"0.00%")&" PIK" -> 6.00% PIK
B25: Purchase Price | E25: =SUM(E21:E24) -> 55183 | F25: =E25/$E$28 -> 0.94196269 | G25: =E25/Model!$F$85 -> 6.3091921 | I25: Rollover Equity | L25: =Model!$K$17 -> 8868.2 | M25: =L25/$L$28 -> 0.15137839 | N25: =L25/Model!$F$85 -> 1.0139205
B26: Cash on Balance Sheet at Close | E26: =Model!$D$13 -> 1000 | F26: =E26/$E$28 -> 0.017069798 | G26: =E26/Model!$F$85 -> 0.11433217 | I26: Sponsor Preferred Equity (3)(4) | L26: =Model!$K$18 -> 12814.92 | M26: =L26/$L$28 -> 0.2187481 | N26: =L26/Model!$F$85 -> 1.4651576 | O26: =TEXT(Assump_CapStructure!$F$28,"0.00%")&" accreting" -> 8.00% accreting
B27: Transaction Costs / Excess Cash | E27: =Model!$D$14 -> 2400 | F27: =E27/$E$28 -> 0.040967516 | G27: =E27/Model!$F$85 -> 0.2743972 | I27: Sponsor Common Equity (3)(4) | L27: =Model!$K$19 -> 1423.88 | M27: =L27/$L$28 -> 0.024305345 | N27: =L27/Model!$F$85 -> 0.16279529
B28: Total Uses | E28: =E25+SUM(E26:E27) -> 58583 | F28: =E28/$E$28 -> 1 | G28: =E28/Model!$F$85 -> 6.6979214 | I28: Total Sources | L28: =SUM(L21:L27) -> 58583 | M28: =SUM(M21:M27) -> 1 | N28: =L28/Model!$F$85 -> 6.6979214
B30: Check: Total Sources - Total Uses (must be 0) | E30: =L28-E28 -> 0
B32: (1) $8.0M revolving credit facility, undrawn at close; commitment fee on the unused portion.
B33: ="(2) Senior leverage of "&TEXT(Model!$M$8,"0.0x")&" FY2025A Adj. EBITDA; full draw of the term loan A at close." -> (2) Senior leverage of 3.0x FY2025A Adj. EBITDA; full draw of the term loan A at close.
B34: (3) Sponsor equity is 90% preferred (8% accreting) / 10% common; common is subject to 10% MEIP dilution.
B35: (4) Sponsor equity may be syndicated to a co-investor consortium; Halvern retains control.

Sheet Live Sheet
A1: =Assump_CapStructure!$F$7 -> Project Kestrel
A2: ="Prepared by: "&Assump_CapStructure!$F$8 -> Prepared by: Halvern
A3: =Assump_CapStructure!$F$11 -> ($ in 000s)
B5: Transaction Summary
B6: =Assump_CapStructure!$F$11 -> ($ in 000s)
B8: Total Enterprise Value | E8: =Assump_CapStructure!$D$72 -> 55083 | I8: =E8/Model!$E$85 -> 7 | J8: x FY2025A Adj. EBITDA
B9: Investor Entry Multiple (FY2025A) | E9: =Assump_CapStructure!$D$73 -> 7
B10: Investor Entry Multiple (FY2026E) | E10: =Assump_CapStructure!$D$74 -> 6.2977588
B11: Operating Case: | E11: =CHOOSE(Assump_CapStructure!$K$5,"Management Case","Case II - No Growth, No Taxes","Case III - Downside Case, No Taxes","Upside Case","Flat Case") -> Management Case
B12: Financing Case: | E12: =CHOOSE(Assump_CapStructure!$K$15,"Base Case - Senior + Mezz","Senior Only","Senior + Seller Note Upsized","All Equity","Unitranche","Case 6","Case 7","Case 8","Case 9","Case 10") -> Base Case - Senior + Mezz | I12: NO | J12: Revolver drawn at close?
B13: Step Up in Basis | E13: =IF(Assump_CapStructure!$F$22=1,"Yes","No") -> Yes
B14: Rollover % of Proceeds | E14: =Model!$K$17/Assump_CapStructure!$D$80 -> 0.1834509
B15: Exit: | E15: 5 Years
B17: (1) Fixed Charge Coverage = (EBITDA - Mgmt Fee - Capex - Cash Taxes) / (Scheduled Principal + Cash Interest).
B19: Sources and Uses of Funds ($ in 000's)
B20: Uses | E20: Amount | F20: % of Total | G20: x FY2026E EBITDA | I20: Sources | L20: Amount | M20: % of Total | N20: x EBITDA | O20: Pricing
B21: Cash Consideration | E21: =Model!$D$7-Model!$K$13 -> 35472.8 | F21: =E21/$E$28 -> 0.60551354 | G21: =E21/Model!$F$85 -> 4.0556821 | I21: Revolver (undrawn) (1) | L21: =Model!$K$7 -> 0 | M21: =L21/$L$28 -> 0 | N21: =L21/Model!$F$85 -> 0 | O21: ="Base + "&TEXT(Assump_CapStructure!$U$36,"0.00%") -> Base + 3.00%
B22: Repay Existing Debt | E22: =Model!$D$8 -> 6842 | F22: =E22/$E$28 -> 0.11679156 | G22: =E22/Model!$F$85 -> 0.7822607 | I22: Term Loan A (2) | L22: =Model!$K$8 -> 23607 | M22: =L22/$L$28 -> 0.40296673 | N22: =L22/Model!$F$85 -> 2.6990395 | O22: ="Base + "&TEXT(Assump_CapStructure!$U$37,"0.00%") -> Base + 3.25%
B23: Seller Note | E23: =Model!$K$13 -> 4000 | F23: =E23/$E$28 -> 0.068279194 | G23: =E23/Model!$F$85 -> 0.45732867 | I23: Mezzanine Debt | L23: =Model!$K$12 -> 7869 | M23: =L23/$L$28 -> 0.13432224 | N23: =L23/Model!$F$85 -> 0.89967983 | O23: =TEXT(Assump_CapStructure!$U$41,"0.00%")&" cash + "&TEXT(Assump_CapStructure!$V$41,"0.00%")&" PIK" -> 11.00% cash + 2.00% PIK
B24: Rollover Equity | E24: =Model!$K$17 -> 8868.2 | F24: =E24/$E$28 -> 0.15137839 | G24: =E24/Model!$F$85 -> 1.0139205 | I24: Seller Note | L24: =Model!$K$13 -> 4000 | M24: =L24/$L$28 -> 0.068279194 | N24: =L24/Model!$F$85 -> 0.45732867 | O24: =TEXT(Assump_CapStructure!$V$42,"0.00%")&" PIK" -> 6.00% PIK
B25: Purchase Price | E25: =SUM(E21:E24) -> 55183 | F25: =E25/$E$28 -> 0.94196269 | G25: =E25/Model!$F$85 -> 6.3091921 | I25: Rollover Equity | L25: =Model!$K$17 -> 8868.2 | M25: =L25/$L$28 -> 0.15137839 | N25: =L25/Model!$F$85 -> 1.0139205
B26: Cash on Balance Sheet at Close | E26: =Model!$D$13 -> 1000 | F26: =E26/$E$28 -> 0.017069798 | G26: =E26/Model!$F$85 -> 0.11433217 | I26: Sponsor Preferred Equity (3)(4) | L26: =Model!$K$18 -> 12814.92 | M26: =L26/$L$28 -> 0.2187481 | N26: =L26/Model!$F$85 -> 1.4651576 | O26: =TEXT(Assump_CapStructure!$F$28,"0.00%")&" accreting" -> 8.00% accreting
B27: Transaction Costs / Excess Cash | E27: =Model!$D$14 -> 2400 | F27: =E27/$E$28 -> 0.040967516 | G27: =E27/Model!$F$85 -> 0.2743972 | I27: Sponsor Common Equity (3)(4) | L27: =Model!$K$19 -> 1423.88 | M27: =L27/$L$28 -> 0.024305345 | N27: =L27/Model!$F$85 -> 0.16279529
B28: Total Uses | E28: =E25+SUM(E26:E27) -> 58583 | F28: =E28/$E$28 -> 1 | G28: =E28/Model!$F$85 -> 6.6979214 | I28: Total Sources | L28: =SUM(L21:L27) -> 58583 | M28: =SUM(M21:M27) -> 1 | N28: =L28/Model!$F$85 -> 6.6979214
B30: Check: Total Sources - Total Uses (must be 0) | E30: =L28-E28 -> 0
B32: Illustrative Five Year Gross Return Profile - IRR and Multiple of Invested Capital
B34: Returns Inputs (linked to Model / Assump_CapStructure)
B35: FY2025A Adj. EBITDA | E35: =Model!$E$85 -> 7869
B36: FY2030E EBITDA (exit year 5) | E36: =Model!$J$85 -> 11754.676
B37: FY2028E EBITDA (exit year 3) | E37: =Model!$H$85 -> 10300.977
B38: Debt raised at close (base case, fixed) | E38: =Model!$K$16 -> 35476
B39: Transaction costs + cash to B/S + cash acquired | E39: =Model!$D$14+Model!$D$13+Assump_CapStructure!$D$79 -> 3500
B40: Net debt at FY2030E (excl. seller note; from Model) | E40: =Model!$J$62-Model!$J$61-Model!$J$51 -> 3755.4841
B41: Seller note accreted balance at FY2030E | E41: =Model!$J$61 -> 5352.9023
B42: Net debt at FY2028E (excl. seller note; from Model) | E42: =Model!$H$62-Model!$H$61-Model!$H$51 -> 16536.503
B43: Seller note accreted balance at FY2028E | E43: =Model!$H$61 -> 4764.064
B44: Cumulative goodwill step-up tax savings through FY2028E | E44: =Model!$H$328 -> 2074.696
B45: Preferred % of equity account | E45: =Assump_CapStructure!$F$31 -> 0.9
B46: Preferred accretion rate | E46: =Assump_CapStructure!$F$28 -> 0.08
B47: MEIP % of common profits | E47: =Assump_CapStructure!$F$29 -> 0.1
...

Sheet Returns  Exhibit-7.5x
A1: =Assump_CapStructure!$F$7 -> Project Kestrel
A2: ="Prepared by: "&Assump_CapStructure!$F$8 -> Prepared by: Halvern
A3: =Assump_CapStructure!$F$11 -> ($ in 000s)
B5: ="Deal Overview and Returns Summary @ "&TEXT($E$7,"0.0x")&" Entry Multiple" -> Deal Overview and Returns Summary @ 7.5x Entry Multiple
B7: Entry Multiple (x FY2025A Adj. EBITDA) | E7: 7.5
B9: Returns Inputs (linked to Model / Assump_CapStructure)
B10: FY2025A Adj. EBITDA | E10: =Model!$E$85 -> 7869
B11: FY2030E EBITDA (exit year 5) | E11: =Model!$J$85 -> 11754.676
B12: FY2028E EBITDA (exit year 3) | E12: =Model!$H$85 -> 10300.977
B13: Debt raised at close (base case, fixed) | E13: =Model!$K$16 -> 35476
B14: Transaction costs + cash to B/S + cash acquired | E14: =Model!$D$14+Model!$D$13+Assump_CapStructure!$D$79 -> 3500
B15: Net debt at FY2030E (excl. seller note; from Model) | E15: =Model!$J$62-Model!$J$61-Model!$J$51 -> 3755.4841
B16: Seller note accreted balance at FY2030E | E16: =Model!$J$61 -> 5352.9023
B17: Net debt at FY2028E (excl. seller note; from Model) | E17: =Model!$H$62-Model!$H$61-Model!$H$51 -> 16536.503
B18: Seller note accreted balance at FY2028E | E18: =Model!$H$61 -> 4764.064
B19: Cumulative goodwill step-up tax savings through FY2028E | E19: =Model!$H$328 -> 2074.696
B20: Preferred % of equity account | E20: =Assump_CapStructure!$F$31 -> 0.9
B21: Preferred accretion rate | E21: =Assump_CapStructure!$F$28 -> 0.08
B22: MEIP % of common profits | E22: =Assump_CapStructure!$F$29 -> 0.1
B23: Sponsor carried interest | E23: =Assump_CapStructure!$F$30 -> 0.2
B25: Purchase Price (Transaction Value) | E25: =$E$7*$E$10 -> 59017.5
B26: Total Equity at Entry (Sponsor + Rollover) | E26: =E25+$E$14-$E$13 -> 27041.5
B27: Preferred Accreted at Exit (year 5) | E27: =E26*$E$20*(1+$E$21)^5 -> 35759.552
B28: Common Equity Invested | E28: =E26*(1-$E$20) -> 2704.15
B30: Five-Year Gross Return Profile (Sponsor + Rollover strip, net of MEIP) (1)
C31: Rev. CAGR | D31: Exit multiple ->
B32: Exit-year EBITDA by case | D32: 6 | E32: 6.5 | F32: 7 | G32: 7.5 | H32: 8
B33: 15% Rev CAGR Case | C33: 0.15 | D33: Exit EBITDA: | E33: =$E$10*(1+C33)^5 -> 15827.37
B34: IRR | D34: =IF(D35<=0,-1,D35^(1/5)-1) -> 0.24570673 | E34: =IF(E35<=0,-1,E35^(1/5)-1) -> 0.26685204 | F34: =IF(F35<=0,-1,F35^(1/5)-1) -> 0.28667313 | G34: =IF(G35<=0,-1,G35^(1/5)-1) -> 0.30534314 | H34: =IF(H35<=0,-1,H35^(1/5)-1) -> 0.32300236
B35: MoIC | D35: =IF($E$26<=0,0,((D$32*$E33-$E$15-$E$16)-$E$22*MAX(0,(D$32*$E33-$E$15-$E$16)-MIN((D$32*$E33-$E$15-$E$16),$E$27)-$E$28))/$E$26) -> 2.9997086 | E35: =IF($E$26<=0,0,((E$32*$E33-$E$15-$E$16)-$E$22*MAX(0,(E$32*$E33-$E$15-$E$16)-MIN((E$32*$E33-$E$15-$E$16),$E$27)-$E$28))/$E$26) -> 3.2630932 | F35: =IF($E$26<=0,0,((F$32*$E33-$E$15-$E$16)-$E$22*MAX(0,(F$32*$E33-$E$15-$E$16)-MIN((F$32*$E33-$E$15-$E$16),$E$27)-$E$28))/$E$26) -> 3.5264779 | G35: =IF($E$26<=0,0,((G$32*$E33-$E$15-$E$16)-$E$22*MAX(0,(G$32*$E33-$E$15-$E$16)-MIN((G$32*$E33-$E$15-$E$16),$E$27)-$E$28))/$E$26) -> 3.7898625 | H35: =IF($E$26<=0,0,((H$32*$E33-$E$15-$E$16)-$E$22*MAX(0,(H$32*$E33-$E$15-$E$16)-MIN((H$32*$E33-$E$15-$E$16),$E$27)-$E$28))/$E$26) -> 4.0532472
B37: 10% Rev CAGR Case | C37: 0.1 | D37: Exit EBITDA: | E37: =$E$10*(1+C37)^5 -> 12673.103
B38: IRR | D38: =IF(D39<=0,-1,D39^(1/5)-1) -> 0.18834679 | E38: =IF(E39<=0,-1,E39^(1/5)-1) -> 0.20878232 | F38: =IF(F39<=0,-1,F39^(1/5)-1) -> 0.22792264 | G38: =IF(G39<=0,-1,G39^(1/5)-1) -> 0.245939 | H38: =IF(H39<=0,-1,H39^(1/5)-1) -> 0.2629698
B39: MoIC | D39: =IF($E$26<=0,0,((D$32*$E37-$E$15-$E$16)-$E$22*MAX(0,(D$32*$E37-$E$15-$E$16)-MIN((D$32*$E37-$E$15-$E$16),$E$27)-$E$28))/$E$26) -> 2.3698234 | E39: =IF($E$26<=0,0,((E$32*$E37-$E$15-$E$16)-$E$22*MAX(0,(E$32*$E37-$E$15-$E$16)-MIN((E$32*$E37-$E$15-$E$16),$E$27)-$E$28))/$E$26) -> 2.5807176 | F39: =IF($E$26<=0,0,((F$32*$E37-$E$15-$E$16)-$E$22*MAX(0,(F$32*$E37-$E$15-$E$16)-MIN((F$32*$E37-$E$15-$E$16),$E$27)-$E$28))/$E$26) -> 2.7916119 | G39: =IF($E$26<=0,0,((G$32*$E37-$E$15-$E$16)-$E$22*MAX(0,(G$32*$E37-$E$15-$E$16)-MIN((G$32*$E37-$E$15-$E$16),$E$27)-$E$28))/$E$26) -> 3.0025061 | H39: =IF($E$26<=0,0,((H$32*$E37-$E$15-$E$16)-$E$22*MAX(0,(H$32*$E37-$E$15-$E$16)-MIN((H$32*$E37-$E$15-$E$16),$E$27)-$E$28))/$E$26) -> 3.2134003
B41: 5% Rev CAGR Case | C41: 0.05 | D41: Exit EBITDA: | E41: =$E$10*(1+C41)^5 -> 10043.06
B42: IRR | D42: =IF(D43<=0,-1,D43^(1/5)-1) -> 0.13026811 | E42: =IF(E43<=0,-1,E43^(1/5)-1) -> 0.15004485 | F42: =IF(F43<=0,-1,F43^(1/5)-1) -> 0.16854795 | G42: =IF(G43<=0,-1,G43^(1/5)-1) -> 0.18594831 | H42: =IF(H43<=0,-1,H43^(1/5)-1) -> 0.20238362
B43: MoIC | D43: =IF($E$26<=0,0,((D$32*$E41-$E$15-$E$16)-$E$22*MAX(0,(D$32*$E41-$E$15-$E$16)-MIN((D$32*$E41-$E$15-$E$16),$E$27)-$E$28))/$E$26) -> 1.8446219 | E43: =IF($E$26<=0,0,((E$32*$E41-$E$15-$E$16)-$E$22*MAX(0,(E$32*$E41-$E$15-$E$16)-MIN((E$32*$E41-$E$15-$E$16),$E$27)-$E$28))/$E$26) -> 2.0117494 | F43: =IF($E$26<=0,0,((F$32*$E41-$E$15-$E$16)-$E$22*MAX(0,(F$32*$E41-$E$15-$E$16)-MIN((F$32*$E41-$E$15-$E$16),$E$27)-$E$28))/$E$26) -> 2.1788768 | G43: =IF($E$26<=0,0,((G$32*$E41-$E$15-$E$16)-$E$22*MAX(0,(G$32*$E41-$E$15-$E$16)-MIN((G$32*$E41-$E$15-$E$16),$E$27)-$E$28))/$E$26) -> 2.3460043 | H43: =IF($E$26<=0,0,((H$32*$E41-$E$15-$E$16)-$E$22*MAX(0,(H$32*$E41-$E$15-$E$16)-MIN((H$32*$E41-$E$15-$E$16),$E$27)-$E$28))/$E$26) -> 2.5131317
B45: Flat Rev CAGR Case | C45: 0 | D45: Exit EBITDA: | E45: =$E$10*(1+C45)^5 -> 7869
B46: IRR | D46: =IF(D47<=0,-1,D47^(1/5)-1) -> 0.07100534 | E46: =IF(E47<=0,-1,E47^(1/5)-1) -> 0.090396726 | F46: =IF(F47<=0,-1,F47^(1/5)-1) -> 0.10832396 | G46: =IF(G47<=0,-1,G47^(1/5)-1) -> 0.12516115 | H46: =IF(H47<=0,-1,H47^(1/5)-1) -> 0.14104696
B47: MoIC | D47: =IF($E$26<=0,0,((D$32*$E45-$E$15-$E$16)-$E$22*MAX(0,(D$32*$E45-$E$15-$E$16)-MIN((D$32*$E45-$E$15-$E$16),$E$27)-$E$28))/$E$26) -> 1.4091531 | E47: =IF($E$26<=0,0,((E$32*$E45-$E$15-$E$16)-$E$22*MAX(0,(E$32*$E45-$E$15-$E$16)-MIN((E$32*$E45-$E$15-$E$16),$E$27)-$E$28))/$E$26) -> 1.541426 | F47: =IF($E$26<=0,0,((F$32*$E45-$E$15-$E$16)-$E$22*MAX(0,(F$32*$E45-$E$15-$E$16)-MIN((F$32*$E45-$E$15-$E$16),$E$27)-$E$28))/$E$26) -> 1.6723748 | G47: =IF($E$26<=0,0,((G$32*$E45-$E$15-$E$16)-$E$22*MAX(0,(G$32*$E45-$E$15-$E$16)-MIN((G$32*$E45-$E$15-$E$16),$E$27)-$E$28))/$E$26) -> 1.8033235 | H47: =IF($E$26<=0,0,((H$32*$E45-$E$15-$E$16)-$E$22*MAX(0,(H$32*$E45-$E$15-$E$16)-MIN((H$32*$E45-$E$15-$E$16),$E$27)-$E$28))/$E$26) -> 1.9342722
B49: Management Case | C49: =($E$11/$E$10)^(1/5)-1 -> 0.083573126 | D49: Exit EBITDA: | E49: =$E$11 -> 11754.676
...

Sheet Returns  Exhibit-6.5x
A1: =Assump_CapStructure!$F$7 -> Project Kestrel
A2: ="Prepared by: "&Assump_CapStructure!$F$8 -> Prepared by: Halvern
A3: =Assump_CapStructure!$F$11 -> ($ in 000s)
B5: ="Deal Overview and Returns Summary @ "&TEXT($E$7,"0.0x")&" Entry Multiple" -> Deal Overview and Returns Summary @ 6.5x Entry Multiple
B7: Entry Multiple (x FY2025A Adj. EBITDA) | E7: 6.5
B9: Returns Inputs (linked to Model / Assump_CapStructure)
B10: FY2025A Adj. EBITDA | E10: =Model!$E$85 -> 7869
B11: FY2030E EBITDA (exit year 5) | E11: =Model!$J$85 -> 11754.676
B12: FY2028E EBITDA (exit year 3) | E12: =Model!$H$85 -> 10300.977
B13: Debt raised at close (base case, fixed) | E13: =Model!$K$16 -> 35476
B14: Transaction costs + cash to B/S + cash acquired | E14: =Model!$D$14+Model!$D$13+Assump_CapStructure!$D$79 -> 3500
B15: Net debt at FY2030E (excl. seller note; from Model) | E15: =Model!$J$62-Model!$J$61-Model!$J$51 -> 3755.4841
B16: Seller note accreted balance at FY2030E | E16: =Model!$J$61 -> 5352.9023
B17: Net debt at FY2028E (excl. seller note; from Model) | E17: =Model!$H$62-Model!$H$61-Model!$H$51 -> 16536.503
B18: Seller note accreted balance at FY2028E | E18: =Model!$H$61 -> 4764.064
B19: Cumulative goodwill step-up tax savings through FY2028E | E19: =Model!$H$328 -> 2074.696
B20: Preferred % of equity account | E20: =Assump_CapStructure!$F$31 -> 0.9
B21: Preferred accretion rate | E21: =Assump_CapStructure!$F$28 -> 0.08
B22: MEIP % of common profits | E22: =Assump_CapStructure!$F$29 -> 0.1
B23: Sponsor carried interest | E23: =Assump_CapStructure!$F$30 -> 0.2
B25: Purchase Price (Transaction Value) | E25: =$E$7*$E$10 -> 51148.5
B26: Total Equity at Entry (Sponsor + Rollover) | E26: =E25+$E$14-$E$13 -> 19172.5
B27: Preferred Accreted at Exit (year 5) | E27: =E26*$E$20*(1+$E$21)^5 -> 25353.623
B28: Common Equity Invested | E28: =E26*(1-$E$20) -> 1917.25
B30: Five-Year Gross Return Profile (Sponsor + Rollover strip, net of MEIP) (1)
C31: Rev. CAGR | D31: Exit multiple ->
B32: Exit-year EBITDA by case | D32: 6 | E32: 6.5 | F32: 7 | G32: 7.5 | H32: 8
B33: 15% Rev CAGR Case | C33: 0.15 | D33: Exit EBITDA: | E33: =$E$10*(1+C33)^5 -> 15827.37
B34: IRR | D34: =IF(D35<=0,-1,D35^(1/5)-1) -> 0.33069755 | E34: =IF(E35<=0,-1,E35^(1/5)-1) -> 0.35359106 | F34: =IF(F35<=0,-1,F35^(1/5)-1) -> 0.375033 | G34: =IF(G35<=0,-1,G35^(1/5)-1) -> 0.39521534 | H34: =IF(H35<=0,-1,H35^(1/5)-1) -> 0.41429326
B35: MoIC | D35: =IF($E$26<=0,0,((D$32*$E33-$E$15-$E$16)-$E$22*MAX(0,(D$32*$E33-$E$15-$E$16)-MIN((D$32*$E33-$E$15-$E$16),$E$27)-$E$28))/$E$26) -> 4.1725042 | E35: =IF($E$26<=0,0,((E$32*$E33-$E$15-$E$16)-$E$22*MAX(0,(E$32*$E33-$E$15-$E$16)-MIN((E$32*$E33-$E$15-$E$16),$E$27)-$E$28))/$E$26) -> 4.5439902 | F35: =IF($E$26<=0,0,((F$32*$E33-$E$15-$E$16)-$E$22*MAX(0,(F$32*$E33-$E$15-$E$16)-MIN((F$32*$E33-$E$15-$E$16),$E$27)-$E$28))/$E$26) -> 4.9154763 | G35: =IF($E$26<=0,0,((G$32*$E33-$E$15-$E$16)-$E$22*MAX(0,(G$32*$E33-$E$15-$E$16)-MIN((G$32*$E33-$E$15-$E$16),$E$27)-$E$28))/$E$26) -> 5.2869623 | H35: =IF($E$26<=0,0,((H$32*$E33-$E$15-$E$16)-$E$22*MAX(0,(H$32*$E33-$E$15-$E$16)-MIN((H$32*$E33-$E$15-$E$16),$E$27)-$E$28))/$E$26) -> 5.6584484
B37: 10% Rev CAGR Case | C37: 0.1 | D37: Exit EBITDA: | E37: =$E$10*(1+C37)^5 -> 12673.103
B38: IRR | D38: =IF(D39<=0,-1,D39^(1/5)-1) -> 0.26847853 | E38: =IF(E39<=0,-1,E39^(1/5)-1) -> 0.29066671 | F38: =IF(F39<=0,-1,F39^(1/5)-1) -> 0.31142637 | G38: =IF(G39<=0,-1,G39^(1/5)-1) -> 0.33094913 | H38: =IF(H39<=0,-1,H39^(1/5)-1) -> 0.34938939
B39: MoIC | D39: =IF($E$26<=0,0,((D$32*$E37-$E$15-$E$16)-$E$22*MAX(0,(D$32*$E37-$E$15-$E$16)-MIN((D$32*$E37-$E$15-$E$16),$E$27)-$E$28))/$E$26) -> 3.2840942 | E39: =IF($E$26<=0,0,((E$32*$E37-$E$15-$E$16)-$E$22*MAX(0,(E$32*$E37-$E$15-$E$16)-MIN((E$32*$E37-$E$15-$E$16),$E$27)-$E$28))/$E$26) -> 3.5815461 | F39: =IF($E$26<=0,0,((F$32*$E37-$E$15-$E$16)-$E$22*MAX(0,(F$32*$E37-$E$15-$E$16)-MIN((F$32*$E37-$E$15-$E$16),$E$27)-$E$28))/$E$26) -> 3.878998 | G39: =IF($E$26<=0,0,((G$32*$E37-$E$15-$E$16)-$E$22*MAX(0,(G$32*$E37-$E$15-$E$16)-MIN((G$32*$E37-$E$15-$E$16),$E$27)-$E$28))/$E$26) -> 4.1764499 | H39: =IF($E$26<=0,0,((H$32*$E37-$E$15-$E$16)-$E$22*MAX(0,(H$32*$E37-$E$15-$E$16)-MIN((H$32*$E37-$E$15-$E$16),$E$27)-$E$28))/$E$26) -> 4.4739018
B41: 5% Rev CAGR Case | C41: 0.05 | D41: Exit EBITDA: | E41: =$E$10*(1+C41)^5 -> 10043.06
B42: IRR | D42: =IF(D43<=0,-1,D43^(1/5)-1) -> 0.20525977 | E42: =IF(E43<=0,-1,E43^(1/5)-1) -> 0.22681602 | F42: =IF(F43<=0,-1,F43^(1/5)-1) -> 0.24695575 | G42: =IF(G43<=0,-1,G43^(1/5)-1) -> 0.26587262 | H42: =IF(H43<=0,-1,H43^(1/5)-1) -> 0.28372198
B43: MoIC | D43: =IF($E$26<=0,0,((D$32*$E41-$E$15-$E$16)-$E$22*MAX(0,(D$32*$E41-$E$15-$E$16)-MIN((D$32*$E41-$E$15-$E$16),$E$27)-$E$28))/$E$26) -> 2.5433335 | E43: =IF($E$26<=0,0,((E$32*$E41-$E$15-$E$16)-$E$22*MAX(0,(E$32*$E41-$E$15-$E$16)-MIN((E$32*$E41-$E$15-$E$16),$E$27)-$E$28))/$E$26) -> 2.7790553 | F43: =IF($E$26<=0,0,((F$32*$E41-$E$15-$E$16)-$E$22*MAX(0,(F$32*$E41-$E$15-$E$16)-MIN((F$32*$E41-$E$15-$E$16),$E$27)-$E$28))/$E$26) -> 3.0147772 | G43: =IF($E$26<=0,0,((G$32*$E41-$E$15-$E$16)-$E$22*MAX(0,(G$32*$E41-$E$15-$E$16)-MIN((G$32*$E41-$E$15-$E$16),$E$27)-$E$28))/$E$26) -> 3.250499 | H43: =IF($E$26<=0,0,((H$32*$E41-$E$15-$E$16)-$E$22*MAX(0,(H$32*$E41-$E$15-$E$16)-MIN((H$32*$E41-$E$15-$E$16),$E$27)-$E$28))/$E$26) -> 3.4862208
B45: Flat Rev CAGR Case | C45: 0 | D45: Exit EBITDA: | E45: =$E$10*(1+C45)^5 -> 7869
B46: IRR | D46: =IF(D47<=0,-1,D47^(1/5)-1) -> 0.1406609 | E46: =IF(E47<=0,-1,E47^(1/5)-1) -> 0.16169112 | F46: =IF(F47<=0,-1,F47^(1/5)-1) -> 0.18130031 | G46: =IF(G47<=0,-1,G47^(1/5)-1) -> 0.19968781 | H46: =IF(H47<=0,-1,H47^(1/5)-1) -> 0.21701257
B47: MoIC | D47: =IF($E$26<=0,0,((D$32*$E45-$E$15-$E$16)-$E$22*MAX(0,(D$32*$E45-$E$15-$E$16)-MIN((D$32*$E45-$E$15-$E$16),$E$27)-$E$28))/$E$26) -> 1.9310022 | E47: =IF($E$26<=0,0,((E$32*$E45-$E$15-$E$16)-$E$22*MAX(0,(E$32*$E45-$E$15-$E$16)-MIN((E$32*$E45-$E$15-$E$16),$E$27)-$E$28))/$E$26) -> 2.1156964 | F47: =IF($E$26<=0,0,((F$32*$E45-$E$15-$E$16)-$E$22*MAX(0,(F$32*$E45-$E$15-$E$16)-MIN((F$32*$E45-$E$15-$E$16),$E$27)-$E$28))/$E$26) -> 2.3003906 | G47: =IF($E$26<=0,0,((G$32*$E45-$E$15-$E$16)-$E$22*MAX(0,(G$32*$E45-$E$15-$E$16)-MIN((G$32*$E45-$E$15-$E$16),$E$27)-$E$28))/$E$26) -> 2.4850849 | H47: =IF($E$26<=0,0,((H$32*$E45-$E$15-$E$16)-$E$22*MAX(0,(H$32*$E45-$E$15-$E$16)-MIN((H$32*$E45-$E$15-$E$16),$E$27)-$E$28))/$E$26) -> 2.6697791
B49: Management Case | C49: =($E$11/$E$10)^(1/5)-1 -> 0.083573126 | D49: Exit EBITDA: | E49: =$E$11 -> 11754.676
...

Sheet Returns  Exhibit-8.5x
A1: =Assump_CapStructure!$F$7 -> Project Kestrel
A2: ="Prepared by: "&Assump_CapStructure!$F$8 -> Prepared by: Halvern
A3: =Assump_CapStructure!$F$11 -> ($ in 000s)
B5: ="Deal Overview and Returns Summary @ "&TEXT($E$7,"0.0x")&" Entry Multiple" -> Deal Overview and Returns Summary @ 8.5x Entry Multiple
B7: Entry Multiple (x FY2025A Adj. EBITDA) | E7: 8.5
B9: Returns Inputs (linked to Model / Assump_CapStructure)
B10: FY2025A Adj. EBITDA | E10: =Model!$E$85 -> 7869
B11: FY2030E EBITDA (exit year 5) | E11: =Model!$J$85 -> 11754.676
B12: FY2028E EBITDA (exit year 3) | E12: =Model!$H$85 -> 10300.977
B13: Debt raised at close (base case, fixed) | E13: =Model!$K$16 -> 35476
B14: Transaction costs + cash to B/S + cash acquired | E14: =Model!$D$14+Model!$D$13+Assump_CapStructure!$D$79 -> 3500
B15: Net debt at FY2030E (excl. seller note; from Model) | E15: =Model!$J$62-Model!$J$61-Model!$J$51 -> 3755.4841
B16: Seller note accreted balance at FY2030E | E16: =Model!$J$61 -> 5352.9023
B17: Net debt at FY2028E (excl. seller note; from Model) | E17: =Model!$H$62-Model!$H$61-Model!$H$51 -> 16536.503
B18: Seller note accreted balance at FY2028E | E18: =Model!$H$61 -> 4764.064
B19: Cumulative goodwill step-up tax savings through FY2028E | E19: =Model!$H$328 -> 2074.696
B20: Preferred % of equity account | E20: =Assump_CapStructure!$F$31 -> 0.9
B21: Preferred accretion rate | E21: =Assump_CapStructure!$F$28 -> 0.08
B22: MEIP % of common profits | E22: =Assump_CapStructure!$F$29 -> 0.1
B23: Sponsor carried interest | E23: =Assump_CapStructure!$F$30 -> 0.2
B25: Purchase Price (Transaction Value) | E25: =$E$7*$E$10 -> 66886.5
B26: Total Equity at Entry (Sponsor + Rollover) | E26: =E25+$E$14-$E$13 -> 34910.5
B27: Preferred Accreted at Exit (year 5) | E27: =E26*$E$20*(1+$E$21)^5 -> 46165.48
B28: Common Equity Invested | E28: =E26*(1-$E$20) -> 3491.05
B30: Five-Year Gross Return Profile (Sponsor + Rollover strip, net of MEIP) (1)
C31: Rev. CAGR | D31: Exit multiple ->
B32: Exit-year EBITDA by case | D32: 6 | E32: 6.5 | F32: 7 | G32: 7.5 | H32: 8
B33: 15% Rev CAGR Case | C33: 0.15 | D33: Exit EBITDA: | E33: =$E$10*(1+C33)^5 -> 15827.37
B34: IRR | D34: =IF(D35<=0,-1,D35^(1/5)-1) -> 0.18691899 | E34: =IF(E35<=0,-1,E35^(1/5)-1) -> 0.20680107 | F34: =IF(F35<=0,-1,F35^(1/5)-1) -> 0.22545319 | G34: =IF(G35<=0,-1,G35^(1/5)-1) -> 0.24303434 | H34: =IF(H35<=0,-1,H35^(1/5)-1) -> 0.25967368
B35: MoIC | D35: =IF($E$26<=0,0,((D$32*$E33-$E$15-$E$16)-$E$22*MAX(0,(D$32*$E33-$E$15-$E$16)-MIN((D$32*$E33-$E$15-$E$16),$E$27)-$E$28))/$E$26) -> 2.3556209 | E35: =IF($E$26<=0,0,((E$32*$E33-$E$15-$E$16)-$E$22*MAX(0,(E$32*$E33-$E$15-$E$16)-MIN((E$32*$E33-$E$15-$E$16),$E$27)-$E$28))/$E$26) -> 2.5596373 | F35: =IF($E$26<=0,0,((F$32*$E33-$E$15-$E$16)-$E$22*MAX(0,(F$32*$E33-$E$15-$E$16)-MIN((F$32*$E33-$E$15-$E$16),$E$27)-$E$28))/$E$26) -> 2.7636538 | G35: =IF($E$26<=0,0,((G$32*$E33-$E$15-$E$16)-$E$22*MAX(0,(G$32*$E33-$E$15-$E$16)-MIN((G$32*$E33-$E$15-$E$16),$E$27)-$E$28))/$E$26) -> 2.9676702 | H35: =IF($E$26<=0,0,((H$32*$E33-$E$15-$E$16)-$E$22*MAX(0,(H$32*$E33-$E$15-$E$16)-MIN((H$32*$E33-$E$15-$E$16),$E$27)-$E$28))/$E$26) -> 3.1716867
B37: 10% Rev CAGR Case | C37: 0.1 | D37: Exit EBITDA: | E37: =$E$10*(1+C37)^5 -> 12673.103
B38: IRR | D38: =IF(D39<=0,-1,D39^(1/5)-1) -> 0.13308403 | E38: =IF(E39<=0,-1,E39^(1/5)-1) -> 0.15224568 | F38: =IF(F39<=0,-1,F39^(1/5)-1) -> 0.17021148 | G38: =IF(G39<=0,-1,G39^(1/5)-1) -> 0.18713728 | H38: =IF(H39<=0,-1,H39^(1/5)-1) -> 0.20314946
B39: MoIC | D39: =IF($E$26<=0,0,((D$32*$E37-$E$15-$E$16)-$E$22*MAX(0,(D$32*$E37-$E$15-$E$16)-MIN((D$32*$E37-$E$15-$E$16),$E$27)-$E$28))/$E$26) -> 1.8677149 | E39: =IF($E$26<=0,0,((E$32*$E37-$E$15-$E$16)-$E$22*MAX(0,(E$32*$E37-$E$15-$E$16)-MIN((E$32*$E37-$E$15-$E$16),$E$27)-$E$28))/$E$26) -> 2.0310726 | F39: =IF($E$26<=0,0,((F$32*$E37-$E$15-$E$16)-$E$22*MAX(0,(F$32*$E37-$E$15-$E$16)-MIN((F$32*$E37-$E$15-$E$16),$E$27)-$E$28))/$E$26) -> 2.1944302 | G39: =IF($E$26<=0,0,((G$32*$E37-$E$15-$E$16)-$E$22*MAX(0,(G$32*$E37-$E$15-$E$16)-MIN((G$32*$E37-$E$15-$E$16),$E$27)-$E$28))/$E$26) -> 2.3577878 | H39: =IF($E$26<=0,0,((H$32*$E37-$E$15-$E$16)-$E$22*MAX(0,(H$32*$E37-$E$15-$E$16)-MIN((H$32*$E37-$E$15-$E$16),$E$27)-$E$28))/$E$26) -> 2.5211455
B41: 5% Rev CAGR Case | C41: 0.05 | D41: Exit EBITDA: | E41: =$E$10*(1+C41)^5 -> 10043.06
B42: IRR | D42: =IF(D43<=0,-1,D43^(1/5)-1) -> 0.078757653 | E42: =IF(E43<=0,-1,E43^(1/5)-1) -> 0.097232553 | F42: =IF(F43<=0,-1,F43^(1/5)-1) -> 0.11454094 | G42: =IF(G43<=0,-1,G43^(1/5)-1) -> 0.1308365 | H42: =IF(H43<=0,-1,H43^(1/5)-1) -> 0.14624355
B43: MoIC | D43: =IF($E$26<=0,0,((D$32*$E41-$E$15-$E$16)-$E$22*MAX(0,(D$32*$E41-$E$15-$E$16)-MIN((D$32*$E41-$E$15-$E$16),$E$27)-$E$28))/$E$26) -> 1.4608965 | E43: =IF($E$26<=0,0,((E$32*$E41-$E$15-$E$16)-$E$22*MAX(0,(E$32*$E41-$E$15-$E$16)-MIN((E$32*$E41-$E$15-$E$16),$E$27)-$E$28))/$E$26) -> 1.5903526 | F43: =IF($E$26<=0,0,((F$32*$E41-$E$15-$E$16)-$E$22*MAX(0,(F$32*$E41-$E$15-$E$16)-MIN((F$32*$E41-$E$15-$E$16),$E$27)-$E$28))/$E$26) -> 1.7198087 | G43: =IF($E$26<=0,0,((G$32*$E41-$E$15-$E$16)-$E$22*MAX(0,(G$32*$E41-$E$15-$E$16)-MIN((G$32*$E41-$E$15-$E$16),$E$27)-$E$28))/$E$26) -> 1.8492648 | H43: =IF($E$26<=0,0,((H$32*$E41-$E$15-$E$16)-$E$22*MAX(0,(H$32*$E41-$E$15-$E$16)-MIN((H$32*$E41-$E$15-$E$16),$E$27)-$E$28))/$E$26) -> 1.9787209
B45: Flat Rev CAGR Case | C45: 0 | D45: Exit EBITDA: | E45: =$E$10*(1+C45)^5 -> 7869
B46: IRR | D46: =IF(D47<=0,-1,D47^(1/5)-1) -> 0.017669077 | E46: =IF(E47<=0,-1,E47^(1/5)-1) -> 0.037866663 | F46: =IF(F47<=0,-1,F47^(1/5)-1) -> 0.056604373 | G46: =IF(G47<=0,-1,G47^(1/5)-1) -> 0.073991362 | H46: =IF(H47<=0,-1,H47^(1/5)-1) -> 0.088823632
B47: MoIC | D47: =IF($E$26<=0,0,((D$32*$E45-$E$15-$E$16)-$E$22*MAX(0,(D$32*$E45-$E$15-$E$16)-MIN((D$32*$E45-$E$15-$E$16),$E$27)-$E$28))/$E$26) -> 1.091523 | E47: =IF($E$26<=0,0,((E$32*$E45-$E$15-$E$16)-$E$22*MAX(0,(E$32*$E45-$E$15-$E$16)-MIN((E$32*$E45-$E$15-$E$16),$E$27)-$E$28))/$E$26) -> 1.2042255 | F47: =IF($E$26<=0,0,((F$32*$E45-$E$15-$E$16)-$E$22*MAX(0,(F$32*$E45-$E$15-$E$16)-MIN((F$32*$E45-$E$15-$E$16),$E$27)-$E$28))/$E$26) -> 1.316928 | G47: =IF($E$26<=0,0,((G$32*$E45-$E$15-$E$16)-$E$22*MAX(0,(G$32*$E45-$E$15-$E$16)-MIN((G$32*$E45-$E$15-$E$16),$E$27)-$E$28))/$E$26) -> 1.4289069 | H47: =IF($E$26<=0,0,((H$32*$E45-$E$15-$E$16)-$E$22*MAX(0,(H$32*$E45-$E$15-$E$16)-MIN((H$32*$E45-$E$15-$E$16),$E$27)-$E$28))/$E$26) -> 1.5303392
B49: Management Case | C49: =($E$11/$E$10)^(1/5)-1 -> 0.083573126 | D49: Exit EBITDA: | E49: =$E$11 -> 11754.676
...

Sheet Sources and Uses-DETAIL
A1: =Assump_CapStructure!$F$7 -> Project Kestrel
A2: ="Prepared by: "&Assump_CapStructure!$F$8 -> Prepared by: Halvern
A3: =Assump_CapStructure!$F$11 -> ($ in 000s)
B5: Transaction Summary
B6: =Assump_CapStructure!$F$11 -> ($ in 000s)
B8: Total Enterprise Value | E8: =Assump_CapStructure!$D$72 -> 55083 | I8: =E8/Model!$E$85 -> 7 | J8: x FY2025A Adj. EBITDA
B9: Investor Entry Multiple (FY2025A) | E9: =Assump_CapStructure!$D$73 -> 7
B10: Investor Entry Multiple (FY2026E) | E10: =Assump_CapStructure!$D$74 -> 6.2977588
B11: Operating Case: | E11: =CHOOSE(Assump_CapStructure!$K$5,"Management Case","Case II - No Growth, No Taxes","Case III - Downside Case, No Taxes","Upside Case","Flat Case") -> Management Case
B12: Financing Case: | E12: =CHOOSE(Assump_CapStructure!$K$15,"Base Case - Senior + Mezz","Senior Only","Senior + Seller Note Upsized","All Equity","Unitranche","Case 6","Case 7","Case 8","Case 9","Case 10") -> Base Case - Senior + Mezz | I12: NO | J12: Revolver drawn at close?
B13: Step Up in Basis | E13: =IF(Assump_CapStructure!$F$22=1,"Yes","No") -> Yes
B14: Rollover % of Proceeds | E14: =Model!$K$17/Assump_CapStructure!$D$80 -> 0.1834509
B15: Exit: | E15: 5 Years
B17: (1) Fixed Charge Coverage = (EBITDA - Mgmt Fee - Capex - Cash Taxes) / (Scheduled Principal + Cash Interest).
B19: LTM 7/31/26 Estimated Adj. EBITDA (per QoE; for x LTM column) | E19: 8214
B21: Sources and Uses of Funds ($ in 000's) - FINAL FOR CLOSING | U21: LOI vs. Final
B22: Uses | E22: Amount | F22: % of Total | G22: x LTM EBITDA | I22: Sources | L22: Amount | M22: % of Total | N22: x LTM EBITDA | O22: Pricing | W22: LOI | X22: Final | Y22: Delta | Z22: % chg
B23: Cash Consideration (incl. payoff of existing debt) | E23: =Consideration!$H$22+Model!$D$8 -> 42314.8 | F23: =E23/$E$29 -> 0.72230511 | G23: =E23/$E$19 -> 5.1515461 | I23: Revolver (undrawn) (2) | L23: =Model!$K$7 -> 0 | M23: =L23/$L$29 -> 0 | N23: =L23/$E$19 -> 0 | O23: ="Base + "&TEXT(Assump_CapStructure!$U$36,"0.00%") -> Base + 3.00% | U23: Cash Consideration | W23: 40125 | X23: =E23 -> 42314.8 | Y23: =X23-W23 -> 2189.8 | Z23: =IF(W23=0,0,X23/W23-1) -> 0.054574455
B24: Seller Note | E24: =Model!$K$13 -> 4000 | F24: =E24/$E$29 -> 0.068279194 | G24: =E24/$E$19 -> 0.48697346 | I24: Term Loan A (3) | L24: =Model!$K$8 -> 23607 | M24: =L24/$L$29 -> 0.40296673 | N24: =L24/$E$19 -> 2.8739956 | O24: ="Base + "&TEXT(Assump_CapStructure!$U$37,"0.00%") -> Base + 3.25% | U24: Seller Note | W24: 4000 | X24: =E24 -> 4000 | Y24: =X24-W24 -> 0 | Z24: =IF(W24=0,0,X24/W24-1) -> 0
B25: Rollover Equity | E25: =Model!$K$17 -> 8868.2 | F25: =E25/$E$29 -> 0.15137839 | G25: =E25/$E$19 -> 1.0796445 | I25: Mezzanine Debt | L25: =Model!$K$12 -> 7869 | M25: =L25/$L$29 -> 0.13432224 | N25: =L25/$E$19 -> 0.95799854 | O25: =TEXT(Assump_CapStructure!$U$41,"0.00%")&" cash + "&TEXT(Assump_CapStructure!$V$41,"0.00%")&" PIK" -> 11.00% cash + 2.00% PIK | U25: Rollover Equity | W25: 8650 | X25: =E25 -> 8868.2 | Y25: =X25-W25 -> 218.2 | Z25: =IF(W25=0,0,X25/W25-1) -> 0.025225434
B26: Purchase Price | E26: =SUM(E23:E25) -> 55183 | F26: =E26/$E$29 -> 0.94196269 | G26: =E26/$E$19 -> 6.7181641 | I26: Seller Note | L26: =Model!$K$13 -> 4000 | M26: =L26/$L$29 -> 0.068279194 | N26: =L26/$E$19 -> 0.48697346 | O26: =TEXT(Assump_CapStructure!$V$42,"0.00%")&" PIK" -> 6.00% PIK | U26: Transaction Costs | W26: 2150 | X26: =E27 -> 2400 | Y26: =X26-W26 -> 250 | Z26: =IF(W26=0,0,X26/W26-1) -> 0.11627907
B27: Transaction Costs (1) | E27: =Model!$D$14 -> 2400 | F27: =E27/$E$29 -> 0.040967516 | G27: =E27/$E$19 -> 0.29218408 | I27: Rollover Equity | L27: =Model!$K$17 -> 8868.2 | M27: =L27/$L$29 -> 0.15137839 | N27: =L27/$E$19 -> 1.0796445 | U27: Cash on Balance Sheet | W27: 750 | X27: =E28 -> 1000 | Y27: =X27-W27 -> 250 | Z27: =IF(W27=0,0,X27/W27-1) -> 0.33333333
B28: Cash on Balance Sheet at Close (6) | E28: =Model!$D$13 -> 1000 | F28: =E28/$E$29 -> 0.017069798 | G28: =E28/$E$19 -> 0.12174336 | I28: Sponsor Equity (5) | L28: =Model!$K$18+Model!$K$19 -> 14238.8 | M28: =L28/$L$29 -> 0.24305345 | N28: =L28/$E$19 -> 1.7334794 | U28: Total Uses | W28: =SUM(W23:W27) -> 55675 | X28: =E29 -> 58583 | Y28: =X28-W28 -> 2908 | Z28: =IF(W28=0,0,X28/W28-1) -> 0.052231702
B29: Total Uses | E29: =E26+SUM(E27:E28) -> 58583 | F29: =E29/$E$29 -> 1 | G29: =E29/$E$19 -> 7.1320916 | I29: Total Sources | L29: =SUM(L23:L28) -> 58583 | M29: =SUM(M23:M28) -> 1 | N29: =L29/$E$19 -> 7.1320916
B31: Check: Total Sources - Total Uses (must be 0) | E31: =L29-E29 -> 0
B32: ="LTM EBITDA is 7/31/26 estimated adjusted EBITDA of $"&TEXT($E$19,"#,##0")&"k." -> LTM EBITDA is 7/31/26 estimated adjusted EBITDA of $8,214k.
B34: (1) Purchaser fees and expenses including the bank / M&A fee, legal, accounting and diligence, and financing fees.
B35: (2) $8.0M revolver, undrawn at close.
B36: (3) Reflects full draw of the term loan A at close.
B37: (4) Sponsor common equity subject to 10% MEIP dilution.
B38: (5) Reflects upsized sponsor equity ticket and seller rollover of 20% of consideration ex seller note.
B39: (6) Excess cash left in the business for liquidity (minimum cash $1.0M).
B41: Uses of Excess Cash from Closing:
B42: Incremental transaction cost estimate vs LOI | E42: =Model!$D$14-M26 -> 2399.9317
B43: Excess cash for liquidity | E43: =Model!$D$13 -> 1000
B44: Investment available for an add-on acquisition | E44: 0
B45: Total (incl. $100k cash left by seller) | E45: =SUM(E42:E44)+Assump_CapStructure!$D$79 -> 3499.9317

Sheet Sources and Uses-SUMMARY
A1: =Assump_CapStructure!$F$7 -> Project Kestrel
A2: ="Prepared by: "&Assump_CapStructure!$F$8 -> Prepared by: Halvern
A3: =Assump_CapStructure!$F$11 -> ($ in 000s)
B5: Transaction Summary
B6: =Assump_CapStructure!$F$11 -> ($ in 000s)
B8: Total Enterprise Value | E8: =Assump_CapStructure!$D$72 -> 55083 | I8: =E8/Model!$E$85 -> 7 | J8: x FY2025A Adj. EBITDA
B9: Investor Entry Multiple (FY2025A) | E9: =Assump_CapStructure!$D$73 -> 7
B10: Investor Entry Multiple (FY2026E) | E10: =Assump_CapStructure!$D$74 -> 6.2977588
B11: Operating Case: | E11: =CHOOSE(Assump_CapStructure!$K$5,"Management Case","Case II - No Growth, No Taxes","Case III - Downside Case, No Taxes","Upside Case","Flat Case") -> Management Case
B12: Financing Case: | E12: =CHOOSE(Assump_CapStructure!$K$15,"Base Case - Senior + Mezz","Senior Only","Senior + Seller Note Upsized","All Equity","Unitranche","Case 6","Case 7","Case 8","Case 9","Case 10") -> Base Case - Senior + Mezz | I12: NO | J12: Revolver drawn at close?
B13: Step Up in Basis | E13: =IF(Assump_CapStructure!$F$22=1,"Yes","No") -> Yes
B14: Rollover % of Proceeds | E14: =Model!$K$17/Assump_CapStructure!$D$80 -> 0.1834509
B15: Exit: | E15: 5 Years
B17: (1) Fixed Charge Coverage = (EBITDA - Mgmt Fee - Capex - Cash Taxes) / (Scheduled Principal + Cash Interest).
B19: LTM 7/31/26 Estimated Adj. EBITDA (per QoE; for x LTM column) | E19: 8214
B21: Sources and Uses of Funds ($ in 000's) - FINAL FOR CLOSING | U21: LOI vs. Final
B22: Uses | E22: Amount | F22: % of Total | G22: x LTM EBITDA | I22: Sources | L22: Amount | M22: % of Total | N22: x LTM EBITDA | O22: Pricing | W22: LOI | X22: Final | Y22: Delta | Z22: % chg
B23: Cash Consideration (incl. payoff of existing debt) | E23: =Consideration!$H$22+Model!$D$8 -> 42314.8 | F23: =E23/$E$29 -> 0.72230511 | G23: =E23/$E$19 -> 5.1515461 | I23: Revolver (undrawn) (2) | L23: =Model!$K$7 -> 0 | M23: =L23/$L$29 -> 0 | N23: =L23/$E$19 -> 0 | O23: ="Base + "&TEXT(Assump_CapStructure!$U$36,"0.00%") -> Base + 3.00% | U23: Cash Consideration | W23: 40125 | X23: =E23 -> 42314.8 | Y23: =X23-W23 -> 2189.8 | Z23: =IF(W23=0,0,X23/W23-1) -> 0.054574455
B24: Seller Note | E24: =Model!$K$13 -> 4000 | F24: =E24/$E$29 -> 0.068279194 | G24: =E24/$E$19 -> 0.48697346 | I24: Term Loan A (3) | L24: =Model!$K$8 -> 23607 | M24: =L24/$L$29 -> 0.40296673 | N24: =L24/$E$19 -> 2.8739956 | O24: ="Base + "&TEXT(Assump_CapStructure!$U$37,"0.00%") -> Base + 3.25% | U24: Seller Note | W24: 4000 | X24: =E24 -> 4000 | Y24: =X24-W24 -> 0 | Z24: =IF(W24=0,0,X24/W24-1) -> 0
B25: Rollover Equity | E25: =Model!$K$17 -> 8868.2 | F25: =E25/$E$29 -> 0.15137839 | G25: =E25/$E$19 -> 1.0796445 | I25: Mezzanine Debt | L25: =Model!$K$12 -> 7869 | M25: =L25/$L$29 -> 0.13432224 | N25: =L25/$E$19 -> 0.95799854 | O25: =TEXT(Assump_CapStructure!$U$41,"0.00%")&" cash + "&TEXT(Assump_CapStructure!$V$41,"0.00%")&" PIK" -> 11.00% cash + 2.00% PIK | U25: Rollover Equity | W25: 8650 | X25: =E25 -> 8868.2 | Y25: =X25-W25 -> 218.2 | Z25: =IF(W25=0,0,X25/W25-1) -> 0.025225434
B26: Purchase Price | E26: =SUM(E23:E25) -> 55183 | F26: =E26/$E$29 -> 0.94196269 | G26: =E26/$E$19 -> 6.7181641 | I26: Seller Note | L26: =Model!$K$13 -> 4000 | M26: =L26/$L$29 -> 0.068279194 | N26: =L26/$E$19 -> 0.48697346 | O26: =TEXT(Assump_CapStructure!$V$42,"0.00%")&" PIK" -> 6.00% PIK | U26: Transaction Costs | W26: 2150 | X26: =E27 -> 2400 | Y26: =X26-W26 -> 250 | Z26: =IF(W26=0,0,X26/W26-1) -> 0.11627907
B27: Transaction Costs (1) | E27: =Model!$D$14 -> 2400 | F27: =E27/$E$29 -> 0.040967516 | G27: =E27/$E$19 -> 0.29218408 | I27: Rollover Equity | L27: =Model!$K$17 -> 8868.2 | M27: =L27/$L$29 -> 0.15137839 | N27: =L27/$E$19 -> 1.0796445 | U27: Cash on Balance Sheet | W27: 750 | X27: =E28 -> 1000 | Y27: =X27-W27 -> 250 | Z27: =IF(W27=0,0,X27/W27-1) -> 0.33333333
B28: Cash on Balance Sheet at Close (6) | E28: =Model!$D$13 -> 1000 | F28: =E28/$E$29 -> 0.017069798 | G28: =E28/$E$19 -> 0.12174336 | I28: Sponsor Equity (5) | L28: =Model!$K$18+Model!$K$19 -> 14238.8 | M28: =L28/$L$29 -> 0.24305345 | N28: =L28/$E$19 -> 1.7334794 | U28: Total Uses | W28: =SUM(W23:W27) -> 55675 | X28: =E29 -> 58583 | Y28: =X28-W28 -> 2908 | Z28: =IF(W28=0,0,X28/W28-1) -> 0.052231702
B29: Total Uses | E29: =E26+SUM(E27:E28) -> 58583 | F29: =E29/$E$29 -> 1 | G29: =E29/$E$19 -> 7.1320916 | I29: Total Sources | L29: =SUM(L23:L28) -> 58583 | M29: =SUM(M23:M28) -> 1 | N29: =L29/$E$19 -> 7.1320916
B31: Check: Total Sources - Total Uses (must be 0) | E31: =L29-E29 -> 0
B32: ="LTM EBITDA is 7/31/26 estimated adjusted EBITDA of $"&TEXT($E$19,"#,##0")&"k." -> LTM EBITDA is 7/31/26 estimated adjusted EBITDA of $8,214k.
B34: (1) Purchaser fees and expenses including the bank / M&A fee, legal, accounting and diligence, and financing fees.
B35: (2) $8.0M revolver, undrawn at close.
B36: (3) Reflects full draw of the term loan A at close.
B37: (4) Sponsor common equity subject to 10% MEIP dilution.
B38: (5) Reflects upsized sponsor equity ticket and seller rollover of 20% of consideration ex seller note.
B39: (6) Excess cash left in the business for liquidity (minimum cash $1.0M).
B41: Total Uses | E41: =E29 -> 58583
B42: LOI Total Uses | E42: =W28 -> 55675
B43: % change vs LOI | E43: =E41/E42-1 -> 0.052231702

Sheet Consideration
A1: =Assump_CapStructure!$F$7 -> Project Kestrel
A2: ="Prepared by: "&Assump_CapStructure!$F$8 -> Prepared by: Halvern
A3: =Assump_CapStructure!$F$11 -> ($ in 000s)
B5: Consideration Summary
B6: Consideration to Seller - Updated for Overcapitalization / Purchase Price
C7: Thomas | D7: Gregory | E7: Anne | H7: Total | M7: Accreted @ 8% / 5 yrs
C8: Marlbeck | D8: Marlbeck | E8: Marlbeck-Holt
B10: Current Ownership % | C10: 0.55 | D10: 0.3 | E10: 0.15 | H10: =SUM(C10:E10) -> 1
B11: Consideration ex Seller Note (1) | C11: =C10*$H$11 -> 24387.55 | D11: =D10*$H$11 -> 13302.3 | E11: =E10*$H$11 -> 6651.15 | H11: =Assump_CapStructure!$D$80-Model!$K$13 -> 44341
B12: Memo: Seller Note allocated by ownership (4) | C12: =C10*$H$12 -> 2200 | D12: =D10*$H$12 -> 1200 | E12: =E10*$H$12 -> 600 | H12: =Model!$K$13 -> 4000
B13: Rollover % of Consideration ex Note | C13: 0.2 | D13: 0.2 | E13: 0.2 | H13: =H14/H11 -> 0.2
B14: Rollover $ Amount | C14: =C13*C11 -> 4877.51 | D14: =D13*D11 -> 2660.46 | E14: =E13*E11 -> 1330.23 | H14: =SUM(C14:E14) -> 8868.2
B15: Newco Equity Account | C15: =C14 -> 4877.51 | D15: =D14 -> 2660.46 | E15: =E14 -> 1330.23 | H15: =Model!$K$20 -> 23107 | M15: =H15*(1+Assump_CapStructure!$F$28)^5 -> 33951.764
B16: Sponsor Equity Check | H16: =H15-H14 -> 14238.8
B17: Newco Ownership % (2) | C17: =C14/$H$15 -> 0.21108365 | D17: =D14/$H$15 -> 0.11513654 | E17: =E14/$H$15 -> 0.057568269 | H17: =SUM(C17:E17) -> 0.38378846
B18: LOI Ownership | C18: 0.184 | D18: 0.101 | E18: 0.05 | H18: =SUM(C18:E18) -> 0.335
B19: Check vs LOI Ownership | C19: =C17-C18 -> 0.027083654 | D19: =D17-D18 -> 0.014136539 | E19: =E17-E18 -> 0.0075682694 | H19: =H17-H18 -> 0.048788462
B21: Gross Consideration Summary (3) | I21: % of Total
B22: Cash proceeds | C22: =C11-C14 -> 19510.04 | D22: =D11-D14 -> 10641.84 | E22: =E11-E14 -> 5320.92 | H22: =H11-H14 -> 35472.8 | I22: =H22/$H$25 -> 0.7338036
B23: Rollover equity | C23: =C14 -> 4877.51 | D23: =D14 -> 2660.46 | E23: =E14 -> 1330.23 | H23: =H14 -> 8868.2 | I23: =H23/$H$25 -> 0.1834509
B24: Seller Note (4) | C24: =C12 -> 2200 | D24: =D12 -> 1200 | E24: =E12 -> 600 | H24: =H12 -> 4000 | I24: =H24/$H$25 -> 0.082745496
B25: Total Consideration | C25: =SUM(C22:C24) -> 26587.55 | D25: =SUM(D22:D24) -> 14502.3 | E25: =SUM(E22:E24) -> 7251.15 | H25: =SUM(H22:H24) -> 48341 | I25: =H25/$H$25 -> 1
B27: (1) Equity purchase price less the seller note; allocated by current ownership.
B28: (2) Rollover $ divided by the total Newco equity account (sponsor + rollover), pre-MEIP.
B29: (3) Gross of transaction expenses borne by the sellers and of any closing working capital adjustment.
B30: (4) Seller note: 6% PIK, 6-year maturity, subordinated to senior and mezzanine debt.
B32: For Purchase Agreement Schedules 1.1 and 1.3
B34: Rollover % of consideration ("a") | C34: =C13 -> 0.2 | D34: =D13 -> 0.2 | E34: =E13 -> 0.2
B35: Contributed membership interest ("b" = a x current ownership) | C35: =C34*C10 -> 0.11 | D35: =D34*D10 -> 0.06 | E35: =E34*E10 -> 0.03 | H35: =SUM(C35:E35) -> 0.2
B36: Purchased membership interest (current ownership - b) | C36: =C10-C35 -> 0.44 | D36: =D10-D35 -> 0.24 | E36: =E10-E35 -> 0.12 | H36: =SUM(C36:E36) -> 0.8
B38: ROLLOVER EQUITY IMPACT WITH PROPOSED OVERCAPITALIZATION
C39: Same Rollover $ from LOI | D39: Same Ownership % from LOI
B40: LOI Newco Equity Account (sponsor check per LOI + rollover) | C40: =13875.25+$H$14 -> 22743.45 | D40: =13875.25+$H$14 -> 22743.45
B41: Rollover $ | C41: =$H$14 -> 8868.2 | D41: =$H$18*$H$15 -> 7740.845
B42: Newco Equity Account (proposed) | C42: =$H$15 -> 23107 | D42: =$H$15 -> 23107
B43: Sponsor Equity Check | C43: =C42-C41 -> 14238.8 | D43: =D42-D41 -> 15366.155
B44: Newco Ownership % | C44: =C41/C42 -> 0.38378846 | D44: =D41/D42 -> 0.335
B45: Ownership delta vs LOI | C45: =C44-$H$18 -> 0.048788462 | D45: =D44-$H$18 -> 0
B46: Dilution vs LOI | C46: =C45/$H$18 -> 0.1456372 | D46: =D45/$H$18 -> 0
B47: Rollover required to dilution-protect (6) | C47: =$H$18*C42 -> 7740.845 | D47: =$H$18*D42 -> 7740.845
...

Sheet Model-->
A1: Model -->

Sheet Model
A1: =Assump_CapStructure!$F$7 -> Project Kestrel | M1: ="Operating Case Running: "&CHOOSE(Assump_CapStructure!$K$5,"Management Case","Case II - No Growth, No Taxes","Case III - Downside Case, No Taxes","Upside Case","Flat Case") -> Operating Case Running: Management Case
A2: ="Prepared by: "&Assump_CapStructure!$F$8 -> Prepared by: Halvern | M2: ="Capital Structure Case: "&CHOOSE(Assump_CapStructure!$K$15,"Base Case - Senior + Mezz","Senior Only","Senior + Seller Note Upsized","All Equity","Unitranche","Case 6","Case 7","Case 8","Case 9","Case 10") -> Capital Structure Case: Base Case - Senior + Mezz
A3: =Assump_CapStructure!$F$11 -> ($ in 000s)
A5: TRANSACTION SUMMARY - USES AND SOURCES OF FUNDS
A6: USES OF FUNDS | D6: Amount | E6: % of Total | F6: x EBITDA | H6: SOURCES OF FUNDS | K6: Amount | L6: % of Total | M6: x EBITDA | N6: Pricing
A7: Cash Consideration to Shareholders | B7: (incl. seller-note portion) | D7: =Assump_CapStructure!D53 -> 39472.8 | E7: =IF($D$15=0,0,D7/$D$15) -> 0.67379274 | F7: =D7/$E$85 -> 5.0162409 | H7: Revolver | K7: =Assump_CapStructure!D36 -> 0 | L7: =IF(K7>0,(ROUND(K7/$K$21,2)*100&"%"),"-") -> - | M7: =K7/$E$85 -> 0 | N7: =IF(K7>0,IF(Assump_CapStructure!$W$36="L +","Base + "&TEXT(Assump_CapStructure!$U$36,"0.00%"),TEXT(Assump_CapStructure!$U$36,"0.00%")&" Fixed")&IF(Assump_CapStructure!$V$36>0," + "&TEXT(Assump_CapStructure!$V$36,"0.00%")&" PIK",""),"-") -> -
A8: Repay Existing Debt | D8: =Assump_CapStructure!D54 -> 6842 | E8: =IF($D$15=0,0,D8/$D$15) -> 0.11679156 | F8: =D8/$E$85 -> 0.86948786 | H8: Term Loan A | K8: =Assump_CapStructure!D37 -> 23607 | L8: =IF(K8>0,(ROUND(K8/$K$21,2)*100&"%"),"-") -> 40% | M8: =K8/$E$85 -> 3 | N8: =IF(K8>0,IF(Assump_CapStructure!$W$37="L +","Base + "&TEXT(Assump_CapStructure!$U$37,"0.00%"),TEXT(Assump_CapStructure!$U$37,"0.00%")&" Fixed")&IF(Assump_CapStructure!$V$37>0," + "&TEXT(Assump_CapStructure!$V$37,"0.00%")&" PIK",""),"-") -> Base + 3.25%
A9: Rollover Equity | D9: =Assump_CapStructure!D55 -> 8868.2 | E9: =IF($D$15=0,0,D9/$D$15) -> 0.15137839 | F9: =D9/$E$85 -> 1.1269793 | H9: Term Loan B | K9: =Assump_CapStructure!D38 -> 0 | L9: =IF(K9>0,(ROUND(K9/$K$21,2)*100&"%"),"-") -> - | M9: =K9/$E$85 -> 0 | N9: =IF(K9>0,IF(Assump_CapStructure!$W$38="L +","Base + "&TEXT(Assump_CapStructure!$U$38,"0.00%"),TEXT(Assump_CapStructure!$U$38,"0.00%")&" Fixed")&IF(Assump_CapStructure!$V$38>0," + "&TEXT(Assump_CapStructure!$V$38,"0.00%")&" PIK",""),"-") -> -
A10: Earnout | D10: =Assump_CapStructure!D56 -> 0 | E10: =IF($D$15=0,0,D10/$D$15) -> 0 | F10: =D10/$E$85 -> 0 | H10: Second Lien | K10: =Assump_CapStructure!D39 -> 0 | L10: =IF(K10>0,(ROUND(K10/$K$21,2)*100&"%"),"-") -> - | M10: =K10/$E$85 -> 0 | N10: =IF(K10>0,IF(Assump_CapStructure!$W$39="L +","Base + "&TEXT(Assump_CapStructure!$U$39,"0.00%"),TEXT(Assump_CapStructure!$U$39,"0.00%")&" Fixed")&IF(Assump_CapStructure!$V$39>0," + "&TEXT(Assump_CapStructure!$V$39,"0.00%")&" PIK",""),"-") -> -
A11: Rollover Debt | D11: =Assump_CapStructure!D57 -> 0 | E11: =IF($D$15=0,0,D11/$D$15) -> 0 | F11: =D11/$E$85 -> 0 | H11: Senior Notes | K11: =Assump_CapStructure!D40 -> 0 | L11: =IF(K11>0,(ROUND(K11/$K$21,2)*100&"%"),"-") -> - | M11: =K11/$E$85 -> 0 | N11: =IF(K11>0,IF(Assump_CapStructure!$W$40="L +","Base + "&TEXT(Assump_CapStructure!$U$40,"0.00%"),TEXT(Assump_CapStructure!$U$40,"0.00%")&" Fixed")&IF(Assump_CapStructure!$V$40>0," + "&TEXT(Assump_CapStructure!$V$40,"0.00%")&" PIK",""),"-") -> -
A12: Purchase Price | D12: =SUM(D7:D11) -> 55183 | E12: =IF($D$15=0,0,D12/$D$15) -> 0.94196269 | F12: =D12/$E$85 -> 7.0127081 | H12: Mezzanine Debt | K12: =Assump_CapStructure!D41 -> 7869 | L12: =IF(K12>0,(ROUND(K12/$K$21,2)*100&"%"),"-") -> 13% | M12: =K12/$E$85 -> 1 | N12: =IF(K12>0,IF(Assump_CapStructure!$W$41="L +","Base + "&TEXT(Assump_CapStructure!$U$41,"0.00%"),TEXT(Assump_CapStructure!$U$41,"0.00%")&" Fixed")&IF(Assump_CapStructure!$V$41>0," + "&TEXT(Assump_CapStructure!$V$41,"0.00%")&" PIK",""),"-") -> 11.00% Fixed + 2.00% PIK
A13: Cash on Balance Sheet at Close | D13: =Assump_CapStructure!D59 -> 1000 | E13: =IF($D$15=0,0,D13/$D$15) -> 0.017069798 | F13: =D13/$E$85 -> 0.12708095 | H13: Seller Note | K13: =Assump_CapStructure!D42 -> 4000 | L13: =IF(K13>0,(ROUND(K13/$K$21,2)*100&"%"),"-") -> 7% | M13: =K13/$E$85 -> 0.5083238 | N13: =IF(K13>0,IF(Assump_CapStructure!$W$42="L +","Base + "&TEXT(Assump_CapStructure!$U$42,"0.00%"),TEXT(Assump_CapStructure!$U$42,"0.00%")&" Fixed")&IF(Assump_CapStructure!$V$42>0," + "&TEXT(Assump_CapStructure!$V$42,"0.00%")&" PIK",""),"-") -> 0.00% Fixed + 6.00% PIK
A14: Transaction Costs | D14: =Assump_CapStructure!D64 -> 2400 | E14: =IF($D$15=0,0,D14/$D$15) -> 0.040967516 | F14: =D14/$E$85 -> 0.30499428 | H14: Subordinated Notes | K14: =Assump_CapStructure!D43 -> 0 | L14: =IF(K14>0,(ROUND(K14/$K$21,2)*100&"%"),"-") -> - | M14: =K14/$E$85 -> 0 | N14: =IF(K14>0,IF(Assump_CapStructure!$W$43="L +","Base + "&TEXT(Assump_CapStructure!$U$43,"0.00%"),TEXT(Assump_CapStructure!$U$43,"0.00%")&" Fixed")&IF(Assump_CapStructure!$V$43>0," + "&TEXT(Assump_CapStructure!$V$43,"0.00%")&" PIK",""),"-") -> -
A15: Total Uses | D15: =D12+D13+D14 -> 58583 | E15: =IF($D$15=0,0,D15/$D$15) -> 1 | F15: =D15/$E$85 -> 7.4447833 | H15: Other | K15: =Assump_CapStructure!D44 -> 0 | L15: =IF(K15>0,(ROUND(K15/$K$21,2)*100&"%"),"-") -> - | M15: =K15/$E$85 -> 0 | N15: =IF(K15>0,IF(Assump_CapStructure!$W$44="L +","Base + "&TEXT(Assump_CapStructure!$U$44,"0.00%"),TEXT(Assump_CapStructure!$U$44,"0.00%")&" Fixed")&IF(Assump_CapStructure!$V$44>0," + "&TEXT(Assump_CapStructure!$V$44,"0.00%")&" PIK",""),"-") -> -
H16: Total Debt | K16: =SUM(K7:K15) -> 35476 | L16: =IF(K16>0,(ROUND(K16/$K$21,2)*100&"%"),"-") -> 61% | M16: =K16/$E$85 -> 4.5083238
H17: Rollover Equity | K17: =Assump_CapStructure!D45 -> 8868.2 | L17: =IF(K17>0,(ROUND(K17/$K$21,2)*100&"%"),"-") -> 15% | M17: =K17/$E$85 -> 1.1269793
H18: Sponsor Preferred Equity | K18: =Assump_CapStructure!D46 -> 12814.92 | L18: =IF(K18>0,(ROUND(K18/$K$21,2)*100&"%"),"-") -> 22% | M18: =K18/$E$85 -> 1.6285322 | N18: =TEXT(Assump_CapStructure!$F$28,"0.00%")&" accreting" -> 8.00% accreting
H19: Sponsor Common Equity | K19: =Assump_CapStructure!D47 -> 1423.88 | L19: =IF(K19>0,(ROUND(K19/$K$21,2)*100&"%"),"-") -> 2% | M19: =K19/$E$85 -> 0.18094802
H20: Total Equity | K20: =SUM(K17:K19) -> 23107 | L20: =IF(K20>0,(ROUND(K20/$K$21,2)*100&"%"),"-") -> 39% | M20: =K20/$E$85 -> 2.9364595
H21: Total Sources | K21: =K16+K20 -> 58583 | L21: =IF(K21>0,(ROUND(K21/$K$21,2)*100&"%"),"-") -> 100% | M21: =K21/$E$85 -> 7.4447833
A23: Check: Total Sources - Total Uses (must be 0) | D23: =K21-D15 -> 0
A26: FINANCIAL SUMMARY
A27: Pro Forma for the Transaction
B29: =C29-1 -> 2022 | C29: =D29-1 -> 2023 | D29: =E29-1 -> 2024 | E29: =F29-1 -> 2025 | F29: =Assump_CapStructure!$F$10 -> 2026 | G29: =F29+1 -> 2027 | H29: =G29+1 -> 2028 | I29: =H29+1 -> 2029 | J29: =I29+1 -> 2030 | K29: =J29+1 -> 2031 | L29: =K29+1 -> 2032 | M29: =L29+1 -> 2033
A30: ="FYE "&Assump_CapStructure!$F$9 -> FYE September 30, | B30: ="FY"&TEXT(B29,"0")&IF(B29<Assump_CapStructure!$F$10,"A","E") -> FY2022A | C30: ="FY"&TEXT(C29,"0")&IF(C29<Assump_CapStructure!$F$10,"A","E") -> FY2023A | D30: ="FY"&TEXT(D29,"0")&IF(D29<Assump_CapStructure!$F$10,"A","E") -> FY2024A | E30: ="FY"&TEXT(E29,"0")&IF(E29<Assump_CapStructure!$F$10,"A","E") -> FY2025A | F30: ="FY"&TEXT(F29,"0")&IF(F29<Assump_CapStructure!$F$10,"A","E") -> FY2026E | G30: ="FY"&TEXT(G29,"0")&IF(G29<Assump_CapStructure!$F$10,"A","E") -> FY2027E | H30: ="FY"&TEXT(H29,"0")&IF(H29<Assump_CapStructure!$F$10,"A","E") -> FY2028E | I30: ="FY"&TEXT(I29,"0")&IF(I29<Assump_CapStructure!$F$10,"A","E") -> FY2029E | ... M30: ="FY"&TEXT(M29,"0")&IF(M29<Assump_CapStructure!$F$10,"A","E") -> FY2033E | N30: CAGR FY25-30
A31: Revenue | B31: =B75 -> 35245 | C31: =C75 -> 38240 | D31: =D75 -> 40516 | E31: =E75 -> 42624 | F31: =F75 -> 46033.92 | G31: =G75 -> 49348.362 | H31: =H75 -> 52556.006 | I31: =I75 -> 55709.366 | ... M31: =M75 -> 67068.656 | N31: =(J31/E31)^(1/5)-1 -> 0.066363557
A32: % Growth | C32: =IF(B31=0,0,C31/B31-1) -> 0.084976592 | D32: =IF(C31=0,0,D31/C31-1) -> 0.059518828 | E32: =IF(D31=0,0,E31/D31-1) -> 0.052028828 | F32: =IF(E31=0,0,F31/E31-1) -> 0.08 | G32: =IF(F31=0,0,G31/F31-1) -> 0.072 | H32: =IF(G31=0,0,H31/G31-1) -> 0.065 | I32: =IF(H31=0,0,I31/H31-1) -> 0.06 | J32: =IF(I31=0,0,J31/I31-1) -> 0.055 | ... M32: =IF(L31=0,0,M31/L31-1) -> 0.04
A33: Adj. EBITDA | B33: =B85 -> 6287 | C33: =C85 -> 6961 | D33: =D85 -> 7923 | E33: =E85 -> 7869 | F33: =F85 -> 8746.4448 | G33: =G85 -> 9524.2339 | H33: =H85 -> 10300.977 | I33: =I85 -> 11030.454 | ... M33: =M85 -> 13547.869 | N33: =(J33/E33)^(1/5)-1 -> 0.083573126
A34: % Margin | B34: =B33/B31 -> 0.17837991 | C34: =C33/C31 -> 0.18203452 | D34: =D33/D31 -> 0.19555237 | E34: =E33/E31 -> 0.1846143 | F34: =F33/F31 -> 0.19 | G34: =G33/G31 -> 0.193 | H34: =H33/H31 -> 0.196 | I34: =I33/I31 -> 0.198 | ... M34: =M33/M31 -> 0.202
A35: Capex | B35: =Assump_Operating!B128 -> 1058 | C35: =Assump_Operating!C128 -> 1032 | D35: =Assump_Operating!D128 -> 1116 | E35: =Assump_Operating!E128 -> 1175 | F35: =Assump_Operating!F128 -> 1288.9498 | G35: =Assump_Operating!G128 -> 1381.7541 | H35: =Assump_Operating!H128 -> 1471.5682 | I35: =Assump_Operating!I128 -> 1559.8623 | ... M35: =Assump_Operating!M128 -> 1877.9224
A36: % of Revenue | B36: =B35/B31 -> 0.030018442 | C36: =C35/C31 -> 0.026987448 | D36: =D35/D31 -> 0.027544674 | E36: =E35/E31 -> 0.027566629 | F36: =F35/F31 -> 0.028 | G36: =G35/G31 -> 0.028 | H36: =H35/H31 -> 0.028 | I36: =I35/I31 -> 0.028 | ... M36: =M35/M31 -> 0.028
A37: Net Working Capital | B37: =B306 -> 4535 | C37: =C306 -> 5102 | D37: =D306 -> 5053 | E37: =E306 -> 5128 | F37: =F306 -> 5667.8476 | G37: =G306 -> 5999.9496 | H37: =H306 -> 6453.0136 | I37: =I306 -> 6884.6856 | ... M37: =M306 -> 8066.8894
A38: % of Revenue | B38: =B37/B31 -> 0.12867073 | C38: =C37/C31 -> 0.1334205 | D38: =D37/D31 -> 0.12471616 | E38: =E37/E31 -> 0.12030781 | F38: =F37/F31 -> 0.12312329 | G38: =G37/G31 -> 0.12158356 | H38: =H37/H31 -> 0.12278356 | I38: =I37/I31 -> 0.12358219 | ... M38: =M37/M31 -> 0.12027808
A40: FREE CASH FLOW
A41: EBITDA | F41: =F85 -> 8746.4448 | G41: =G85 -> 9524.2339 | H41: =H85 -> 10300.977 | I41: =I85 -> 11030.454 | J41: =J85 -> 11754.676 | K41: =K85 -> 12342.41 | L41: =L85 -> 13026.797 | M41: =M85 -> 13547.869
A42: Other (management fee) | F42: =-F93 -> 0 | G42: =-G93 -> 0 | H42: =-H93 -> 0 | I42: =-I93 -> 0 | J42: =-J93 -> 0 | K42: =-K93 -> 0 | L42: =-L93 -> 0 | M42: =-M93 -> 0
A43: Capex | F43: =-F35 -> -1288.9498 | G43: =-G35 -> -1381.7541 | H43: =-H35 -> -1471.5682 | I43: =-I35 -> -1559.8623 | J43: =-J35 -> -1645.6547 | K43: =-K35 -> -1727.9374 | L43: =-L35 -> -1805.6946 | M43: =-M35 -> -1877.9224
A44: (Inc)/Dec in Working Capital | F44: =F179 -> -356.84757 | G44: =G179 -> -332.10207 | H44: =H179 -> -453.06393 | I44: =I179 -> -431.67199 | J44: =J179 -> -425.43488 | K44: =K179 -> -141.99005 | L44: =L179 -> -449.65851 | M44: =M179 -> -165.12035
A45: Cash Interest, net | F45: =-('Debt Schedules'!F116-F106) -> -2665.115 | G45: =-('Debt Schedules'!G116-G106) -> -2428.3218 | H45: =-('Debt Schedules'!H116-H106) -> -2135.0824 | I45: =-('Debt Schedules'!I116-I106) -> -1791.4986 | J45: =-('Debt Schedules'!J116-J106) -> -1393.9077 | K45: =-('Debt Schedules'!K116-K106) -> -936.93423 | L45: =-('Debt Schedules'!L116-L106) -> -294.53899 | M45: =-('Debt Schedules'!M116-M106) -> 34.769477
A46: Cash Taxes | F46: =-F109 -> -338.3035 | G46: =-G109 -> -574.26513 | H46: =-H109 -> -825.13958 | I46: =-I109 -> -1076.9407 | J46: =-J109 -> -1341.775 | K46: =-K109 -> -1712.4468 | L46: =-L109 -> -2062.3308 | M46: =-M109 -> -2340.2946
...

Sheet Assump_CapStructure
A1: =$F$7 -> Project Kestrel | U1: ="Operating Case Running: "&CHOOSE(Assump_CapStructure!$K$5,"Management Case","Case II - No Growth, No Taxes","Case III - Downside Case, No Taxes","Upside Case","Flat Case") -> Operating Case Running: Management Case
A2: ="Prepared by: "&$F$8 -> Prepared by: Halvern | U2: ="Capital Structure Case: "&CHOOSE(Assump_CapStructure!$K$15,"Base Case - Senior + Mezz","Senior Only","Senior + Seller Note Upsized","All Equity","Unitranche","Case 6","Case 7","Case 8","Case 9","Case 10") -> Capital Structure Case: Base Case - Senior + Mezz
A3: =$F$11 -> ($ in 000s)
C5: GENERAL ASSUMPTIONS | J5: Operating Case (1-5): | K5: 1
