Workbook
Name Project_Name: "Project Larkspur"
Name Rev_Total: 'Revenue Build'!$I$41:$BP$41
Name QoE_Aug: 'QoE PF Adj. P&L Aug-26'!$AI$8
Name wrn.CIM: 'CIM Output'!$B$2:$K$40
Name \a: 'Historical & Projected P&L'!$J$8
Name \b: 'Historical & Projected P&L'!$BQ$8
Name Rev_2024: 'CIM Output'!$D$9
Name Rev_2025: 'CIM Output'!$E$9
Name Rev_2026: 'CIM Output'!$F$9
Name Rev_2027: 'CIM Output'!$G$9
Name Rev_2028: 'CIM Output'!$H$9
Name EBITDA_2024: 'CIM Output'!$D$36
Name EBITDA_2025: 'CIM Output'!$E$36
Name EBITDA_2026: 'CIM Output'!$F$36
Name EBITDA_2027: 'CIM Output'!$G$36
Name EBITDA_2028: 'CIM Output'!$H$36
Name Acc_Total: 'Revenue Build'!$I$51:$BP$51
Name Acc_Current: 'Revenue Build'!$I$6:$BP$6
Name Acc_SL: 'Revenue Build'!$I$24:$BP$24
Name Acc_New: 'Revenue Build'!$I$34:$BP$34
Name Months: 'Historical & Projected P&L'!$J$8:$BQ$8
Name Years: 'Historical & Projected P&L'!$J$7:$BQ$7
Name Model_Start: 'Historical & Projected P&L'!$J$8
Name Proj_Start: 'Historical & Projected P&L'!$AS$8
Name Model_End: 'Historical & Projected P&L'!$BQ$8
Name CIM_Table: 'CIM Output'!$B$3:$K$39
Name QoE_LTM: 'QoE PF Adj. P&L Aug-26'!$AK$8:$AK$118
Name QoE_Rev: 'QoE PF Adj. P&L Aug-26'!$D$15:$AI$15
Name QoE_EBITDA: 'QoE PF Adj. P&L Aug-26'!$D$108:$AI$108
Name SW_Build: 'Separate Line Item Builds'!$J$22:$BQ$22
Name SW_Increase: 'Separate Line Item Builds'!$AS$24:$BQ$24
Name Ins_Table: 'Separate Line Item Builds'!$C$46:$D$50
Name Holidays: 'Revenue Build'!$AQ$61:$AQ$70
Name GL_Data: 'GL 2026'!$B$5:$M$4548
Name SepNov_Map: 'Sep - Nov P&L'!$D$6:$D$83
Name SepNov_Sep: 'Sep - Nov P&L'!$I$6:$I$83
Name SepNov_Oct: 'Sep - Nov P&L'!$J$6:$J$83
Name SepNov_Nov: 'Sep - Nov P&L'!$K$6:$K$83
Name Cap_Max: 'Revenue Build'!$I$44
Name Coll_Rate: 'Revenue Build'!$I$56:$BP$56
Name Infl_M: 'Historical & Projected P&L'!$D$121
Name Sen_Living: 'Revenue Build'!$I$22:$BP$28
Name New_Team: 'Revenue Build'!$I$31:$BP$38
Name check_1: 'CIM Output'!$D$33:$H$33
Name check_2: 'CIM Output'!$D$39:$H$39
Name check_3: 'Historical & Projected P&L'!$J$117:$AO$117
Name Opex_Total: 'Historical & Projected P&L'!$D$95:$H$95
Name EBITDA_Row: 'Historical & Projected P&L'!$D$105:$H$105
Name Rev_Row: 'Historical & Projected P&L'!$D$10:$H$10
Name Assumptions_Block: 'Historical & Projected P&L'!$C$120:$BQ$211
Name Accessioner_Cost: 'Separate Line Item Builds'!$B$20
Name Acc_per_Accessioner: 'Separate Line Item Builds'!$B$29
Name NewRep_Pct: 'Separate Line Item Builds'!$B$32
Name Hires_Table: 'Separate Line Item Builds'!$C$13:$E$19
Name Ramp_Anchor: 'Revenue Build'!$AW$10
Name Ramp_Target: 'Revenue Build'!$BD$10
Name NewTeam_Ramp: 'Revenue Build'!$AU$32:$BF$32
Name Workdays: 'Revenue Build'!$I$9:$BP$9
Name Gross_Charges: 'Revenue Build'!$I$58:$BP$58
Name Units: 'Historical & Projected P&L'!$C$8

Sheet Cover
B4: Orivane Clinical Laboratories
B5: Financial Model
B6: QoE financials through Aug-26, Management reported Sep – Nov-26, projections from Dec-26
B8: Prepared by Falkmere Advisory – draft for discussion
B10: Notes / Disclaimer
B11: (1) All figures are synthetic and illustrative; no real company data.
B12: (2) Monthly model; annual roll-ups via SUMIFS on the year row. No debt schedule, no returns – CIM output only.
B13: (3) Workdays use NETWORKDAYS(prior month-end, month-end) as in the original build; holiday list applies from Dec-26.
B14: (4) Sep–Nov-26 S&W, payroll taxes and processing fees are restated from the reported gross payroll figure (see builds tab).
B15: (5) No circular references; fixed-cost projections = trailing 12-month average grown at a monthly inflation input.

Sheet CIM Output
B2: Orivane Clinical Laboratories – Summary Financials | J2: CAGR
C3: $ in actual | D3: 2024 | E3: 2025 | F3: 2026 | G3: 2027 | H3: 2028 | J3: 2024 - 2026 | K3: 2026 - 2028
B4: Summary Financials
B5: Total Accessions | D5: =+'Revenue Build'!C51 -> 85204 | E5: =+'Revenue Build'!D51 -> 92761 | F5: =+'Revenue Build'!E51 -> 101458 | G5: =+'Revenue Build'!F51 -> 113147 | H5: =+'Revenue Build'!G51 -> 136217 | J5: =+(F5/D5)^(1/(F$3-D$3))-1 -> 0.091222109 | K5: =+(H5/F5)^(1/(H$3-F$3))-1 -> 0.158704
B6: YoY % Growth | E6: =+IFERROR(E5/D5-1,) -> 0.088693019 | F6: =+IFERROR(F5/E5-1,) -> 0.093757075 | G6: =+IFERROR(G5/F5-1,) -> 0.11521023 | H6: =+IFERROR(H5/G5-1,) -> 0.20389405
B7: Implied Reimbursement per Accession | D7: =+IFERROR(D9/D5,) -> 149.1937 | E7: =+IFERROR(E9/E5,) -> 148.31017 | F7: =+IFERROR(F9/F5,) -> 147.38235 | G7: =+IFERROR(G9/G5,) -> 143.52708 | H7: =+IFERROR(H9/H5,) -> 139.07986
B9: Net Operating Revenue | D9: =+'Historical & Projected P&L'!D10 -> 12711900 | E9: =+'Historical & Projected P&L'!E10 -> 13757400 | F9: =+'Historical & Projected P&L'!F10 -> 14953118 | G9: =+'Historical & Projected P&L'!G10 -> 16239659 | H9: =+'Historical & Projected P&L'!H10 -> 18945041 | J9: =+(F9/D9)^(1/(F$3-D$3))-1 -> 0.08457765 | K9: =+(H9/F9)^(1/(H$3-F$3))-1 -> 0.12559433
B10: YoY % Growth | E10: =+IFERROR(E9/D9-1,) -> 0.08224577 | F10: =+IFERROR(F9/E9-1,) -> 0.086914554 | G10: =+IFERROR(G9/F9-1,) -> 0.086038284 | H10: =+IFERROR(H9/G9-1,) -> 0.16659109
B12: Operating Expenses
B13: Drugs & Medical Supplies
C14: Medical Supplies | D14: =+SUMIFS('Historical & Projected P&L'!D$10:D$115,'Historical & Projected P&L'!$C$10:$C$115,'CIM Output'!$C14) -> 317200 | E14: =+SUMIFS('Historical & Projected P&L'!E$10:E$115,'Historical & Projected P&L'!$C$10:$C$115,'CIM Output'!$C14) -> 343800 | F14: =+SUMIFS('Historical & Projected P&L'!F$10:F$115,'Historical & Projected P&L'!$C$10:$C$115,'CIM Output'!$C14) -> 430923.07 | G14: =+SUMIFS('Historical & Projected P&L'!G$10:G$115,'Historical & Projected P&L'!$C$10:$C$115,'CIM Output'!$C14) -> 414111.3 | H14: =+SUMIFS('Historical & Projected P&L'!H$10:H$115,'Historical & Projected P&L'!$C$10:$C$115,'CIM Output'!$C14) -> 483098.56
C15: Lab Supplies | D15: =+SUMIFS('Historical & Projected P&L'!D$10:D$115,'Historical & Projected P&L'!$C$10:$C$115,'CIM Output'!$C15) -> 1073300 | E15: =+SUMIFS('Historical & Projected P&L'!E$10:E$115,'Historical & Projected P&L'!$C$10:$C$115,'CIM Output'!$C15) -> 1164300 | F15: =+SUMIFS('Historical & Projected P&L'!F$10:F$115,'Historical & Projected P&L'!$C$10:$C$115,'CIM Output'!$C15) -> 1264791.2 | G15: =+SUMIFS('Historical & Projected P&L'!G$10:G$115,'Historical & Projected P&L'!$C$10:$C$115,'CIM Output'!$C15) -> 1403106.5 | H15: =+SUMIFS('Historical & Projected P&L'!H$10:H$115,'Historical & Projected P&L'!$C$10:$C$115,'CIM Output'!$C15) -> 1636851.6
C16: Drugs | D16: =+SUMIFS('Historical & Projected P&L'!D$10:D$115,'Historical & Projected P&L'!$C$10:$C$115,'CIM Output'!$C16) -> 114800 | E16: =+SUMIFS('Historical & Projected P&L'!E$10:E$115,'Historical & Projected P&L'!$C$10:$C$115,'CIM Output'!$C16) -> 123600 | F16: =+SUMIFS('Historical & Projected P&L'!F$10:F$115,'Historical & Projected P&L'!$C$10:$C$115,'CIM Output'!$C16) -> 100193.01 | G16: =+SUMIFS('Historical & Projected P&L'!G$10:G$115,'Historical & Projected P&L'!$C$10:$C$115,'CIM Output'!$C16) -> 144532.96 | H16: =+SUMIFS('Historical & Projected P&L'!H$10:H$115,'Historical & Projected P&L'!$C$10:$C$115,'CIM Output'!$C16) -> 168610.87
C17: Pharmacy | D17: =+SUMIFS('Historical & Projected P&L'!D$10:D$115,'Historical & Projected P&L'!$C$10:$C$115,'CIM Output'!$C17) -> 75600 | E17: =+SUMIFS('Historical & Projected P&L'!E$10:E$115,'Historical & Projected P&L'!$C$10:$C$115,'CIM Output'!$C17) -> 82400 | F17: =+SUMIFS('Historical & Projected P&L'!F$10:F$115,'Historical & Projected P&L'!$C$10:$C$115,'CIM Output'!$C17) -> 65089.829 | G17: =+SUMIFS('Historical & Projected P&L'!G$10:G$115,'Historical & Projected P&L'!$C$10:$C$115,'CIM Output'!$C17) -> 94190.022 | H17: =+SUMIFS('Historical & Projected P&L'!H$10:H$115,'Historical & Projected P&L'!$C$10:$C$115,'CIM Output'!$C17) -> 109881.24
B18: Total Drugs & Medical Supplies | D18: =SUM(D14:D17) -> 1580900 | E18: =SUM(E14:E17) -> 1714100 | F18: =SUM(F14:F17) -> 1860997.1 | G18: =SUM(G14:G17) -> 2055940.8 | H18: =SUM(H14:H17) -> 2398442.3
B20: Employee Salaries & Wages
C21: Salaries & Wages | D21: =+SUMIFS('Historical & Projected P&L'!D$10:D$115,'Historical & Projected P&L'!$C$10:$C$115,'CIM Output'!$C21) -> 3317600 | E21: =+SUMIFS('Historical & Projected P&L'!E$10:E$115,'Historical & Projected P&L'!$C$10:$C$115,'CIM Output'!$C21) -> 3509800 | F21: =+SUMIFS('Historical & Projected P&L'!F$10:F$115,'Historical & Projected P&L'!$C$10:$C$115,'CIM Output'!$C21) -> 3716855.6 | G21: =+SUMIFS('Historical & Projected P&L'!G$10:G$115,'Historical & Projected P&L'!$C$10:$C$115,'CIM Output'!$C21) -> 4327258.5 | H21: =+SUMIFS('Historical & Projected P&L'!H$10:H$115,'Historical & Projected P&L'!$C$10:$C$115,'CIM Output'!$C21) -> 4610459.6
C22: Contract Labor | D22: =+SUMIFS('Historical & Projected P&L'!D$10:D$115,'Historical & Projected P&L'!$C$10:$C$115,'CIM Output'!$C22) -> 187900 | E22: =+SUMIFS('Historical & Projected P&L'!E$10:E$115,'Historical & Projected P&L'!$C$10:$C$115,'CIM Output'!$C22) -> 205500 | F22: =+SUMIFS('Historical & Projected P&L'!F$10:F$115,'Historical & Projected P&L'!$C$10:$C$115,'CIM Output'!$C22) -> 249542.07 | G22: =+SUMIFS('Historical & Projected P&L'!G$10:G$115,'Historical & Projected P&L'!$C$10:$C$115,'CIM Output'!$C22) -> 241970.92 | H22: =+SUMIFS('Historical & Projected P&L'!H$10:H$115,'Historical & Projected P&L'!$C$10:$C$115,'CIM Output'!$C22) -> 282281.12
C23: Sales Rep Expense | D23: =+SUMIFS('Historical & Projected P&L'!D$10:D$115,'Historical & Projected P&L'!$C$10:$C$115,'CIM Output'!$C23) -> 636600 | E23: =+SUMIFS('Historical & Projected P&L'!E$10:E$115,'Historical & Projected P&L'!$C$10:$C$115,'CIM Output'!$C23) -> 684700 | F23: =+SUMIFS('Historical & Projected P&L'!F$10:F$115,'Historical & Projected P&L'!$C$10:$C$115,'CIM Output'!$C23) -> 747121.01 | G23: =+SUMIFS('Historical & Projected P&L'!G$10:G$115,'Historical & Projected P&L'!$C$10:$C$115,'CIM Output'!$C23) -> 873223.9 | H23: =+SUMIFS('Historical & Projected P&L'!H$10:H$115,'Historical & Projected P&L'!$C$10:$C$115,'CIM Output'!$C23) -> 1116103.7
C24: Other Personnel Costs | D24: =+SUMIFS('Historical & Projected P&L'!D$10:D$115,'Historical & Projected P&L'!$C$10:$C$115,'CIM Output'!$C24) -> 88400 | E24: =+SUMIFS('Historical & Projected P&L'!E$10:E$115,'Historical & Projected P&L'!$C$10:$C$115,'CIM Output'!$C24) -> 95900 | F24: =+SUMIFS('Historical & Projected P&L'!F$10:F$115,'Historical & Projected P&L'!$C$10:$C$115,'CIM Output'!$C24) -> 74791.667 | G24: =+SUMIFS('Historical & Projected P&L'!G$10:G$115,'Historical & Projected P&L'!$C$10:$C$115,'CIM Output'!$C24) -> 78467.515 | H24: =+SUMIFS('Historical & Projected P&L'!H$10:H$115,'Historical & Projected P&L'!$C$10:$C$115,'CIM Output'!$C24) -> 81827.338
B25: Total Employee Salaries & Wages | D25: =SUM(D21:D24) -> 4230500 | E25: =SUM(E21:E24) -> 4495900 | F25: =SUM(F21:F24) -> 4788310.3 | G25: =SUM(G21:G24) -> 5520920.9 | H25: =SUM(H21:H24) -> 6090671.7
B27: Laboratory Fees | D27: =+SUMIFS('Historical & Projected P&L'!D$10:D$115,'Historical & Projected P&L'!$C$10:$C$115,'CIM Output'!$B27) -> 729800 | E27: =+SUMIFS('Historical & Projected P&L'!E$10:E$115,'Historical & Projected P&L'!$C$10:$C$115,'CIM Output'!$B27) -> 792200 | F27: =+SUMIFS('Historical & Projected P&L'!F$10:F$115,'Historical & Projected P&L'!$C$10:$C$115,'CIM Output'!$B27) -> 863135.37 | G27: =+SUMIFS('Historical & Projected P&L'!G$10:G$115,'Historical & Projected P&L'!$C$10:$C$115,'CIM Output'!$B27) -> 948396.08 | H27: =+SUMIFS('Historical & Projected P&L'!H$10:H$115,'Historical & Projected P&L'!$C$10:$C$115,'CIM Output'!$B27) -> 1106390.4
B28: Billing & Collection Fees | D28: =+SUMIFS('Historical & Projected P&L'!D$10:D$115,'Historical & Projected P&L'!$C$10:$C$115,'CIM Output'!$B28) -> 448300 | E28: =+SUMIFS('Historical & Projected P&L'!E$10:E$115,'Historical & Projected P&L'!$C$10:$C$115,'CIM Output'!$B28) -> 476000 | F28: =+SUMIFS('Historical & Projected P&L'!F$10:F$115,'Historical & Projected P&L'!$C$10:$C$115,'CIM Output'!$B28) -> 581873.31 | G28: =+SUMIFS('Historical & Projected P&L'!G$10:G$115,'Historical & Projected P&L'!$C$10:$C$115,'CIM Output'!$B28) -> 578131.86 | H28: =+SUMIFS('Historical & Projected P&L'!H$10:H$115,'Historical & Projected P&L'!$C$10:$C$115,'CIM Output'!$B28) -> 674443.48
B29: Total Employee Taxes & Benefits | D29: =+SUMIFS('Historical & Projected P&L'!D$10:D$115,'Historical & Projected P&L'!$C$10:$C$115,'CIM Output'!$B29) -> 522000 | E29: =+SUMIFS('Historical & Projected P&L'!E$10:E$115,'Historical & Projected P&L'!$C$10:$C$115,'CIM Output'!$B29) -> 549300 | F29: =+SUMIFS('Historical & Projected P&L'!F$10:F$115,'Historical & Projected P&L'!$C$10:$C$115,'CIM Output'!$B29) -> 592903.9 | G29: =+SUMIFS('Historical & Projected P&L'!G$10:G$115,'Historical & Projected P&L'!$C$10:$C$115,'CIM Output'!$B29) -> 682997.79 | H29: =+SUMIFS('Historical & Projected P&L'!H$10:H$115,'Historical & Projected P&L'!$C$10:$C$115,'CIM Output'!$B29) -> 753482.15
B30: Total Occupancy Costs | D30: =+SUMIFS('Historical & Projected P&L'!D$10:D$115,'Historical & Projected P&L'!$C$10:$C$115,'CIM Output'!$B30) -> 710400 | E30: =+SUMIFS('Historical & Projected P&L'!E$10:E$115,'Historical & Projected P&L'!$C$10:$C$115,'CIM Output'!$B30) -> 768100 | F30: =+SUMIFS('Historical & Projected P&L'!F$10:F$115,'Historical & Projected P&L'!$C$10:$C$115,'CIM Output'!$B30) -> 806806.72 | G30: =+SUMIFS('Historical & Projected P&L'!G$10:G$115,'Historical & Projected P&L'!$C$10:$C$115,'CIM Output'!$B30) -> 825178.33 | H30: =+SUMIFS('Historical & Projected P&L'!H$10:H$115,'Historical & Projected P&L'!$C$10:$C$115,'CIM Output'!$B30) -> 860510.82
B31: All Other Operating Expenses | D31: =+'Historical & Projected P&L'!D95-(D18+D25+SUM(D27:D30)) -> 1996400 | E31: =+'Historical & Projected P&L'!E95-(E18+E25+SUM(E27:E30)) -> 2143600 | F31: =+'Historical & Projected P&L'!F95-(F18+F25+SUM(F27:F30)) -> 2237574.7 | G31: =+'Historical & Projected P&L'!G95-(G18+G25+SUM(G27:G30)) -> 2357629.1 | H31: =+'Historical & Projected P&L'!H95-(H18+H25+SUM(H27:H30)) -> 2594093
B32: Total Operating Expenses | D32: =+D18+D25+SUM(D27:D31) -> 10218300 | E32: =+E18+E25+SUM(E27:E31) -> 10939200 | F32: =+F18+F25+SUM(F27:F31) -> 11731601 | G32: =+G18+G25+SUM(G27:G31) -> 12969195 | H32: =+H18+H25+SUM(H27:H31) -> 14478034 | J32: =+(F32/D32)^(1/(F$3-D$3))-1 -> 0.071492969 | K32: =+(H32/F32)^(1/(H$3-F$3))-1 -> 0.11090301
B33: check | D33: =+D32-'Historical & Projected P&L'!D95 -> 0 | E33: =+E32-'Historical & Projected P&L'!E95 -> 0 | F33: =+F32-'Historical & Projected P&L'!F95 -> 0 | G33: =+G32-'Historical & Projected P&L'!G95 -> 0 | H33: =+H32-'Historical & Projected P&L'!H95 -> 0
B34: % of Revenue | D34: =+IFERROR(D32/D9,) -> 0.80383735 | E34: =+IFERROR(E32/E9,) -> 0.79515025 | F34: =+IFERROR(F32/F9,) -> 0.78455886 | G34: =+IFERROR(G32/G9,) -> 0.79861251 | H34: =+IFERROR(H32/H9,) -> 0.76421231
B36: EBITDA, as adjusted | D36: =+D9-D32-SUMIFS('Historical & Projected P&L'!D$10:D$115,'Historical & Projected P&L'!$C$10:$C$115,"Non-Operating Expense / (Income)")+SUMIFS('Historical & Projected P&L'!D$10:D$115,'Historical & Projected P&L'!$C$10:$C$115,"Non-Operating Income / (Expense)") -> 2475500 | E36: =+E9-E32-SUMIFS('Historical & Projected P&L'!E$10:E$115,'Historical & Projected P&L'!$C$10:$C$115,"Non-Operating Expense / (Income)")+SUMIFS('Historical & Projected P&L'!E$10:E$115,'Historical & Projected P&L'!$C$10:$C$115,"Non-Operating Income / (Expense)") -> 2800700 | F36: =+F9-F32-SUMIFS('Historical & Projected P&L'!F$10:F$115,'Historical & Projected P&L'!$C$10:$C$115,"Non-Operating Expense / (Income)")+SUMIFS('Historical & Projected P&L'!F$10:F$115,'Historical & Projected P&L'!$C$10:$C$115,"Non-Operating Income / (Expense)") -> 3207266.8 | G36: =+G9-G32-SUMIFS('Historical & Projected P&L'!G$10:G$115,'Historical & Projected P&L'!$C$10:$C$115,"Non-Operating Expense / (Income)")+SUMIFS('Historical & Projected P&L'!G$10:G$115,'Historical & Projected P&L'!$C$10:$C$115,"Non-Operating Income / (Expense)") -> 3255118.4 | H36: =+H9-H32-SUMIFS('Historical & Projected P&L'!H$10:H$115,'Historical & Projected P&L'!$C$10:$C$115,"Non-Operating Expense / (Income)")+SUMIFS('Historical & Projected P&L'!H$10:H$115,'Historical & Projected P&L'!$C$10:$C$115,"Non-Operating Income / (Expense)") -> 4451004.9 | J36: =+(F36/D36)^(1/(F$3-D$3))-1 -> 0.13824587 | K36: =+(H36/F36)^(1/(H$3-F$3))-1 -> 0.17804393
B37: YoY % Growth | E37: =+IFERROR(E36/D36-1,) -> 0.1313674 | F37: =+IFERROR(F36/E36-1,) -> 0.14516615 | G37: =+IFERROR(G36/F36-1,) -> 0.014919732 | H37: =+IFERROR(H36/G36-1,) -> 0.36738647
B38: % Margin | D38: =+IFERROR(D36/D9,) -> 0.19473879 | E38: =+IFERROR(E36/E9,) -> 0.20357771 | F38: =+IFERROR(F36/F9,) -> 0.21448816 | G38: =+IFERROR(G36/G9,) -> 0.20044254 | H38: =+IFERROR(H36/H9,) -> 0.234943
B39: check | D39: =+D36-'Historical & Projected P&L'!D105 -> 0 | E39: =+E36-'Historical & Projected P&L'!E105 -> 0 | F39: =+F36-'Historical & Projected P&L'!F105 -> 0 | G39: =+G36-'Historical & Projected P&L'!G105 -> 0 | H39: =+H36-'Historical & Projected P&L'!H105 -> 0
B40: (1) 2024–Aug-26 per QoE databook; Sep–Nov-26 management reported; Dec-26 onward projected. EBITDA as adjusted is net of non-operating items.

Sheet Historical & Projected P&L
A2: Orivane Clinical Laboratories, LLC
A3: Adj. P&L
A4: Accrual Basis
C6: Fiscal year ending December 31,
J7: =+YEAR(J8) -> 2024 | K7: =+YEAR(K8) -> 2024 | L7: =+YEAR(L8) -> 2024 | M7: =+YEAR(M8) -> 2024 | N7: =+YEAR(N8) -> 2024 | O7: =+YEAR(O8) -> 2024 | P7: =+YEAR(P8) -> 2024 | Q7: =+YEAR(Q8) -> 2024 | ... BQ7: =+YEAR(BQ8) -> 2028
C8: $ in actual | D8: 2024 | E8: 2025 | F8: 2026 | G8: 2027 | H8: 2028 | J8: 45322 | K8: =+EOMONTH(J8,1) -> 45351 | L8: =+EOMONTH(K8,1) -> 45382 | M8: =+EOMONTH(L8,1) -> 45412 | N8: =+EOMONTH(M8,1) -> 45443 | O8: =+EOMONTH(N8,1) -> 45473 | P8: =+EOMONTH(O8,1) -> 45504 | Q8: =+EOMONTH(P8,1) -> 45535 | R8: =+EOMONTH(Q8,1) -> 45565 | ... BQ8: =+EOMONTH(BP8,1) -> 47118
A9: Adjusted P&L
A10: x | C10: Net Operating Revenue | D10: =+SUMIFS($J10:$BQ10,$J$7:$BQ$7,D$8) -> 12711900 | E10: =+SUMIFS($J10:$BQ10,$J$7:$BQ$7,E$8) -> 13757400 | F10: =+SUMIFS($J10:$BQ10,$J$7:$BQ$7,F$8) -> 14953118 | G10: =+SUMIFS($J10:$BQ10,$J$7:$BQ$7,G$8) -> 16239659 | H10: =+SUMIFS($J10:$BQ10,$J$7:$BQ$7,H$8) -> 18945041 | J10: =+'QoE PF Adj. P&L Aug-26'!D15*1000 -> 1059600 | K10: =+'QoE PF Adj. P&L Aug-26'!E15*1000 -> 957100 | L10: =+'QoE PF Adj. P&L Aug-26'!F15*1000 -> 1053300 | M10: =+'QoE PF Adj. P&L Aug-26'!G15*1000 -> 1024700 | N10: =+'QoE PF Adj. P&L Aug-26'!H15*1000 -> 1153100 | O10: =+'QoE PF Adj. P&L Aug-26'!I15*1000 -> 972600 | P10: =+'QoE PF Adj. P&L Aug-26'!J15*1000 -> 1073500 | Q10: =+'QoE PF Adj. P&L Aug-26'!K15*1000 -> 1097400 | ... AO10: =+'QoE PF Adj. P&L Aug-26'!AI15*1000 -> 1233000 | AP10: =+SUMIFS('Sep - Nov P&L'!I:I,'Sep - Nov P&L'!$D:$D,$C10) -> 1311360.1 | AQ10: =+SUMIFS('Sep - Nov P&L'!J:J,'Sep - Nov P&L'!$D:$D,$C10) -> 1394034.4 | AR10: =+SUMIFS('Sep - Nov P&L'!K:K,'Sep - Nov P&L'!$D:$D,$C10) -> 1183374 | AS10: =+'Revenue Build'!AR41 -> 1291349.8 | AT10: =+'Revenue Build'!AS41 -> 1179018.3 | AU10: =+'Revenue Build'!AT41 -> 1122852.5 | AV10: =+'Revenue Build'!AU41 -> 1326493.8 | AW10: =+'Revenue Build'!AV41 -> 1352253.8 | AX10: =+'Revenue Build'!AW41 -> 1258146.3 | AY10: =+'Revenue Build'!AX41 -> 1344727.6 | AZ10: =+'Revenue Build'!AY41 -> 1371375.2 | ... BQ10: =+'Revenue Build'!BP41 -> 1563044.9
C11: YoY % Growth | E11: =+IFERROR(E10/D10-1,) -> 0.08224577 | F11: =+IFERROR(F10/E10-1,) -> 0.086914554 | G11: =+IFERROR(G10/F10-1,) -> 0.086038284 | H11: =+IFERROR(H10/G10-1,) -> 0.16659109
C13: Operating Expenses
C14: Employee Salaries & Wages
C15: Salaries & Wages | D15: =+SUMIFS($J15:$BQ15,$J$7:$BQ$7,D$8) -> 3317600 | E15: =+SUMIFS($J15:$BQ15,$J$7:$BQ$7,E$8) -> 3509800 | F15: =+SUMIFS($J15:$BQ15,$J$7:$BQ$7,F$8) -> 3716855.6 | G15: =+SUMIFS($J15:$BQ15,$J$7:$BQ$7,G$8) -> 4327258.5 | H15: =+SUMIFS($J15:$BQ15,$J$7:$BQ$7,H$8) -> 4610459.6 | J15: =+INDEX('QoE PF Adj. P&L Aug-26'!$D$11:$AI$108,MATCH($C15,'QoE PF Adj. P&L Aug-26'!$C$11:$C$108,0),MATCH(J$8,'QoE PF Adj. P&L Aug-26'!$D$8:$AI$8,0))*1000 -> 277600 | K15: =+INDEX('QoE PF Adj. P&L Aug-26'!$D$11:$AI$108,MATCH($C15,'QoE PF Adj. P&L Aug-26'!$C$11:$C$108,0),MATCH(K$8,'QoE PF Adj. P&L Aug-26'!$D$8:$AI$8,0))*1000 -> 272100 | L15: =+INDEX('QoE PF Adj. P&L Aug-26'!$D$11:$AI$108,MATCH($C15,'QoE PF Adj. P&L Aug-26'!$C$11:$C$108,0),MATCH(L$8,'QoE PF Adj. P&L Aug-26'!$D$8:$AI$8,0))*1000 -> 278100 | M15: =+INDEX('QoE PF Adj. P&L Aug-26'!$D$11:$AI$108,MATCH($C15,'QoE PF Adj. P&L Aug-26'!$C$11:$C$108,0),MATCH(M$8,'QoE PF Adj. P&L Aug-26'!$D$8:$AI$8,0))*1000 -> 280500 | N15: =+INDEX('QoE PF Adj. P&L Aug-26'!$D$11:$AI$108,MATCH($C15,'QoE PF Adj. P&L Aug-26'!$C$11:$C$108,0),MATCH(N$8,'QoE PF Adj. P&L Aug-26'!$D$8:$AI$8,0))*1000 -> 274300 | O15: =+INDEX('QoE PF Adj. P&L Aug-26'!$D$11:$AI$108,MATCH($C15,'QoE PF Adj. P&L Aug-26'!$C$11:$C$108,0),MATCH(O$8,'QoE PF Adj. P&L Aug-26'!$D$8:$AI$8,0))*1000 -> 276000 | P15: =+INDEX('QoE PF Adj. P&L Aug-26'!$D$11:$AI$108,MATCH($C15,'QoE PF Adj. P&L Aug-26'!$C$11:$C$108,0),MATCH(P$8,'QoE PF Adj. P&L Aug-26'!$D$8:$AI$8,0))*1000 -> 277800 | Q15: =+INDEX('QoE PF Adj. P&L Aug-26'!$D$11:$AI$108,MATCH($C15,'QoE PF Adj. P&L Aug-26'!$C$11:$C$108,0),MATCH(Q$8,'QoE PF Adj. P&L Aug-26'!$D$8:$AI$8,0))*1000 -> 276200 | ... AO15: =+INDEX('QoE PF Adj. P&L Aug-26'!$D$11:$AI$108,MATCH($C15,'QoE PF Adj. P&L Aug-26'!$C$11:$C$108,0),MATCH(AO$8,'QoE PF Adj. P&L Aug-26'!$D$8:$AI$8,0))*1000 -> 308500 | AP15: =+'Separate Line Item Builds'!AP61 -> 310028.94 | AQ15: =+'Separate Line Item Builds'!AQ61 -> 314092.79 | AR15: =+'Separate Line Item Builds'!AR61 -> 309783.59 | AS15: =+'Separate Line Item Builds'!AS61 -> 326450.26 | AT15: =+'Separate Line Item Builds'!AT61 -> 323243.77 | AU15: =+'Separate Line Item Builds'!AU61 -> 340743.77 | AV15: =+'Separate Line Item Builds'!AV61 -> 361993.77 | AW15: =+'Separate Line Item Builds'!AW61 -> 361993.77 | ... BQ15: =+'Separate Line Item Builds'!BQ61 -> 384566.08
B16: % rev | C16: Contract Labor | D16: =+SUMIFS($J16:$BQ16,$J$7:$BQ$7,D$8) -> 187900 | E16: =+SUMIFS($J16:$BQ16,$J$7:$BQ$7,E$8) -> 205500 | F16: =+SUMIFS($J16:$BQ16,$J$7:$BQ$7,F$8) -> 249542.07 | G16: =+SUMIFS($J16:$BQ16,$J$7:$BQ$7,G$8) -> 241970.92 | H16: =+SUMIFS($J16:$BQ16,$J$7:$BQ$7,H$8) -> 282281.12 | J16: =+INDEX('QoE PF Adj. P&L Aug-26'!$D$11:$AI$108,MATCH($C16,'QoE PF Adj. P&L Aug-26'!$C$11:$C$108,0),MATCH(J$8,'QoE PF Adj. P&L Aug-26'!$D$8:$AI$8,0))*1000 -> 15500 | K16: =+INDEX('QoE PF Adj. P&L Aug-26'!$D$11:$AI$108,MATCH($C16,'QoE PF Adj. P&L Aug-26'!$C$11:$C$108,0),MATCH(K$8,'QoE PF Adj. P&L Aug-26'!$D$8:$AI$8,0))*1000 -> 14300 | L16: =+INDEX('QoE PF Adj. P&L Aug-26'!$D$11:$AI$108,MATCH($C16,'QoE PF Adj. P&L Aug-26'!$C$11:$C$108,0),MATCH(L$8,'QoE PF Adj. P&L Aug-26'!$D$8:$AI$8,0))*1000 -> 15100 | M16: =+INDEX('QoE PF Adj. P&L Aug-26'!$D$11:$AI$108,MATCH($C16,'QoE PF Adj. P&L Aug-26'!$C$11:$C$108,0),MATCH(M$8,'QoE PF Adj. P&L Aug-26'!$D$8:$AI$8,0))*1000 -> 15400 | N16: =+INDEX('QoE PF Adj. P&L Aug-26'!$D$11:$AI$108,MATCH($C16,'QoE PF Adj. P&L Aug-26'!$C$11:$C$108,0),MATCH(N$8,'QoE PF Adj. P&L Aug-26'!$D$8:$AI$8,0))*1000 -> 16500 | O16: =+INDEX('QoE PF Adj. P&L Aug-26'!$D$11:$AI$108,MATCH($C16,'QoE PF Adj. P&L Aug-26'!$C$11:$C$108,0),MATCH(O$8,'QoE PF Adj. P&L Aug-26'!$D$8:$AI$8,0))*1000 -> 14800 | P16: =+INDEX('QoE PF Adj. P&L Aug-26'!$D$11:$AI$108,MATCH($C16,'QoE PF Adj. P&L Aug-26'!$C$11:$C$108,0),MATCH(P$8,'QoE PF Adj. P&L Aug-26'!$D$8:$AI$8,0))*1000 -> 15700 | Q16: =+INDEX('QoE PF Adj. P&L Aug-26'!$D$11:$AI$108,MATCH($C16,'QoE PF Adj. P&L Aug-26'!$C$11:$C$108,0),MATCH(Q$8,'QoE PF Adj. P&L Aug-26'!$D$8:$AI$8,0))*1000 -> 17000 | ... AO16: =+INDEX('QoE PF Adj. P&L Aug-26'!$D$11:$AI$108,MATCH($C16,'QoE PF Adj. P&L Aug-26'!$C$11:$C$108,0),MATCH(AO$8,'QoE PF Adj. P&L Aug-26'!$D$8:$AI$8,0))*1000 -> 18500 | AP16: =+SUMIFS('Sep - Nov P&L'!I:I,'Sep - Nov P&L'!$D:$D,$C16) -> 29625.63 | AQ16: =+SUMIFS('Sep - Nov P&L'!J:J,'Sep - Nov P&L'!$D:$D,$C16) -> 30177.2 | AR16: =+SUMIFS('Sep - Nov P&L'!K:K,'Sep - Nov P&L'!$D:$D,$C16) -> 26298.13 | AS16: =+AS$10*AS124 -> 19241.113 | AT16: =+AT$10*AT124 -> 17567.372 | AU16: =+AU$10*AU124 -> 16730.502 | AV16: =+AV$10*AV124 -> 19764.758 | AW16: =+AW$10*AW124 -> 20148.582 | AX16: =+AX$10*AX124 -> 18746.379 | AY16: =+AY$10*AY124 -> 20036.441 | AZ16: =+AZ$10*AZ124 -> 20433.49 | ... BQ16: =+BQ$10*BQ124 -> 23289.369
C17: Sales Rep Expense | D17: =+SUMIFS($J17:$BQ17,$J$7:$BQ$7,D$8) -> 636600 | E17: =+SUMIFS($J17:$BQ17,$J$7:$BQ$7,E$8) -> 684700 | F17: =+SUMIFS($J17:$BQ17,$J$7:$BQ$7,F$8) -> 747121.01 | G17: =+SUMIFS($J17:$BQ17,$J$7:$BQ$7,G$8) -> 873223.9 | H17: =+SUMIFS($J17:$BQ17,$J$7:$BQ$7,H$8) -> 1116103.7 | J17: =+INDEX('QoE PF Adj. P&L Aug-26'!$D$11:$AI$108,MATCH($C17,'QoE PF Adj. P&L Aug-26'!$C$11:$C$108,0),MATCH(J$8,'QoE PF Adj. P&L Aug-26'!$D$8:$AI$8,0))*1000 -> 51700 | K17: =+INDEX('QoE PF Adj. P&L Aug-26'!$D$11:$AI$108,MATCH($C17,'QoE PF Adj. P&L Aug-26'!$C$11:$C$108,0),MATCH(K$8,'QoE PF Adj. P&L Aug-26'!$D$8:$AI$8,0))*1000 -> 48600 | L17: =+INDEX('QoE PF Adj. P&L Aug-26'!$D$11:$AI$108,MATCH($C17,'QoE PF Adj. P&L Aug-26'!$C$11:$C$108,0),MATCH(L$8,'QoE PF Adj. P&L Aug-26'!$D$8:$AI$8,0))*1000 -> 53100 | M17: =+INDEX('QoE PF Adj. P&L Aug-26'!$D$11:$AI$108,MATCH($C17,'QoE PF Adj. P&L Aug-26'!$C$11:$C$108,0),MATCH(M$8,'QoE PF Adj. P&L Aug-26'!$D$8:$AI$8,0))*1000 -> 52300 | N17: =+INDEX('QoE PF Adj. P&L Aug-26'!$D$11:$AI$108,MATCH($C17,'QoE PF Adj. P&L Aug-26'!$C$11:$C$108,0),MATCH(N$8,'QoE PF Adj. P&L Aug-26'!$D$8:$AI$8,0))*1000 -> 57500 | O17: =+INDEX('QoE PF Adj. P&L Aug-26'!$D$11:$AI$108,MATCH($C17,'QoE PF Adj. P&L Aug-26'!$C$11:$C$108,0),MATCH(O$8,'QoE PF Adj. P&L Aug-26'!$D$8:$AI$8,0))*1000 -> 50200 | P17: =+INDEX('QoE PF Adj. P&L Aug-26'!$D$11:$AI$108,MATCH($C17,'QoE PF Adj. P&L Aug-26'!$C$11:$C$108,0),MATCH(P$8,'QoE PF Adj. P&L Aug-26'!$D$8:$AI$8,0))*1000 -> 54400 | Q17: =+INDEX('QoE PF Adj. P&L Aug-26'!$D$11:$AI$108,MATCH($C17,'QoE PF Adj. P&L Aug-26'!$C$11:$C$108,0),MATCH(Q$8,'QoE PF Adj. P&L Aug-26'!$D$8:$AI$8,0))*1000 -> 56300 | ... AO17: =+INDEX('QoE PF Adj. P&L Aug-26'!$D$11:$AI$108,MATCH($C17,'QoE PF Adj. P&L Aug-26'!$C$11:$C$108,0),MATCH(AO$8,'QoE PF Adj. P&L Aug-26'!$D$8:$AI$8,0))*1000 -> 63300 | AP17: =+SUMIFS('Sep - Nov P&L'!I:I,'Sep - Nov P&L'!$D:$D,$C17) -> 63206.61 | AQ17: =+SUMIFS('Sep - Nov P&L'!J:J,'Sep - Nov P&L'!$D:$D,$C17) -> 69262.96 | AR17: =+SUMIFS('Sep - Nov P&L'!K:K,'Sep - Nov P&L'!$D:$D,$C17) -> 59675.72 | AS17: =+'Separate Line Item Builds'!AS35 -> 59675.72 | AT17: =+'Separate Line Item Builds'!AT35 -> 61465.992 | AU17: =+'Separate Line Item Builds'!AU35 -> 61465.992 | AV17: =+'Separate Line Item Builds'!AV35 -> 64041.992 | AW17: =+'Separate Line Item Builds'!AW35 -> 66617.992 | AX17: =+'Separate Line Item Builds'!AX35 -> 68521.992 | AY17: =+'Separate Line Item Builds'!AY35 -> 71321.992 | AZ17: =+'Separate Line Item Builds'!AZ35 -> 73785.992 | ... BQ17: =+'Separate Line Item Builds'!BQ35 -> 92877.971
C18: Other Personnel Costs | D18: =+SUMIFS($J18:$BQ18,$J$7:$BQ$7,D$8) -> 88400 | E18: =+SUMIFS($J18:$BQ18,$J$7:$BQ$7,E$8) -> 95900 | F18: =+SUMIFS($J18:$BQ18,$J$7:$BQ$7,F$8) -> 74791.667 | G18: =+SUMIFS($J18:$BQ18,$J$7:$BQ$7,G$8) -> 78467.515 | H18: =+SUMIFS($J18:$BQ18,$J$7:$BQ$7,H$8) -> 81827.338 | J18: =+INDEX('QoE PF Adj. P&L Aug-26'!$D$11:$AI$108,MATCH($C18,'QoE PF Adj. P&L Aug-26'!$C$11:$C$108,0),MATCH(J$8,'QoE PF Adj. P&L Aug-26'!$D$8:$AI$8,0))*1000 -> 7100 | K18: =+INDEX('QoE PF Adj. P&L Aug-26'!$D$11:$AI$108,MATCH($C18,'QoE PF Adj. P&L Aug-26'!$C$11:$C$108,0),MATCH(K$8,'QoE PF Adj. P&L Aug-26'!$D$8:$AI$8,0))*1000 -> 7000 | L18: =+INDEX('QoE PF Adj. P&L Aug-26'!$D$11:$AI$108,MATCH($C18,'QoE PF Adj. P&L Aug-26'!$C$11:$C$108,0),MATCH(L$8,'QoE PF Adj. P&L Aug-26'!$D$8:$AI$8,0))*1000 -> 7700 | M18: =+INDEX('QoE PF Adj. P&L Aug-26'!$D$11:$AI$108,MATCH($C18,'QoE PF Adj. P&L Aug-26'!$C$11:$C$108,0),MATCH(M$8,'QoE PF Adj. P&L Aug-26'!$D$8:$AI$8,0))*1000 -> 7100 | N18: =+INDEX('QoE PF Adj. P&L Aug-26'!$D$11:$AI$108,MATCH($C18,'QoE PF Adj. P&L Aug-26'!$C$11:$C$108,0),MATCH(N$8,'QoE PF Adj. P&L Aug-26'!$D$8:$AI$8,0))*1000 -> 7000 | O18: =+INDEX('QoE PF Adj. P&L Aug-26'!$D$11:$AI$108,MATCH($C18,'QoE PF Adj. P&L Aug-26'!$C$11:$C$108,0),MATCH(O$8,'QoE PF Adj. P&L Aug-26'!$D$8:$AI$8,0))*1000 -> 7400 | P18: =+INDEX('QoE PF Adj. P&L Aug-26'!$D$11:$AI$108,MATCH($C18,'QoE PF Adj. P&L Aug-26'!$C$11:$C$108,0),MATCH(P$8,'QoE PF Adj. P&L Aug-26'!$D$8:$AI$8,0))*1000 -> 7400 | Q18: =+INDEX('QoE PF Adj. P&L Aug-26'!$D$11:$AI$108,MATCH($C18,'QoE PF Adj. P&L Aug-26'!$C$11:$C$108,0),MATCH(Q$8,'QoE PF Adj. P&L Aug-26'!$D$8:$AI$8,0))*1000 -> 7500 | ... AO18: =+INDEX('QoE PF Adj. P&L Aug-26'!$D$11:$AI$108,MATCH($C18,'QoE PF Adj. P&L Aug-26'!$C$11:$C$108,0),MATCH(AO$8,'QoE PF Adj. P&L Aug-26'!$D$8:$AI$8,0))*1000 -> 9300 | AP18: =+SUMIFS('Sep - Nov P&L'!I:I,'Sep - Nov P&L'!$D:$D,$C18) -> 0 | AQ18: =+SUMIFS('Sep - Nov P&L'!J:J,'Sep - Nov P&L'!$D:$D,$C18) -> 0 | AR18: =+SUMIFS('Sep - Nov P&L'!K:K,'Sep - Nov P&L'!$D:$D,$C18) -> 0 | AS18: =+AS126 -> 6391.6667 | AT18: =+AT126 -> 6414.0375 | AU18: =+AU126 -> 6436.4866 | AV18: =+AV126 -> 6459.0143 | AW18: =+AW126 -> 6481.6209 | AX18: =+AX126 -> 6504.3066 | AY18: =+AY126 -> 6527.0716 | AZ18: =+AZ126 -> 6549.9164 | ... BQ18: =+BQ126 -> 6950.7419
C19: Total Employee Salaries & Wages | D19: =+SUMIFS($J19:$BQ19,$J$7:$BQ$7,D$8) -> 4230500 | E19: =+SUMIFS($J19:$BQ19,$J$7:$BQ$7,E$8) -> 4495900 | F19: =+SUMIFS($J19:$BQ19,$J$7:$BQ$7,F$8) -> 4788310.3 | G19: =+SUMIFS($J19:$BQ19,$J$7:$BQ$7,G$8) -> 5520920.9 | H19: =+SUMIFS($J19:$BQ19,$J$7:$BQ$7,H$8) -> 6090671.7 | J19: =SUM(J15:J18) -> 351900 | K19: =SUM(K15:K18) -> 342000 | L19: =SUM(L15:L18) -> 354000 | M19: =SUM(M15:M18) -> 355300 | N19: =SUM(N15:N18) -> 355300 | O19: =SUM(O15:O18) -> 348400 | P19: =SUM(P15:P18) -> 355300 | Q19: =SUM(Q15:Q18) -> 357000 | ... BQ19: =SUM(BQ15:BQ18) -> 507684.16
C21: Employee Taxes & Benefits
C22: Payroll Taxes | D22: =+SUMIFS($J22:$BQ22,$J$7:$BQ$7,D$8) -> 266000 | E22: =+SUMIFS($J22:$BQ22,$J$7:$BQ$7,E$8) -> 279200 | F22: =+SUMIFS($J22:$BQ22,$J$7:$BQ$7,F$8) -> 304828.26 | G22: =+SUMIFS($J22:$BQ22,$J$7:$BQ$7,G$8) -> 351065.62 | H22: =+SUMIFS($J22:$BQ22,$J$7:$BQ$7,H$8) -> 387295.07 | J22: =+INDEX('QoE PF Adj. P&L Aug-26'!$D$11:$AI$108,MATCH($C22,'QoE PF Adj. P&L Aug-26'!$C$11:$C$108,0),MATCH(J$8,'QoE PF Adj. P&L Aug-26'!$D$8:$AI$8,0))*1000 -> 22600 | K22: =+INDEX('QoE PF Adj. P&L Aug-26'!$D$11:$AI$108,MATCH($C22,'QoE PF Adj. P&L Aug-26'!$C$11:$C$108,0),MATCH(K$8,'QoE PF Adj. P&L Aug-26'!$D$8:$AI$8,0))*1000 -> 22300 | L22: =+INDEX('QoE PF Adj. P&L Aug-26'!$D$11:$AI$108,MATCH($C22,'QoE PF Adj. P&L Aug-26'!$C$11:$C$108,0),MATCH(L$8,'QoE PF Adj. P&L Aug-26'!$D$8:$AI$8,0))*1000 -> 22000 | M22: =+INDEX('QoE PF Adj. P&L Aug-26'!$D$11:$AI$108,MATCH($C22,'QoE PF Adj. P&L Aug-26'!$C$11:$C$108,0),MATCH(M$8,'QoE PF Adj. P&L Aug-26'!$D$8:$AI$8,0))*1000 -> 22200 | N22: =+INDEX('QoE PF Adj. P&L Aug-26'!$D$11:$AI$108,MATCH($C22,'QoE PF Adj. P&L Aug-26'!$C$11:$C$108,0),MATCH(N$8,'QoE PF Adj. P&L Aug-26'!$D$8:$AI$8,0))*1000 -> 21300 | O22: =+INDEX('QoE PF Adj. P&L Aug-26'!$D$11:$AI$108,MATCH($C22,'QoE PF Adj. P&L Aug-26'!$C$11:$C$108,0),MATCH(O$8,'QoE PF Adj. P&L Aug-26'!$D$8:$AI$8,0))*1000 -> 22000 | P22: =+INDEX('QoE PF Adj. P&L Aug-26'!$D$11:$AI$108,MATCH($C22,'QoE PF Adj. P&L Aug-26'!$C$11:$C$108,0),MATCH(P$8,'QoE PF Adj. P&L Aug-26'!$D$8:$AI$8,0))*1000 -> 22500 | Q22: =+INDEX('QoE PF Adj. P&L Aug-26'!$D$11:$AI$108,MATCH($C22,'QoE PF Adj. P&L Aug-26'!$C$11:$C$108,0),MATCH(Q$8,'QoE PF Adj. P&L Aug-26'!$D$8:$AI$8,0))*1000 -> 21700 | ... AO22: =+INDEX('QoE PF Adj. P&L Aug-26'!$D$11:$AI$108,MATCH($C22,'QoE PF Adj. P&L Aug-26'!$C$11:$C$108,0),MATCH(AO$8,'QoE PF Adj. P&L Aug-26'!$D$8:$AI$8,0))*1000 -> 24600 | AP22: =+'Separate Line Item Builds'!AP62+SUMIFS('Sep - Nov P&L'!I:I,'Sep - Nov P&L'!$D:$D,$C22) -> 27311.904 | AQ22: =+'Separate Line Item Builds'!AQ62+SUMIFS('Sep - Nov P&L'!J:J,'Sep - Nov P&L'!$D:$D,$C22) -> 27642.963 | AR22: =+'Separate Line Item Builds'!AR62+SUMIFS('Sep - Nov P&L'!K:K,'Sep - Nov P&L'!$D:$D,$C22) -> 27290.378 | AS22: =+AS$19*AS130 -> 26183.013 | AT22: =+AT$19*AT130 -> 25987.951 | AU22: =+AU$19*AU130 -> 27048.957 | AV22: =+AV$19*AV130 -> 28758.386 | AW22: =+AW$19*AW130 -> 28948.034 | AX22: =+AX$19*AX130 -> 28981.384 | AY22: =+AY$19*AY130 -> 29518.461 | AZ22: =+AZ$19*AZ130 -> 29701.843 | ... BQ22: =+BQ$19*BQ130 -> 32282.741
C23: Employee Benefits | D23: =+SUMIFS($J23:$BQ23,$J$7:$BQ$7,D$8) -> 199300 | E23: =+SUMIFS($J23:$BQ23,$J$7:$BQ$7,E$8) -> 210500 | F23: =+SUMIFS($J23:$BQ23,$J$7:$BQ$7,F$8) -> 237778.87 | G23: =+SUMIFS($J23:$BQ23,$J$7:$BQ$7,G$8) -> 272626.67 | H23: =+SUMIFS($J23:$BQ23,$J$7:$BQ$7,H$8) -> 300761.34 | J23: =+INDEX('QoE PF Adj. P&L Aug-26'!$D$11:$AI$108,MATCH($C23,'QoE PF Adj. P&L Aug-26'!$C$11:$C$108,0),MATCH(J$8,'QoE PF Adj. P&L Aug-26'!$D$8:$AI$8,0))*1000 -> 16900 | K23: =+INDEX('QoE PF Adj. P&L Aug-26'!$D$11:$AI$108,MATCH($C23,'QoE PF Adj. P&L Aug-26'!$C$11:$C$108,0),MATCH(K$8,'QoE PF Adj. P&L Aug-26'!$D$8:$AI$8,0))*1000 -> 16600 | L23: =+INDEX('QoE PF Adj. P&L Aug-26'!$D$11:$AI$108,MATCH($C23,'QoE PF Adj. P&L Aug-26'!$C$11:$C$108,0),MATCH(L$8,'QoE PF Adj. P&L Aug-26'!$D$8:$AI$8,0))*1000 -> 16400 | M23: =+INDEX('QoE PF Adj. P&L Aug-26'!$D$11:$AI$108,MATCH($C23,'QoE PF Adj. P&L Aug-26'!$C$11:$C$108,0),MATCH(M$8,'QoE PF Adj. P&L Aug-26'!$D$8:$AI$8,0))*1000 -> 17100 | N23: =+INDEX('QoE PF Adj. P&L Aug-26'!$D$11:$AI$108,MATCH($C23,'QoE PF Adj. P&L Aug-26'!$C$11:$C$108,0),MATCH(N$8,'QoE PF Adj. P&L Aug-26'!$D$8:$AI$8,0))*1000 -> 16200 | O23: =+INDEX('QoE PF Adj. P&L Aug-26'!$D$11:$AI$108,MATCH($C23,'QoE PF Adj. P&L Aug-26'!$C$11:$C$108,0),MATCH(O$8,'QoE PF Adj. P&L Aug-26'!$D$8:$AI$8,0))*1000 -> 17000 | P23: =+INDEX('QoE PF Adj. P&L Aug-26'!$D$11:$AI$108,MATCH($C23,'QoE PF Adj. P&L Aug-26'!$C$11:$C$108,0),MATCH(P$8,'QoE PF Adj. P&L Aug-26'!$D$8:$AI$8,0))*1000 -> 16500 | Q23: =+INDEX('QoE PF Adj. P&L Aug-26'!$D$11:$AI$108,MATCH($C23,'QoE PF Adj. P&L Aug-26'!$C$11:$C$108,0),MATCH(Q$8,'QoE PF Adj. P&L Aug-26'!$D$8:$AI$8,0))*1000 -> 16700 | ... AO23: =+INDEX('QoE PF Adj. P&L Aug-26'!$D$11:$AI$108,MATCH($C23,'QoE PF Adj. P&L Aug-26'!$C$11:$C$108,0),MATCH(AO$8,'QoE PF Adj. P&L Aug-26'!$D$8:$AI$8,0))*1000 -> 18800 | AP23: =+SUMIFS('Sep - Nov P&L'!I:I,'Sep - Nov P&L'!$D:$D,$C23) -> 23121.22 | AQ23: =+SUMIFS('Sep - Nov P&L'!J:J,'Sep - Nov P&L'!$D:$D,$C23) -> 23283.72 | AR23: =+SUMIFS('Sep - Nov P&L'!K:K,'Sep - Nov P&L'!$D:$D,$C23) -> 23241.01 | AS23: =+AS$19*AS131 -> 20332.916 | AT23: =+AT$19*AT131 -> 20181.436 | AU23: =+AU$19*AU131 -> 21005.381 | AV23: =+AV$19*AV131 -> 22332.87 | AW23: =+AW$19*AW131 -> 22480.145 | AX23: =+AX$19*AX131 -> 22506.044 | AY23: =+AY$19*AY131 -> 22923.121 | AZ23: =+AZ$19*AZ131 -> 23065.529 | ... BQ23: =+BQ$19*BQ131 -> 25069.775
C24: Pension Plans | D24: =+SUMIFS($J24:$BQ24,$J$7:$BQ$7,D$8) -> 33600 | E24: =+SUMIFS($J24:$BQ24,$J$7:$BQ$7,E$8) -> 34800 | F24: =+SUMIFS($J24:$BQ24,$J$7:$BQ$7,F$8) -> 26891.197 | G24: =+SUMIFS($J24:$BQ24,$J$7:$BQ$7,G$8) -> 32061.512 | H24: =+SUMIFS($J24:$BQ24,$J$7:$BQ$7,H$8) -> 35370.212 | J24: =+INDEX('QoE PF Adj. P&L Aug-26'!$D$11:$AI$108,MATCH($C24,'QoE PF Adj. P&L Aug-26'!$C$11:$C$108,0),MATCH(J$8,'QoE PF Adj. P&L Aug-26'!$D$8:$AI$8,0))*1000 -> 2800 | K24: =+INDEX('QoE PF Adj. P&L Aug-26'!$D$11:$AI$108,MATCH($C24,'QoE PF Adj. P&L Aug-26'!$C$11:$C$108,0),MATCH(K$8,'QoE PF Adj. P&L Aug-26'!$D$8:$AI$8,0))*1000 -> 2800 | L24: =+INDEX('QoE PF Adj. P&L Aug-26'!$D$11:$AI$108,MATCH($C24,'QoE PF Adj. P&L Aug-26'!$C$11:$C$108,0),MATCH(L$8,'QoE PF Adj. P&L Aug-26'!$D$8:$AI$8,0))*1000 -> 2800 | M24: =+INDEX('QoE PF Adj. P&L Aug-26'!$D$11:$AI$108,MATCH($C24,'QoE PF Adj. P&L Aug-26'!$C$11:$C$108,0),MATCH(M$8,'QoE PF Adj. P&L Aug-26'!$D$8:$AI$8,0))*1000 -> 2900 | N24: =+INDEX('QoE PF Adj. P&L Aug-26'!$D$11:$AI$108,MATCH($C24,'QoE PF Adj. P&L Aug-26'!$C$11:$C$108,0),MATCH(N$8,'QoE PF Adj. P&L Aug-26'!$D$8:$AI$8,0))*1000 -> 2700 | O24: =+INDEX('QoE PF Adj. P&L Aug-26'!$D$11:$AI$108,MATCH($C24,'QoE PF Adj. P&L Aug-26'!$C$11:$C$108,0),MATCH(O$8,'QoE PF Adj. P&L Aug-26'!$D$8:$AI$8,0))*1000 -> 2800 | P24: =+INDEX('QoE PF Adj. P&L Aug-26'!$D$11:$AI$108,MATCH($C24,'QoE PF Adj. P&L Aug-26'!$C$11:$C$108,0),MATCH(P$8,'QoE PF Adj. P&L Aug-26'!$D$8:$AI$8,0))*1000 -> 2800 | Q24: =+INDEX('QoE PF Adj. P&L Aug-26'!$D$11:$AI$108,MATCH($C24,'QoE PF Adj. P&L Aug-26'!$C$11:$C$108,0),MATCH(Q$8,'QoE PF Adj. P&L Aug-26'!$D$8:$AI$8,0))*1000 -> 2800 | ... AO24: =+INDEX('QoE PF Adj. P&L Aug-26'!$D$11:$AI$108,MATCH($C24,'QoE PF Adj. P&L Aug-26'!$C$11:$C$108,0),MATCH(AO$8,'QoE PF Adj. P&L Aug-26'!$D$8:$AI$8,0))*1000 -> 3100 | AP24: =+SUMIFS('Sep - Nov P&L'!I:I,'Sep - Nov P&L'!$D:$D,$C24) -> 0 | AQ24: =+SUMIFS('Sep - Nov P&L'!J:J,'Sep - Nov P&L'!$D:$D,$C24) -> 0 | AR24: =+SUMIFS('Sep - Nov P&L'!K:K,'Sep - Nov P&L'!$D:$D,$C24) -> 0 | AS24: =+AS$19*AS132 -> 2391.1968 | AT24: =+AT$19*AT132 -> 2373.3825 | AU24: =+AU$19*AU132 -> 2470.2802 | AV24: =+AV$19*AV132 -> 2626.396 | AW24: =+AW$19*AW132 -> 2643.7158 | AX24: =+AX$19*AX132 -> 2646.7616 | AY24: =+AY$19*AY132 -> 2695.8108 | AZ24: =+AZ$19*AZ132 -> 2712.5583 | ... BQ24: =+BQ$19*BQ132 -> 2948.2621
C25: Other Personnel Expenses | D25: =+SUMIFS($J25:$BQ25,$J$7:$BQ$7,D$8) -> 9800 | E25: =+SUMIFS($J25:$BQ25,$J$7:$BQ$7,E$8) -> 10700 | F25: =+SUMIFS($J25:$BQ25,$J$7:$BQ$7,F$8) -> 7904.4149 | G25: =+SUMIFS($J25:$BQ25,$J$7:$BQ$7,G$8) -> 9444.8966 | H25: =+SUMIFS($J25:$BQ25,$J$7:$BQ$7,H$8) -> 10419.596 | J25: =+INDEX('QoE PF Adj. P&L Aug-26'!$D$11:$AI$108,MATCH($C25,'QoE PF Adj. P&L Aug-26'!$C$11:$C$108,0),MATCH(J$8,'QoE PF Adj. P&L Aug-26'!$D$8:$AI$8,0))*1000 -> 900 | K25: =+INDEX('QoE PF Adj. P&L Aug-26'!$D$11:$AI$108,MATCH($C25,'QoE PF Adj. P&L Aug-26'!$C$11:$C$108,0),MATCH(K$8,'QoE PF Adj. P&L Aug-26'!$D$8:$AI$8,0))*1000 -> 800 | L25: =+INDEX('QoE PF Adj. P&L Aug-26'!$D$11:$AI$108,MATCH($C25,'QoE PF Adj. P&L Aug-26'!$C$11:$C$108,0),MATCH(L$8,'QoE PF Adj. P&L Aug-26'!$D$8:$AI$8,0))*1000 -> 800 | M25: =+INDEX('QoE PF Adj. P&L Aug-26'!$D$11:$AI$108,MATCH($C25,'QoE PF Adj. P&L Aug-26'!$C$11:$C$108,0),MATCH(M$8,'QoE PF Adj. P&L Aug-26'!$D$8:$AI$8,0))*1000 -> 900 | N25: =+INDEX('QoE PF Adj. P&L Aug-26'!$D$11:$AI$108,MATCH($C25,'QoE PF Adj. P&L Aug-26'!$C$11:$C$108,0),MATCH(N$8,'QoE PF Adj. P&L Aug-26'!$D$8:$AI$8,0))*1000 -> 800 | O25: =+INDEX('QoE PF Adj. P&L Aug-26'!$D$11:$AI$108,MATCH($C25,'QoE PF Adj. P&L Aug-26'!$C$11:$C$108,0),MATCH(O$8,'QoE PF Adj. P&L Aug-26'!$D$8:$AI$8,0))*1000 -> 800 | P25: =+INDEX('QoE PF Adj. P&L Aug-26'!$D$11:$AI$108,MATCH($C25,'QoE PF Adj. P&L Aug-26'!$C$11:$C$108,0),MATCH(P$8,'QoE PF Adj. P&L Aug-26'!$D$8:$AI$8,0))*1000 -> 800 | Q25: =+INDEX('QoE PF Adj. P&L Aug-26'!$D$11:$AI$108,MATCH($C25,'QoE PF Adj. P&L Aug-26'!$C$11:$C$108,0),MATCH(Q$8,'QoE PF Adj. P&L Aug-26'!$D$8:$AI$8,0))*1000 -> 800 | ... AO25: =+INDEX('QoE PF Adj. P&L Aug-26'!$D$11:$AI$108,MATCH($C25,'QoE PF Adj. P&L Aug-26'!$C$11:$C$108,0),MATCH(AO$8,'QoE PF Adj. P&L Aug-26'!$D$8:$AI$8,0))*1000 -> 900 | AP25: =+SUMIFS('Sep - Nov P&L'!I:I,'Sep - Nov P&L'!$D:$D,$C25) -> 0 | AQ25: =+SUMIFS('Sep - Nov P&L'!J:J,'Sep - Nov P&L'!$D:$D,$C25) -> 0 | AR25: =+SUMIFS('Sep - Nov P&L'!K:K,'Sep - Nov P&L'!$D:$D,$C25) -> 0 | AS25: =+AS$19*AS133 -> 704.4149 | AT25: =+AT$19*AT133 -> 699.16703 | AU25: =+AU$19*AU133 -> 727.71182 | AV25: =+AV$19*AV133 -> 773.70146 | AW25: =+AW$19*AW133 -> 778.80364 | AX25: =+AX$19*AX133 -> 779.7009 | AY25: =+AY$19*AY133 -> 794.15014 | AZ25: =+AZ$19*AZ133 -> 799.08375 | ... BQ25: =+BQ$19*BQ133 -> 868.51895
C26: Payroll Processing Fee | D26: =+SUMIFS($J26:$BQ26,$J$7:$BQ$7,D$8) -> 13300 | E26: =+SUMIFS($J26:$BQ26,$J$7:$BQ$7,E$8) -> 14100 | F26: =+SUMIFS($J26:$BQ26,$J$7:$BQ$7,F$8) -> 15501.161 | G26: =+SUMIFS($J26:$BQ26,$J$7:$BQ$7,G$8) -> 17799.087 | H26: =+SUMIFS($J26:$BQ26,$J$7:$BQ$7,H$8) -> 19635.926 | J26: =+INDEX('QoE PF Adj. P&L Aug-26'!$D$11:$AI$108,MATCH($C26,'QoE PF Adj. P&L Aug-26'!$C$11:$C$108,0),MATCH(J$8,'QoE PF Adj. P&L Aug-26'!$D$8:$AI$8,0))*1000 -> 1100 | K26: =+INDEX('QoE PF Adj. P&L Aug-26'!$D$11:$AI$108,MATCH($C26,'QoE PF Adj. P&L Aug-26'!$C$11:$C$108,0),MATCH(K$8,'QoE PF Adj. P&L Aug-26'!$D$8:$AI$8,0))*1000 -> 1100 | L26: =+INDEX('QoE PF Adj. P&L Aug-26'!$D$11:$AI$108,MATCH($C26,'QoE PF Adj. P&L Aug-26'!$C$11:$C$108,0),MATCH(L$8,'QoE PF Adj. P&L Aug-26'!$D$8:$AI$8,0))*1000 -> 1100 | M26: =+INDEX('QoE PF Adj. P&L Aug-26'!$D$11:$AI$108,MATCH($C26,'QoE PF Adj. P&L Aug-26'!$C$11:$C$108,0),MATCH(M$8,'QoE PF Adj. P&L Aug-26'!$D$8:$AI$8,0))*1000 -> 1200 | N26: =+INDEX('QoE PF Adj. P&L Aug-26'!$D$11:$AI$108,MATCH($C26,'QoE PF Adj. P&L Aug-26'!$C$11:$C$108,0),MATCH(N$8,'QoE PF Adj. P&L Aug-26'!$D$8:$AI$8,0))*1000 -> 1100 | O26: =+INDEX('QoE PF Adj. P&L Aug-26'!$D$11:$AI$108,MATCH($C26,'QoE PF Adj. P&L Aug-26'!$C$11:$C$108,0),MATCH(O$8,'QoE PF Adj. P&L Aug-26'!$D$8:$AI$8,0))*1000 -> 1100 | P26: =+INDEX('QoE PF Adj. P&L Aug-26'!$D$11:$AI$108,MATCH($C26,'QoE PF Adj. P&L Aug-26'!$C$11:$C$108,0),MATCH(P$8,'QoE PF Adj. P&L Aug-26'!$D$8:$AI$8,0))*1000 -> 1100 | Q26: =+INDEX('QoE PF Adj. P&L Aug-26'!$D$11:$AI$108,MATCH($C26,'QoE PF Adj. P&L Aug-26'!$C$11:$C$108,0),MATCH(Q$8,'QoE PF Adj. P&L Aug-26'!$D$8:$AI$8,0))*1000 -> 1100 | ... AO26: =+INDEX('QoE PF Adj. P&L Aug-26'!$D$11:$AI$108,MATCH($C26,'QoE PF Adj. P&L Aug-26'!$C$11:$C$108,0),MATCH(AO$8,'QoE PF Adj. P&L Aug-26'!$D$8:$AI$8,0))*1000 -> 1200 | AP26: =+'Separate Line Item Builds'!AP63+SUMIFS('Sep - Nov P&L'!I:I,'Sep - Nov P&L'!$D:$D,$C26) -> 1486.7349 | AQ26: =+'Separate Line Item Builds'!AQ63+SUMIFS('Sep - Nov P&L'!J:J,'Sep - Nov P&L'!$D:$D,$C26) -> 1499.7325 | AR26: =+'Separate Line Item Builds'!AR63+SUMIFS('Sep - Nov P&L'!K:K,'Sep - Nov P&L'!$D:$D,$C26) -> 1487.2101 | AS26: =+SUM(AS$19,AS$22:AS$25)*AS134 -> 1327.4832 | AT26: =+SUM(AT$19,AT$22:AT$25)*AT134 -> 1317.5935 | AU26: =+SUM(AU$19,AU$22:AU$25)*AU134 -> 1371.3867 | AV26: =+SUM(AV$19,AV$22:AV$25)*AV134 -> 1458.0551 | AW26: =+SUM(AW$19,AW$22:AW$25)*AW134 -> 1467.6702 | AX26: =+SUM(AX$19,AX$22:AX$25)*AX134 -> 1469.3611 | AY26: =+SUM(AY$19,AY$22:AY$25)*AY134 -> 1496.591 | AZ26: =+SUM(AZ$19,AZ$22:AZ$25)*AZ134 -> 1505.8885 | ... BQ26: =+SUM(BQ$19,BQ$22:BQ$25)*BQ134 -> 1636.7404
C27: Total Employee Taxes & Benefits | D27: =+SUMIFS($J27:$BQ27,$J$7:$BQ$7,D$8) -> 522000 | E27: =+SUMIFS($J27:$BQ27,$J$7:$BQ$7,E$8) -> 549300 | F27: =+SUMIFS($J27:$BQ27,$J$7:$BQ$7,F$8) -> 592903.9 | G27: =+SUMIFS($J27:$BQ27,$J$7:$BQ$7,G$8) -> 682997.79 | H27: =+SUMIFS($J27:$BQ27,$J$7:$BQ$7,H$8) -> 753482.15 | J27: =SUM(J22:J26) -> 44300 | K27: =SUM(K22:K26) -> 43600 | L27: =SUM(L22:L26) -> 43100 | M27: =SUM(M22:M26) -> 44300 | N27: =SUM(N22:N26) -> 42100 | O27: =SUM(O22:O26) -> 43700 | P27: =SUM(P22:P26) -> 43700 | Q27: =SUM(Q22:Q26) -> 43100 | ... BQ27: =SUM(BQ22:BQ26) -> 62806.037
C29: Occupancy Costs
C30: Facility Rent | D30: =+SUMIFS($J30:$BQ30,$J$7:$BQ$7,D$8) -> 465000 | E30: =+SUMIFS($J30:$BQ30,$J$7:$BQ$7,E$8) -> 507800 | F30: =+SUMIFS($J30:$BQ30,$J$7:$BQ$7,F$8) -> 530311.8 | G30: =+SUMIFS($J30:$BQ30,$J$7:$BQ$7,G$8) -> 543295.01 | H30: =+SUMIFS($J30:$BQ30,$J$7:$BQ$7,H$8) -> 566557.82 | J30: =+INDEX('QoE PF Adj. P&L Aug-26'!$D$11:$AI$108,MATCH($C30,'QoE PF Adj. P&L Aug-26'!$C$11:$C$108,0),MATCH(J$8,'QoE PF Adj. P&L Aug-26'!$D$8:$AI$8,0))*1000 -> 38000 | K30: =+INDEX('QoE PF Adj. P&L Aug-26'!$D$11:$AI$108,MATCH($C30,'QoE PF Adj. P&L Aug-26'!$C$11:$C$108,0),MATCH(K$8,'QoE PF Adj. P&L Aug-26'!$D$8:$AI$8,0))*1000 -> 36300 | L30: =+INDEX('QoE PF Adj. P&L Aug-26'!$D$11:$AI$108,MATCH($C30,'QoE PF Adj. P&L Aug-26'!$C$11:$C$108,0),MATCH(L$8,'QoE PF Adj. P&L Aug-26'!$D$8:$AI$8,0))*1000 -> 39700 | M30: =+INDEX('QoE PF Adj. P&L Aug-26'!$D$11:$AI$108,MATCH($C30,'QoE PF Adj. P&L Aug-26'!$C$11:$C$108,0),MATCH(M$8,'QoE PF Adj. P&L Aug-26'!$D$8:$AI$8,0))*1000 -> 38800 | N30: =+INDEX('QoE PF Adj. P&L Aug-26'!$D$11:$AI$108,MATCH($C30,'QoE PF Adj. P&L Aug-26'!$C$11:$C$108,0),MATCH(N$8,'QoE PF Adj. P&L Aug-26'!$D$8:$AI$8,0))*1000 -> 40400 | O30: =+INDEX('QoE PF Adj. P&L Aug-26'!$D$11:$AI$108,MATCH($C30,'QoE PF Adj. P&L Aug-26'!$C$11:$C$108,0),MATCH(O$8,'QoE PF Adj. P&L Aug-26'!$D$8:$AI$8,0))*1000 -> 39000 | P30: =+INDEX('QoE PF Adj. P&L Aug-26'!$D$11:$AI$108,MATCH($C30,'QoE PF Adj. P&L Aug-26'!$C$11:$C$108,0),MATCH(P$8,'QoE PF Adj. P&L Aug-26'!$D$8:$AI$8,0))*1000 -> 38500 | Q30: =+INDEX('QoE PF Adj. P&L Aug-26'!$D$11:$AI$108,MATCH($C30,'QoE PF Adj. P&L Aug-26'!$C$11:$C$108,0),MATCH(Q$8,'QoE PF Adj. P&L Aug-26'!$D$8:$AI$8,0))*1000 -> 37700 | ... AO30: =+INDEX('QoE PF Adj. P&L Aug-26'!$D$11:$AI$108,MATCH($C30,'QoE PF Adj. P&L Aug-26'!$C$11:$C$108,0),MATCH(AO$8,'QoE PF Adj. P&L Aug-26'!$D$8:$AI$8,0))*1000 -> 42300 | AP30: =+SUMIFS('Sep - Nov P&L'!I:I,'Sep - Nov P&L'!$D:$D,$C30) -> 43353.99 | AQ30: =+SUMIFS('Sep - Nov P&L'!J:J,'Sep - Nov P&L'!$D:$D,$C30) -> 43742.9 | AR30: =+SUMIFS('Sep - Nov P&L'!K:K,'Sep - Nov P&L'!$D:$D,$C30) -> 45360.16 | AS30: =+AS138 -> 44254.754 | AT30: =+AT138 -> 44409.646 | AU30: =+AU138 -> 44565.08 | AV30: =+AV138 -> 44721.057 | AW30: =+AW138 -> 44877.581 | AX30: =+AX138 -> 45034.653 | AY30: =+AY138 -> 45192.274 | AZ30: =+AZ138 -> 45350.447 | ... BQ30: =+BQ138 -> 48125.691
C31: Utilities | D31: =+SUMIFS($J31:$BQ31,$J$7:$BQ$7,D$8) -> 77600 | E31: =+SUMIFS($J31:$BQ31,$J$7:$BQ$7,E$8) -> 81200 | F31: =+SUMIFS($J31:$BQ31,$J$7:$BQ$7,F$8) -> 87475.867 | G31: =+SUMIFS($J31:$BQ31,$J$7:$BQ$7,G$8) -> 88934.867 | H31: =+SUMIFS($J31:$BQ31,$J$7:$BQ$7,H$8) -> 92742.881 | J31: =+INDEX('QoE PF Adj. P&L Aug-26'!$D$11:$AI$108,MATCH($C31,'QoE PF Adj. P&L Aug-26'!$C$11:$C$108,0),MATCH(J$8,'QoE PF Adj. P&L Aug-26'!$D$8:$AI$8,0))*1000 -> 6300 | K31: =+INDEX('QoE PF Adj. P&L Aug-26'!$D$11:$AI$108,MATCH($C31,'QoE PF Adj. P&L Aug-26'!$C$11:$C$108,0),MATCH(K$8,'QoE PF Adj. P&L Aug-26'!$D$8:$AI$8,0))*1000 -> 6100 | L31: =+INDEX('QoE PF Adj. P&L Aug-26'!$D$11:$AI$108,MATCH($C31,'QoE PF Adj. P&L Aug-26'!$C$11:$C$108,0),MATCH(L$8,'QoE PF Adj. P&L Aug-26'!$D$8:$AI$8,0))*1000 -> 6600 | M31: =+INDEX('QoE PF Adj. P&L Aug-26'!$D$11:$AI$108,MATCH($C31,'QoE PF Adj. P&L Aug-26'!$C$11:$C$108,0),MATCH(M$8,'QoE PF Adj. P&L Aug-26'!$D$8:$AI$8,0))*1000 -> 6400 | N31: =+INDEX('QoE PF Adj. P&L Aug-26'!$D$11:$AI$108,MATCH($C31,'QoE PF Adj. P&L Aug-26'!$C$11:$C$108,0),MATCH(N$8,'QoE PF Adj. P&L Aug-26'!$D$8:$AI$8,0))*1000 -> 6400 | O31: =+INDEX('QoE PF Adj. P&L Aug-26'!$D$11:$AI$108,MATCH($C31,'QoE PF Adj. P&L Aug-26'!$C$11:$C$108,0),MATCH(O$8,'QoE PF Adj. P&L Aug-26'!$D$8:$AI$8,0))*1000 -> 6600 | P31: =+INDEX('QoE PF Adj. P&L Aug-26'!$D$11:$AI$108,MATCH($C31,'QoE PF Adj. P&L Aug-26'!$C$11:$C$108,0),MATCH(P$8,'QoE PF Adj. P&L Aug-26'!$D$8:$AI$8,0))*1000 -> 6200 | Q31: =+INDEX('QoE PF Adj. P&L Aug-26'!$D$11:$AI$108,MATCH($C31,'QoE PF Adj. P&L Aug-26'!$C$11:$C$108,0),MATCH(Q$8,'QoE PF Adj. P&L Aug-26'!$D$8:$AI$8,0))*1000 -> 6800 | ... AO31: =+INDEX('QoE PF Adj. P&L Aug-26'!$D$11:$AI$108,MATCH($C31,'QoE PF Adj. P&L Aug-26'!$C$11:$C$108,0),MATCH(AO$8,'QoE PF Adj. P&L Aug-26'!$D$8:$AI$8,0))*1000 -> 7300 | AP31: =+SUMIFS('Sep - Nov P&L'!I:I,'Sep - Nov P&L'!$D:$D,$C31) -> 7569.46 | AQ31: =+SUMIFS('Sep - Nov P&L'!J:J,'Sep - Nov P&L'!$D:$D,$C31) -> 7723.55 | AR31: =+SUMIFS('Sep - Nov P&L'!K:K,'Sep - Nov P&L'!$D:$D,$C31) -> 7138.56 | AS31: =+AS139 -> 7244.2975 | AT31: =+AT139 -> 7269.6525 | AU31: =+AU139 -> 7295.0963 | AV31: =+AV139 -> 7320.6292 | AW31: =+AW139 -> 7346.2514 | AX31: =+AX139 -> 7371.9632 | AY31: =+AY139 -> 7397.7651 | AZ31: =+AZ139 -> 7423.6573 | ... BQ31: =+BQ139 -> 7877.9518
C32: Janitorial | D32: =+SUMIFS($J32:$BQ32,$J$7:$BQ$7,D$8) -> 38600 | E32: =+SUMIFS($J32:$BQ32,$J$7:$BQ$7,E$8) -> 41200 | F32: =+SUMIFS($J32:$BQ32,$J$7:$BQ$7,F$8) -> 32141.667 | G32: =+SUMIFS($J32:$BQ32,$J$7:$BQ$7,G$8) -> 33658.165 | H32: =+SUMIFS($J32:$BQ32,$J$7:$BQ$7,H$8) -> 35099.341 | J32: =+INDEX('QoE PF Adj. P&L Aug-26'!$D$11:$AI$108,MATCH($C32,'QoE PF Adj. P&L Aug-26'!$C$11:$C$108,0),MATCH(J$8,'QoE PF Adj. P&L Aug-26'!$D$8:$AI$8,0))*1000 -> 3200 | K32: =+INDEX('QoE PF Adj. P&L Aug-26'!$D$11:$AI$108,MATCH($C32,'QoE PF Adj. P&L Aug-26'!$C$11:$C$108,0),MATCH(K$8,'QoE PF Adj. P&L Aug-26'!$D$8:$AI$8,0))*1000 -> 3000 | L32: =+INDEX('QoE PF Adj. P&L Aug-26'!$D$11:$AI$108,MATCH($C32,'QoE PF Adj. P&L Aug-26'!$C$11:$C$108,0),MATCH(L$8,'QoE PF Adj. P&L Aug-26'!$D$8:$AI$8,0))*1000 -> 3000 | M32: =+INDEX('QoE PF Adj. P&L Aug-26'!$D$11:$AI$108,MATCH($C32,'QoE PF Adj. P&L Aug-26'!$C$11:$C$108,0),MATCH(M$8,'QoE PF Adj. P&L Aug-26'!$D$8:$AI$8,0))*1000 -> 3100 | N32: =+INDEX('QoE PF Adj. P&L Aug-26'!$D$11:$AI$108,MATCH($C32,'QoE PF Adj. P&L Aug-26'!$C$11:$C$108,0),MATCH(N$8,'QoE PF Adj. P&L Aug-26'!$D$8:$AI$8,0))*1000 -> 3300 | O32: =+INDEX('QoE PF Adj. P&L Aug-26'!$D$11:$AI$108,MATCH($C32,'QoE PF Adj. P&L Aug-26'!$C$11:$C$108,0),MATCH(O$8,'QoE PF Adj. P&L Aug-26'!$D$8:$AI$8,0))*1000 -> 3200 | P32: =+INDEX('QoE PF Adj. P&L Aug-26'!$D$11:$AI$108,MATCH($C32,'QoE PF Adj. P&L Aug-26'!$C$11:$C$108,0),MATCH(P$8,'QoE PF Adj. P&L Aug-26'!$D$8:$AI$8,0))*1000 -> 3400 | Q32: =+INDEX('QoE PF Adj. P&L Aug-26'!$D$11:$AI$108,MATCH($C32,'QoE PF Adj. P&L Aug-26'!$C$11:$C$108,0),MATCH(Q$8,'QoE PF Adj. P&L Aug-26'!$D$8:$AI$8,0))*1000 -> 3000 | ... AO32: =+INDEX('QoE PF Adj. P&L Aug-26'!$D$11:$AI$108,MATCH($C32,'QoE PF Adj. P&L Aug-26'!$C$11:$C$108,0),MATCH(AO$8,'QoE PF Adj. P&L Aug-26'!$D$8:$AI$8,0))*1000 -> 3700 | AP32: =+SUMIFS('Sep - Nov P&L'!I:I,'Sep - Nov P&L'!$D:$D,$C32) -> 0 | AQ32: =+SUMIFS('Sep - Nov P&L'!J:J,'Sep - Nov P&L'!$D:$D,$C32) -> 0 | AR32: =+SUMIFS('Sep - Nov P&L'!K:K,'Sep - Nov P&L'!$D:$D,$C32) -> 0 | AS32: =+AS140 -> 2741.6667 | AT32: =+AT140 -> 2751.2625 | AU32: =+AU140 -> 2760.8919 | AV32: =+AV140 -> 2770.555 | AW32: =+AW140 -> 2780.252 | AX32: =+AX140 -> 2789.9829 | AY32: =+AY140 -> 2799.7478 | AZ32: =+AZ140 -> 2809.5469 | ... BQ32: =+BQ140 -> 2981.4786
C33: Security | D33: =+SUMIFS($J33:$BQ33,$J$7:$BQ$7,D$8) -> 12900 | E33: =+SUMIFS($J33:$BQ33,$J$7:$BQ$7,E$8) -> 14100 | F33: =+SUMIFS($J33:$BQ33,$J$7:$BQ$7,F$8) -> 10725 | G33: =+SUMIFS($J33:$BQ33,$J$7:$BQ$7,G$8) -> 11355.794 | H33: =+SUMIFS($J33:$BQ33,$J$7:$BQ$7,H$8) -> 11842.027 | J33: =+INDEX('QoE PF Adj. P&L Aug-26'!$D$11:$AI$108,MATCH($C33,'QoE PF Adj. P&L Aug-26'!$C$11:$C$108,0),MATCH(J$8,'QoE PF Adj. P&L Aug-26'!$D$8:$AI$8,0))*1000 -> 1000 | K33: =+INDEX('QoE PF Adj. P&L Aug-26'!$D$11:$AI$108,MATCH($C33,'QoE PF Adj. P&L Aug-26'!$C$11:$C$108,0),MATCH(K$8,'QoE PF Adj. P&L Aug-26'!$D$8:$AI$8,0))*1000 -> 1100 | L33: =+INDEX('QoE PF Adj. P&L Aug-26'!$D$11:$AI$108,MATCH($C33,'QoE PF Adj. P&L Aug-26'!$C$11:$C$108,0),MATCH(L$8,'QoE PF Adj. P&L Aug-26'!$D$8:$AI$8,0))*1000 -> 1000 | M33: =+INDEX('QoE PF Adj. P&L Aug-26'!$D$11:$AI$108,MATCH($C33,'QoE PF Adj. P&L Aug-26'!$C$11:$C$108,0),MATCH(M$8,'QoE PF Adj. P&L Aug-26'!$D$8:$AI$8,0))*1000 -> 1000 | N33: =+INDEX('QoE PF Adj. P&L Aug-26'!$D$11:$AI$108,MATCH($C33,'QoE PF Adj. P&L Aug-26'!$C$11:$C$108,0),MATCH(N$8,'QoE PF Adj. P&L Aug-26'!$D$8:$AI$8,0))*1000 -> 1100 | O33: =+INDEX('QoE PF Adj. P&L Aug-26'!$D$11:$AI$108,MATCH($C33,'QoE PF Adj. P&L Aug-26'!$C$11:$C$108,0),MATCH(O$8,'QoE PF Adj. P&L Aug-26'!$D$8:$AI$8,0))*1000 -> 1100 | P33: =+INDEX('QoE PF Adj. P&L Aug-26'!$D$11:$AI$108,MATCH($C33,'QoE PF Adj. P&L Aug-26'!$C$11:$C$108,0),MATCH(P$8,'QoE PF Adj. P&L Aug-26'!$D$8:$AI$8,0))*1000 -> 1100 | Q33: =+INDEX('QoE PF Adj. P&L Aug-26'!$D$11:$AI$108,MATCH($C33,'QoE PF Adj. P&L Aug-26'!$C$11:$C$108,0),MATCH(Q$8,'QoE PF Adj. P&L Aug-26'!$D$8:$AI$8,0))*1000 -> 1000 | ... AO33: =+INDEX('QoE PF Adj. P&L Aug-26'!$D$11:$AI$108,MATCH($C33,'QoE PF Adj. P&L Aug-26'!$C$11:$C$108,0),MATCH(AO$8,'QoE PF Adj. P&L Aug-26'!$D$8:$AI$8,0))*1000 -> 1300 | AP33: =+SUMIFS('Sep - Nov P&L'!I:I,'Sep - Nov P&L'!$D:$D,$C33) -> 0 | AQ33: =+SUMIFS('Sep - Nov P&L'!J:J,'Sep - Nov P&L'!$D:$D,$C33) -> 0 | AR33: =+SUMIFS('Sep - Nov P&L'!K:K,'Sep - Nov P&L'!$D:$D,$C33) -> 0 | AS33: =+AS141 -> 925 | AT33: =+AT141 -> 928.2375 | AU33: =+AU141 -> 931.48633 | AV33: =+AV141 -> 934.74653 | AW33: =+AW141 -> 938.01815 | AX33: =+AX141 -> 941.30121 | AY33: =+AY141 -> 944.59576 | AZ33: =+AZ141 -> 947.90185 | ... BQ33: =+BQ141 -> 1005.9092
C34: Other Facility Expenses | D34: =+SUMIFS($J34:$BQ34,$J$7:$BQ$7,D$8) -> 26200 | E34: =+SUMIFS($J34:$BQ34,$J$7:$BQ$7,E$8) -> 27500 | F34: =+SUMIFS($J34:$BQ34,$J$7:$BQ$7,F$8) -> 29028.139 | G34: =+SUMIFS($J34:$BQ34,$J$7:$BQ$7,G$8) -> 29679.125 | H34: =+SUMIFS($J34:$BQ34,$J$7:$BQ$7,H$8) -> 30949.926 | J34: =+INDEX('QoE PF Adj. P&L Aug-26'!$D$11:$AI$108,MATCH($C34,'QoE PF Adj. P&L Aug-26'!$C$11:$C$108,0),MATCH(J$8,'QoE PF Adj. P&L Aug-26'!$D$8:$AI$8,0))*1000 -> 2000 | K34: =+INDEX('QoE PF Adj. P&L Aug-26'!$D$11:$AI$108,MATCH($C34,'QoE PF Adj. P&L Aug-26'!$C$11:$C$108,0),MATCH(K$8,'QoE PF Adj. P&L Aug-26'!$D$8:$AI$8,0))*1000 -> 2000 | L34: =+INDEX('QoE PF Adj. P&L Aug-26'!$D$11:$AI$108,MATCH($C34,'QoE PF Adj. P&L Aug-26'!$C$11:$C$108,0),MATCH(L$8,'QoE PF Adj. P&L Aug-26'!$D$8:$AI$8,0))*1000 -> 2200 | M34: =+INDEX('QoE PF Adj. P&L Aug-26'!$D$11:$AI$108,MATCH($C34,'QoE PF Adj. P&L Aug-26'!$C$11:$C$108,0),MATCH(M$8,'QoE PF Adj. P&L Aug-26'!$D$8:$AI$8,0))*1000 -> 2200 | N34: =+INDEX('QoE PF Adj. P&L Aug-26'!$D$11:$AI$108,MATCH($C34,'QoE PF Adj. P&L Aug-26'!$C$11:$C$108,0),MATCH(N$8,'QoE PF Adj. P&L Aug-26'!$D$8:$AI$8,0))*1000 -> 2200 | O34: =+INDEX('QoE PF Adj. P&L Aug-26'!$D$11:$AI$108,MATCH($C34,'QoE PF Adj. P&L Aug-26'!$C$11:$C$108,0),MATCH(O$8,'QoE PF Adj. P&L Aug-26'!$D$8:$AI$8,0))*1000 -> 2100 | P34: =+INDEX('QoE PF Adj. P&L Aug-26'!$D$11:$AI$108,MATCH($C34,'QoE PF Adj. P&L Aug-26'!$C$11:$C$108,0),MATCH(P$8,'QoE PF Adj. P&L Aug-26'!$D$8:$AI$8,0))*1000 -> 2200 | Q34: =+INDEX('QoE PF Adj. P&L Aug-26'!$D$11:$AI$108,MATCH($C34,'QoE PF Adj. P&L Aug-26'!$C$11:$C$108,0),MATCH(Q$8,'QoE PF Adj. P&L Aug-26'!$D$8:$AI$8,0))*1000 -> 2300 | ... AO34: =+INDEX('QoE PF Adj. P&L Aug-26'!$D$11:$AI$108,MATCH($C34,'QoE PF Adj. P&L Aug-26'!$C$11:$C$108,0),MATCH(AO$8,'QoE PF Adj. P&L Aug-26'!$D$8:$AI$8,0))*1000 -> 2600 | AP34: =+SUMIFS('Sep - Nov P&L'!I:I,'Sep - Nov P&L'!$D:$D,$C34) -> 2388.26 | AQ34: =+SUMIFS('Sep - Nov P&L'!J:J,'Sep - Nov P&L'!$D:$D,$C34) -> 2510.58 | AR34: =+SUMIFS('Sep - Nov P&L'!K:K,'Sep - Nov P&L'!$D:$D,$C34) -> 2511.75 | AS34: =+AS142 -> 2417.5492 | AT34: =+AT142 -> 2426.0106 | AU34: =+AU142 -> 2434.5016 | AV34: =+AV142 -> 2443.0224 | AW34: =+AW142 -> 2451.573 | AX34: =+AX142 -> 2460.1535 | AY34: =+AY142 -> 2468.764 | AZ34: =+AZ142 -> 2477.4047 | ... BQ34: =+BQ142 -> 2629.0107
C35: Storage | D35: =+SUMIFS($J35:$BQ35,$J$7:$BQ$7,D$8) -> 13000 | E35: =+SUMIFS($J35:$BQ35,$J$7:$BQ$7,E$8) -> 13700 | F35: =+SUMIFS($J35:$BQ35,$J$7:$BQ$7,F$8) -> 10825 | G35: =+SUMIFS($J35:$BQ35,$J$7:$BQ$7,G$8) -> 11355.794 | H35: =+SUMIFS($J35:$BQ35,$J$7:$BQ$7,H$8) -> 11842.027 | J35: =+INDEX('QoE PF Adj. P&L Aug-26'!$D$11:$AI$108,MATCH($C35,'QoE PF Adj. P&L Aug-26'!$C$11:$C$108,0),MATCH(J$8,'QoE PF Adj. P&L Aug-26'!$D$8:$AI$8,0))*1000 -> 1100 | K35: =+INDEX('QoE PF Adj. P&L Aug-26'!$D$11:$AI$108,MATCH($C35,'QoE PF Adj. P&L Aug-26'!$C$11:$C$108,0),MATCH(K$8,'QoE PF Adj. P&L Aug-26'!$D$8:$AI$8,0))*1000 -> 1100 | L35: =+INDEX('QoE PF Adj. P&L Aug-26'!$D$11:$AI$108,MATCH($C35,'QoE PF Adj. P&L Aug-26'!$C$11:$C$108,0),MATCH(L$8,'QoE PF Adj. P&L Aug-26'!$D$8:$AI$8,0))*1000 -> 1100 | M35: =+INDEX('QoE PF Adj. P&L Aug-26'!$D$11:$AI$108,MATCH($C35,'QoE PF Adj. P&L Aug-26'!$C$11:$C$108,0),MATCH(M$8,'QoE PF Adj. P&L Aug-26'!$D$8:$AI$8,0))*1000 -> 1000 | N35: =+INDEX('QoE PF Adj. P&L Aug-26'!$D$11:$AI$108,MATCH($C35,'QoE PF Adj. P&L Aug-26'!$C$11:$C$108,0),MATCH(N$8,'QoE PF Adj. P&L Aug-26'!$D$8:$AI$8,0))*1000 -> 1100 | O35: =+INDEX('QoE PF Adj. P&L Aug-26'!$D$11:$AI$108,MATCH($C35,'QoE PF Adj. P&L Aug-26'!$C$11:$C$108,0),MATCH(O$8,'QoE PF Adj. P&L Aug-26'!$D$8:$AI$8,0))*1000 -> 1100 | P35: =+INDEX('QoE PF Adj. P&L Aug-26'!$D$11:$AI$108,MATCH($C35,'QoE PF Adj. P&L Aug-26'!$C$11:$C$108,0),MATCH(P$8,'QoE PF Adj. P&L Aug-26'!$D$8:$AI$8,0))*1000 -> 1100 | Q35: =+INDEX('QoE PF Adj. P&L Aug-26'!$D$11:$AI$108,MATCH($C35,'QoE PF Adj. P&L Aug-26'!$C$11:$C$108,0),MATCH(Q$8,'QoE PF Adj. P&L Aug-26'!$D$8:$AI$8,0))*1000 -> 1000 | ... AO35: =+INDEX('QoE PF Adj. P&L Aug-26'!$D$11:$AI$108,MATCH($C35,'QoE PF Adj. P&L Aug-26'!$C$11:$C$108,0),MATCH(AO$8,'QoE PF Adj. P&L Aug-26'!$D$8:$AI$8,0))*1000 -> 1200 | AP35: =+SUMIFS('Sep - Nov P&L'!I:I,'Sep - Nov P&L'!$D:$D,$C35) -> 0 | AQ35: =+SUMIFS('Sep - Nov P&L'!J:J,'Sep - Nov P&L'!$D:$D,$C35) -> 0 | AR35: =+SUMIFS('Sep - Nov P&L'!K:K,'Sep - Nov P&L'!$D:$D,$C35) -> 0 | AS35: =+AS143 -> 925 | AT35: =+AT143 -> 928.2375 | AU35: =+AU143 -> 931.48633 | AV35: =+AV143 -> 934.74653 | AW35: =+AW143 -> 938.01815 | AX35: =+AX143 -> 941.30121 | AY35: =+AY143 -> 944.59576 | AZ35: =+AZ143 -> 947.90185 | ... BQ35: =+BQ143 -> 1005.9092
C36: Facility Repairs & Maintenance | D36: =+SUMIFS($J36:$BQ36,$J$7:$BQ$7,D$8) -> 45100 | E36: =+SUMIFS($J36:$BQ36,$J$7:$BQ$7,E$8) -> 48100 | F36: =+SUMIFS($J36:$BQ36,$J$7:$BQ$7,F$8) -> 69385.306 | G36: =+SUMIFS($J36:$BQ36,$J$7:$BQ$7,G$8) -> 69395.76 | H36: =+SUMIFS($J36:$BQ36,$J$7:$BQ$7,H$8) -> 72367.148 | J36: =+INDEX('QoE PF Adj. P&L Aug-26'!$D$11:$AI$108,MATCH($C36,'QoE PF Adj. P&L Aug-26'!$C$11:$C$108,0),MATCH(J$8,'QoE PF Adj. P&L Aug-26'!$D$8:$AI$8,0))*1000 -> 3600 | K36: =+INDEX('QoE PF Adj. P&L Aug-26'!$D$11:$AI$108,MATCH($C36,'QoE PF Adj. P&L Aug-26'!$C$11:$C$108,0),MATCH(K$8,'QoE PF Adj. P&L Aug-26'!$D$8:$AI$8,0))*1000 -> 3600 | L36: =+INDEX('QoE PF Adj. P&L Aug-26'!$D$11:$AI$108,MATCH($C36,'QoE PF Adj. P&L Aug-26'!$C$11:$C$108,0),MATCH(L$8,'QoE PF Adj. P&L Aug-26'!$D$8:$AI$8,0))*1000 -> 3600 | M36: =+INDEX('QoE PF Adj. P&L Aug-26'!$D$11:$AI$108,MATCH($C36,'QoE PF Adj. P&L Aug-26'!$C$11:$C$108,0),MATCH(M$8,'QoE PF Adj. P&L Aug-26'!$D$8:$AI$8,0))*1000 -> 3600 | N36: =+INDEX('QoE PF Adj. P&L Aug-26'!$D$11:$AI$108,MATCH($C36,'QoE PF Adj. P&L Aug-26'!$C$11:$C$108,0),MATCH(N$8,'QoE PF Adj. P&L Aug-26'!$D$8:$AI$8,0))*1000 -> 3800 | O36: =+INDEX('QoE PF Adj. P&L Aug-26'!$D$11:$AI$108,MATCH($C36,'QoE PF Adj. P&L Aug-26'!$C$11:$C$108,0),MATCH(O$8,'QoE PF Adj. P&L Aug-26'!$D$8:$AI$8,0))*1000 -> 4000 | P36: =+INDEX('QoE PF Adj. P&L Aug-26'!$D$11:$AI$108,MATCH($C36,'QoE PF Adj. P&L Aug-26'!$C$11:$C$108,0),MATCH(P$8,'QoE PF Adj. P&L Aug-26'!$D$8:$AI$8,0))*1000 -> 4000 | Q36: =+INDEX('QoE PF Adj. P&L Aug-26'!$D$11:$AI$108,MATCH($C36,'QoE PF Adj. P&L Aug-26'!$C$11:$C$108,0),MATCH(Q$8,'QoE PF Adj. P&L Aug-26'!$D$8:$AI$8,0))*1000 -> 3500 | ... AO36: =+INDEX('QoE PF Adj. P&L Aug-26'!$D$11:$AI$108,MATCH($C36,'QoE PF Adj. P&L Aug-26'!$C$11:$C$108,0),MATCH(AO$8,'QoE PF Adj. P&L Aug-26'!$D$8:$AI$8,0))*1000 -> 4300 | AP36: =+SUMIFS('Sep - Nov P&L'!I:I,'Sep - Nov P&L'!$D:$D,$C36) -> 9552.87 | AQ36: =+SUMIFS('Sep - Nov P&L'!J:J,'Sep - Nov P&L'!$D:$D,$C36) -> 9671.37 | AR36: =+SUMIFS('Sep - Nov P&L'!K:K,'Sep - Nov P&L'!$D:$D,$C36) -> 9508.35 | AS36: =+AS144 -> 5652.7158 | AT36: =+AT144 -> 5672.5003 | AU36: =+AU144 -> 5692.3541 | AV36: =+AV144 -> 5712.2773 | AW36: =+AW144 -> 5732.2703 | AX36: =+AX144 -> 5752.3332 | AY36: =+AY144 -> 5772.4664 | AZ36: =+AZ144 -> 5792.67 | ... BQ36: =+BQ144 -> 6147.1555
