Workbook
Name \a: Cover!$C$3
Name \b: Control!$E$5
Name \p: Control!$E$11
Name \z: Control!$E$12
Name _Key1: '6. AHG (Combined Entity)'!$G$7
Name _Key2: '2. Tallowick (Combined Entity)'!$G$7
Name _Order1: Control!$E$10
Name _Sort: Control!$E$9
Name wrn.Summary.: 'Transaction Summary'!$C$3
Name wrn.Waterfall.: 'SPV Waterfall'!$C$3
Name wrn.AHG.: '6. AHG (Combined Entity)'!$C$3
Name FX_LCA: Control!$E$17
Name FX_LCB: Control!$E$22
Name RefDate: Control!$E$11
Name TxDate: Control!$E$12
Name MgmtFee: Control!$E$27
Name GP_Commit: Control!$E$33
Name Hurdle_T2: Control!$E$39
Name Hurdle_T4: Control!$E$51
Name Hurdle_T5: Control!$E$57
Name Carry_T3: Control!$E$44
Name Carry_T4: Control!$E$50
Name Carry_T5: Control!$E$56
Name CircuitBreaker: Control!$E$5
Name MHG_Rev: '6. AHG (Combined Entity)'!$G$202:$R$202
Name MHG_EBITDA: '6. AHG (Combined Entity)'!$G$211:$R$211
Name MHG_NI: '6. AHG (Combined Entity)'!$G$224:$R$224
Name MHG_Cash: '6. AHG (Combined Entity)'!$G$250:$R$250
Name MHG_NetDebt: '6. AHG (Combined Entity)'!$G$304:$R$304
Name MHG_BSCheck: '6. AHG (Combined Entity)'!$G$273:$R$273
Name MHG_TaxRate: '6. AHG (Combined Entity)'!$N$12
Name MHG_Toggle2027: '6. AHG (Combined Entity)'!$E$47
Name MHG_Toggle2031: '6. AHG (Combined Entity)'!$E$95
Name MHG_FollowOn: '6. AHG (Combined Entity)'!$G$195:$R$195
Name MHG_Div: '6. AHG (Combined Entity)'!$G$312:$R$312
Name Tall_Rev: '2. Tallowick (Combined Entity)'!$G$199:$R$199
Name Tall_EBITDA: '2. Tallowick (Combined Entity)'!$G$208:$R$208
Name Tall_NI: '2. Tallowick (Combined Entity)'!$G$217:$R$217
Name Tall_Cash: '2. Tallowick (Combined Entity)'!$G$227:$R$227
Name Tall_NetDebt: '2. Tallowick (Combined Entity)'!$G$271:$R$271
Name Tall_BSCheck: '2. Tallowick (Combined Entity)'!$G$241:$R$241
Name Tall_Toggle2027: '2. Tallowick (Combined Entity)'!$E$53
Name Tall_FollowOn: '2. Tallowick (Combined Entity)'!$G$192:$R$192
Name AHG_EntryMult: '7. Entry & Exit'!$E$19
Name AHG_ExitMult: '7. Entry & Exit'!$E$63
Name AHG_NAVPricing: '7. Entry & Exit'!$E$13
Name AHG_EqV: '7. Entry & Exit'!$E$25
Name AHG_Price: '7. Entry & Exit'!$E$28
Name AHG_CF_IRR: '7. Entry & Exit'!$E$96
Name AHG_CF_MoIC: '7. Entry & Exit'!$E$95
Name AHG_CF_Flows: '7. Entry & Exit'!$G$94:$S$94
Name Tall_EntryMult: '3. Entry & Exit'!$E$19
Name Tall_ExitMult: '3. Entry & Exit'!$E$61
Name Tall_NAVPricing: '3. Entry & Exit'!$E$13
Name Tall_EqV: '3. Entry & Exit'!$E$25
Name Tall_Price: '3. Entry & Exit'!$E$28
Name Tall_CF_IRR: '3. Entry & Exit'!$E$91
Name Tall_CF_MoIC: '3. Entry & Exit'!$E$90
Name Tall_CF_Flows: '3. Entry & Exit'!$G$89:$S$89
Name TS_Sources: 'Transaction Summary'!$E$32

Sheet Cover
C3: Project Dunecrest
C4: Continuation-fund transaction model – Kessport Frontier Managers Limited
C5: Tabs:
C7: Cover / Disclaimer / Control
C9: AHG Company Section (tabs 1–7): entity builds, combined entity, entry & exit
C11: Tallowick Company Section (tabs 1–3): build, combined entity, entry & exit
C13: Transaction Summary
C15: SPV Waterfall
C17: Instructions
C19: Inputs (can be amended by user) | D19: 12345
C20: Outputs (cannot be amended by user) | D20: =D19*2 -> 24690

Sheet Disclaimer
C3: =Cover!$C$3 -> Project Dunecrest | D3: Confidential
C5: This document is not a marketing communication. It has been prepared by Kessport Frontier Managers Limited solely for discussion with existing limited partners of Kessport Frontier Fund II in connection with a proposed continuation-fund transaction (Project Dunecrest) under which interests in Arvenna Health Group and Tallowick Consumer Products would be transferred to the Dunecrest Continuation Fund. It does not constitute an offer or a solicitation to acquire or subscribe for any interest in any fund or company. Figures are illustrative and unaudited; projections are based on assumptions that may not be realised and actual results may differ materially. Interest on debt is computed on opening balances; the model contains no circular references. Nothing in this document should be relied upon as investment, legal or tax advice.

Sheet Control
C3: =Cover!$C$3 -> Project Dunecrest | D3: Confidential
C4: Circuit Breaker
C5: Circuit Breaker (1 = on) | E5: 1
C7: Transaction Assumptions:
C9: Sponsor | E9: Kessport Frontier Managers Limited
C10: Funds | E10: Fund II
C11: Reference Date | E11: 46203
C12: Transaction Date | E12: 46387
C14: Portfolio Company Assumptions:
C15: Arvenna Health Group:
C16: Currency | E16: LCA
C17: Currency Conversion to USD | E17: 0.235
C18: Converted Currency | E18: USD
C20: Tallowick:
C21: Currency | E21: LCB
C22: Currency Conversion to USD | E22: 0.0125
C23: Converted Currency | E23: USD
C25: New SPV Economics:
C26: Management Fee | E26: On net invested capital
C27: Management Fee p.a (%) | E27: 0.0175
C29: Reinvested GP Economics ($M) | E29: 5.2
C30: Rolling LPs (% of Continuation Fund) | E30: 0.41
C32: Tier 1: Return of Capital
C33: GP Proceeds Allocation (GP commitment %) | E33: 0.02
C34: LP Proceeds Allocation | E34: =1-E33 -> 0.98
C36: Tier 2: Preferred Return to LPs
C37: GP Proceeds Allocation | E37: 0
C38: LP Proceeds Allocation | E38: =1-E37 -> 1
C39: IRR Threshold | E39: 0.08
C40: MOIC Threshold | E40: 1
C42: Tier 3: Catch-Up & Carried Interest
C43: GP Catch-Up | E43: 1
C44: GP Carried Interest | E44: 0.1
C45: IRR Threshold | E45: 0.08
C46: MOIC Threshold | E46: 1.5
C48: Tier 4: Catch-Up & Carried Interest
C49: GP Catch-Up | E49: 1
C50: GP Carried Interest | E50: 0.15
C51: IRR Threshold | E51: 0.15
C52: MOIC Threshold | E52: 2
...

Sheet 1. AHG Central
C3: =Cover!$C$3 -> Project Dunecrest | D3: Confidential
C4: AHG Central – Operating Build
C6: Fiscal Year Ending | G6: 43830 | H6: 44196 | I6: 44561 | J6: 44926 | K6: =EOMONTH(J6,12) -> 45291 | L6: =EOMONTH(K6,12) -> 45657 | M6: =EOMONTH(L6,12) -> 46022 | N6: =EOMONTH(M6,12) -> 46387 | O6: =EOMONTH(N6,12) -> 46752 | P6: =EOMONTH(O6,12) -> 47118 | Q6: =EOMONTH(P6,12) -> 47483 | R6: =EOMONTH(Q6,12) -> 47848
C7: Fiscal Year | G7: =YEAR(G6) -> 2019 | H7: =YEAR(H6) -> 2020 | I7: =YEAR(I6) -> 2021 | J7: =YEAR(J6) -> 2022 | K7: =YEAR(K6) -> 2023 | L7: =YEAR(L6) -> 2024 | M7: =YEAR(M6) -> 2025 | N7: =YEAR(N6) -> 2026 | ... R7: =YEAR(R6) -> 2030
C8: Actual / Estimate | G8: =IF(G6<=Control!$E$11,"A","E") -> A | H8: =IF(H6<=Control!$E$11,"A","E") -> A | I8: =IF(I6<=Control!$E$11,"A","E") -> A | J8: =IF(J6<=Control!$E$11,"A","E") -> A | K8: =IF(K6<=Control!$E$11,"A","E") -> A | L8: =IF(L6<=Control!$E$11,"A","E") -> A | M8: =IF(M6<=Control!$E$11,"A","E") -> A | N8: =IF(N6<=Control!$E$11,"A","E") -> E | ... R8: =IF(R6<=Control!$E$11,"A","E") -> E
C10: Supporting Data
C11: A | D11: Revenue Build | E11: ="("&Control!$E$16&" in Actual)" -> (LCA in Actual)
C12: Laboratory:
C13: # of Tests | G13: 104371 | H13: 95978 | I13: 103537 | J13: 110725 | K13: 121389 | L13: 128622 | M13: 136349 | N13: =M13*(1+N14) -> 142484.7 | O13: =N13*(1+O14) -> 149039 | P13: =O13*(1+P14) -> 160962.12 | Q13: =P13*(1+Q14) -> 175126.79 | R13: =Q13*(1+R14) -> 188261.3
C14: Growth (%) | G14: =IFERROR(G13/F13-1,"N/A") -> N/A | H14: =IFERROR(H13/G13-1,"N/A") -> -0.080415058 | I14: =IFERROR(I13/H13-1,"N/A") -> 0.078757632 | J14: =IFERROR(J13/I13-1,"N/A") -> 0.069424457 | K14: =IFERROR(K13/J13-1,"N/A") -> 0.09631068 | L14: =IFERROR(L13/K13-1,"N/A") -> 0.0595853 | M14: =IFERROR(M13/L13-1,"N/A") -> 0.060075259 | N14: 0.045 | O14: 0.046 | P14: 0.08 | Q14: 0.088 | R14: 0.075
C15: Gross Revenue [per Test] (LCA) | G15: 37 | H15: 38 | I15: 41 | J15: 43 | K15: 45 | L15: 47 | M15: 50 | N15: =M15*(1+N16) -> 52.9 | O15: =N15*(1+O16) -> 55.9682 | P15: =O15*(1+P16) -> 58.990483 | Q15: =P15*(1+Q16) -> 62.29395 | R15: =Q15*(1+R16) -> 66.405351
C16: Growth (%) | G16: =IFERROR(G15/F15-1,"N/A") -> N/A | H16: =IFERROR(H15/G15-1,"N/A") -> 0.027027027 | I16: =IFERROR(I15/H15-1,"N/A") -> 0.078947368 | J16: =IFERROR(J15/I15-1,"N/A") -> 0.048780488 | K16: =IFERROR(K15/J15-1,"N/A") -> 0.046511628 | L16: =IFERROR(L15/K15-1,"N/A") -> 0.044444444 | M16: =IFERROR(M15/L15-1,"N/A") -> 0.063829787 | N16: 0.058 | O16: 0.058 | P16: 0.054 | Q16: 0.056 | R16: 0.066
C17: Revenue | G17: =G13*G15 -> 3861727 | H17: =H13*H15 -> 3647164 | I17: =I13*I15 -> 4245017 | J17: =J13*J15 -> 4761175 | K17: =K13*K15 -> 5462505 | L17: =L13*L15 -> 6045234 | M17: =M13*M15 -> 6817450 | N17: =N13*N15 -> 7537440.9 | ... R17: =R13*R15 -> 12501557
C19: Radiology:
C20: # of Tests | G20: 26516 | H20: 25439 | I20: 27841 | J20: 30119 | K20: 31770 | L20: 33965 | M20: 36270 | N20: =M20*(1+N21) -> 38518.74 | O20: =N20*(1+O21) -> 40329.121 | P20: =O20*(1+P21) -> 42910.185 | Q20: =P20*(1+Q21) -> 45913.897 | R20: =Q20*(1+R21) -> 49770.665
C21: Growth (%) | G21: =IFERROR(G20/F20-1,"N/A") -> N/A | H21: =IFERROR(H20/G20-1,"N/A") -> -0.040616986 | I21: =IFERROR(I20/H20-1,"N/A") -> 0.094421951 | J21: =IFERROR(J20/I20-1,"N/A") -> 0.081821774 | K21: =IFERROR(K20/J20-1,"N/A") -> 0.054815897 | L21: =IFERROR(L20/K20-1,"N/A") -> 0.069090337 | M21: =IFERROR(M20/L20-1,"N/A") -> 0.067863978 | N21: 0.062 | O21: 0.047 | P21: 0.064 | Q21: 0.07 | R21: 0.084
C22: Gross Revenue [per Test] (LCA) | G22: 120 | H22: 121 | I22: 127 | J22: 136 | K22: 147 | L22: 155 | M22: 170 | N22: =M22*(1+N23) -> 177.14 | O22: =N22*(1+O23) -> 187.94554 | P22: =O22*(1+P23) -> 196.96693 | Q22: =P22*(1+Q23) -> 205.63347 | R22: =Q22*(1+R23) -> 220.02781
C23: Growth (%) | G23: =IFERROR(G22/F22-1,"N/A") -> N/A | H23: =IFERROR(H22/G22-1,"N/A") -> 0.0083333333 | I23: =IFERROR(I22/H22-1,"N/A") -> 0.049586777 | J23: =IFERROR(J22/I22-1,"N/A") -> 0.070866142 | K23: =IFERROR(K22/J22-1,"N/A") -> 0.080882353 | L23: =IFERROR(L22/K22-1,"N/A") -> 0.054421769 | M23: =IFERROR(M22/L22-1,"N/A") -> 0.096774194 | N23: 0.042 | O23: 0.061 | P23: 0.048 | Q23: 0.044 | R23: 0.07
C24: Revenue | G24: =G20*G22 -> 3181920 | H24: =H20*H22 -> 3078119 | I24: =I20*I22 -> 3535807 | J24: =J20*J22 -> 4096184 | K24: =K20*K22 -> 4670190 | L24: =L20*L22 -> 5264575 | M24: =M20*M22 -> 6165900 | N24: =N20*N22 -> 6823209.6 | ... R24: =R20*R22 -> 10950931
C26: Endoscopy:
C27: # of Visits | G27: 1831 | H27: 1709 | I27: 1814 | J27: 1969 | K27: 2062 | L27: 2203 | M27: 2347 | N27: =M27*(1+N28) -> 2504.249 | O27: =N27*(1+O28) -> 2702.0847 | P27: =O27*(1+P28) -> 2858.8056 | Q27: =P27*(1+Q28) -> 3027.4751 | R27: =Q27*(1+R28) -> 3175.8214
C28: Growth (%) | G28: =IFERROR(G27/F27-1,"N/A") -> N/A | H28: =IFERROR(H27/G27-1,"N/A") -> -0.066630257 | I28: =IFERROR(I27/H27-1,"N/A") -> 0.061439438 | J28: =IFERROR(J27/I27-1,"N/A") -> 0.085446527 | K28: =IFERROR(K27/J27-1,"N/A") -> 0.047232098 | L28: =IFERROR(L27/K27-1,"N/A") -> 0.068380213 | M28: =IFERROR(M27/L27-1,"N/A") -> 0.065365411 | N28: 0.067 | O28: 0.079 | P28: 0.058 | Q28: 0.059 | R28: 0.049
C29: Gross Revenue [per Visit] (LCA) | G29: 740 | H29: 769 | I29: 808 | J29: 888 | K29: 934 | L29: 1013 | M29: 1105 | N29: =M29*(1+N30) -> 1164.67 | O29: =N29*(1+O30) -> 1233.3855 | P29: =O29*(1+P30) -> 1319.7225 | Q29: =P29*(1+Q30) -> 1410.7834 | R29: =Q29*(1+R30) -> 1495.4304
C30: Growth (%) | G30: =IFERROR(G29/F29-1,"N/A") -> N/A | H30: =IFERROR(H29/G29-1,"N/A") -> 0.039189189 | I30: =IFERROR(I29/H29-1,"N/A") -> 0.050715215 | J30: =IFERROR(J29/I29-1,"N/A") -> 0.099009901 | K30: =IFERROR(K29/J29-1,"N/A") -> 0.051801802 | L30: =IFERROR(L29/K29-1,"N/A") -> 0.084582441 | M30: =IFERROR(M29/L29-1,"N/A") -> 0.090819348 | N30: 0.054 | O30: 0.059 | P30: 0.07 | Q30: 0.069 | R30: 0.06
C31: Revenue | G31: =G27*G29 -> 1354940 | H31: =H27*H29 -> 1314221 | I31: =I27*I29 -> 1465712 | J31: =J27*J29 -> 1748472 | K31: =K27*K29 -> 1925908 | L31: =L27*L29 -> 2231639 | M31: =M27*M29 -> 2593435 | N31: =N27*N29 -> 2916623.7 | ... R31: =R27*R29 -> 4749219.8
C33: Physiotherapy:
C34: # of Patients | G34: 5603 | H34: 5184 | I34: 5596 | J34: 5788 | K34: 6353 | L34: 6895 | M34: 7535 | N34: =M34*(1+N35) -> 7919.285 | O34: =N34*(1+O35) -> 8323.1685 | P34: =O34*(1+P35) -> 8672.7416 | Q34: =P34*(1+Q35) -> 9175.7606 | R34: =Q34*(1+R35) -> 9735.482
C35: Growth (%) | G35: =IFERROR(G34/F34-1,"N/A") -> N/A | H35: =IFERROR(H34/G34-1,"N/A") -> -0.074781367 | I35: =IFERROR(I34/H34-1,"N/A") -> 0.079475309 | J35: =IFERROR(J34/I34-1,"N/A") -> 0.034310222 | K35: =IFERROR(K34/J34-1,"N/A") -> 0.097615757 | L35: =IFERROR(L34/K34-1,"N/A") -> 0.085314025 | M35: =IFERROR(M34/L34-1,"N/A") -> 0.092820885 | N35: 0.051 | O35: 0.051 | P35: 0.042 | Q35: 0.058 | R35: 0.061
C36: Gross Revenue [per Patient] (LCA) | G36: 104 | H36: 107 | I36: 111 | J36: 120 | K36: 134 | L36: 144 | M36: 156 | N36: =M36*(1+N37) -> 163.8 | O36: =N36*(1+O37) -> 175.1022 | P36: =O36*(1+P37) -> 185.43323 | Q36: =P36*(1+Q37) -> 195.07576 | R36: =Q36*(1+R37) -> 206.58523
C37: Growth (%) | G37: =IFERROR(G36/F36-1,"N/A") -> N/A | H37: =IFERROR(H36/G36-1,"N/A") -> 0.028846154 | I37: =IFERROR(I36/H36-1,"N/A") -> 0.037383178 | J37: =IFERROR(J36/I36-1,"N/A") -> 0.081081081 | K37: =IFERROR(K36/J36-1,"N/A") -> 0.11666667 | L37: =IFERROR(L36/K36-1,"N/A") -> 0.074626866 | M37: =IFERROR(M36/L36-1,"N/A") -> 0.083333333 | N37: 0.05 | O37: 0.069 | P37: 0.059 | Q37: 0.052 | R37: 0.059
C38: Revenue | G38: =G34*G36 -> 582712 | H38: =H34*H36 -> 554688 | I38: =I34*I36 -> 621156 | J38: =J34*J36 -> 694560 | K38: =K34*K36 -> 851302 | L38: =L34*L36 -> 992880 | M38: =M34*M36 -> 1175460 | N38: =N34*N36 -> 1297178.9 | ... R38: =R34*R36 -> 2011206.8
C40: IVF:
C41: # of Patients | G41: 240 | H41: 218 | I41: 238 | J41: 259 | K41: 282 | L41: 308 | M41: 335 | N41: =M41*(1+N42) -> 349.74 | O41: =N41*(1+O42) -> 369.67518 | P41: =O41*(1+P42) -> 390.00731 | Q41: =P41*(1+Q42) -> 416.91782 | R41: =Q41*(1+R42) -> 448.18666
C42: Growth (%) | G42: =IFERROR(G41/F41-1,"N/A") -> N/A | H42: =IFERROR(H41/G41-1,"N/A") -> -0.091666667 | I42: =IFERROR(I41/H41-1,"N/A") -> 0.091743119 | J42: =IFERROR(J41/I41-1,"N/A") -> 0.088235294 | K42: =IFERROR(K41/J41-1,"N/A") -> 0.088803089 | L42: =IFERROR(L41/K41-1,"N/A") -> 0.092198582 | M42: =IFERROR(M41/L41-1,"N/A") -> 0.087662338 | N42: 0.044 | O42: 0.057 | P42: 0.055 | Q42: 0.069 | R42: 0.075
C43: Gross Revenue [per Patient] (LCA) | G43: 3968 | H43: 4025 | I43: 4222 | J43: 4423 | K43: 4706 | L43: 5167 | M43: 5518 | N43: =M43*(1+N44) -> 5815.972 | O43: =N43*(1+O44) -> 6159.1143 | P43: =O43*(1+P44) -> 6473.2292 | Q43: =P43*(1+Q44) -> 6777.471 | R43: =Q43*(1+R44) -> 7218.0066
C44: Growth (%) | G44: =IFERROR(G43/F43-1,"N/A") -> N/A | H44: =IFERROR(H43/G43-1,"N/A") -> 0.014364919 | I44: =IFERROR(I43/H43-1,"N/A") -> 0.048944099 | J44: =IFERROR(J43/I43-1,"N/A") -> 0.047607769 | K44: =IFERROR(K43/J43-1,"N/A") -> 0.063983721 | L44: =IFERROR(L43/K43-1,"N/A") -> 0.097960051 | M44: =IFERROR(M43/L43-1,"N/A") -> 0.067931101 | N44: 0.054 | O44: 0.059 | P44: 0.051 | Q44: 0.047 | R44: 0.065
C45: Revenue | G45: =G41*G43 -> 952320 | H45: =H41*H43 -> 877450 | I45: =I41*I43 -> 1004836 | J45: =J41*J43 -> 1145557 | K45: =K41*K43 -> 1327092 | L45: =L41*L43 -> 1591436 | M45: =M41*M43 -> 1848530 | N45: =N41*N43 -> 2034078 | ... R45: =R41*R43 -> 3235014.2
C47: Anapath:
C48: # of Patients | G48: 7417 | H48: 6961 | I48: 7592 | J48: 8178 | K48: 9185 | L48: 10117 | M48: 11179 | N48: =M48*(1+N49) -> 12017.425 | O48: =N48*(1+O49) -> 12954.784 | P48: =O48*(1+P49) -> 13615.478 | Q48: =P48*(1+Q49) -> 14486.869 | R48: =Q48*(1+R49) -> 15515.436
C49: Growth (%) | G49: =IFERROR(G48/F48-1,"N/A") -> N/A | H49: =IFERROR(H48/G48-1,"N/A") -> -0.061480383 | I49: =IFERROR(I48/H48-1,"N/A") -> 0.090647895 | J49: =IFERROR(J48/I48-1,"N/A") -> 0.077186512 | K49: =IFERROR(K48/J48-1,"N/A") -> 0.12313524 | L49: =IFERROR(L48/K48-1,"N/A") -> 0.10146979 | M49: =IFERROR(M48/L48-1,"N/A") -> 0.10497183 | N49: 0.075 | O49: 0.078 | P49: 0.051 | Q49: 0.064 | R49: 0.071
...

Sheet 2. AHG Coast
C3: =Cover!$C$3 -> Project Dunecrest | D3: Confidential
C4: AHG Coast – Operating Build
C6: Fiscal Year Ending | G6: 43830 | H6: 44196 | I6: 44561 | J6: 44926 | K6: =EOMONTH(J6,12) -> 45291 | L6: =EOMONTH(K6,12) -> 45657 | M6: =EOMONTH(L6,12) -> 46022 | N6: =EOMONTH(M6,12) -> 46387 | O6: =EOMONTH(N6,12) -> 46752 | P6: =EOMONTH(O6,12) -> 47118 | Q6: =EOMONTH(P6,12) -> 47483 | R6: =EOMONTH(Q6,12) -> 47848
C7: Fiscal Year | G7: =YEAR(G6) -> 2019 | H7: =YEAR(H6) -> 2020 | I7: =YEAR(I6) -> 2021 | J7: =YEAR(J6) -> 2022 | K7: =YEAR(K6) -> 2023 | L7: =YEAR(L6) -> 2024 | M7: =YEAR(M6) -> 2025 | N7: =YEAR(N6) -> 2026 | ... R7: =YEAR(R6) -> 2030
C8: Actual / Estimate | G8: =IF(G6<=Control!$E$11,"A","E") -> A | H8: =IF(H6<=Control!$E$11,"A","E") -> A | I8: =IF(I6<=Control!$E$11,"A","E") -> A | J8: =IF(J6<=Control!$E$11,"A","E") -> A | K8: =IF(K6<=Control!$E$11,"A","E") -> A | L8: =IF(L6<=Control!$E$11,"A","E") -> A | M8: =IF(M6<=Control!$E$11,"A","E") -> A | N8: =IF(N6<=Control!$E$11,"A","E") -> E | ... R8: =IF(R6<=Control!$E$11,"A","E") -> E
C10: Supporting Data
C11: A | D11: Revenue Build | E11: ="("&Control!$E$16&" in Actual)" -> (LCA in Actual)
C12: Laboratory:
C13: # of Tests | G13: 71942 | H13: 66041 | I13: 73822 | J13: 82138 | K13: 89179 | L13: 100453 | M13: 111021 | N13: =M13*(1+N14) -> 116905.11 | O13: =N13*(1+O14) -> 125322.28 | P13: =O13*(1+P14) -> 135724.03 | Q13: =P13*(1+Q14) -> 141152.99 | R13: =Q13*(1+R14) -> 153574.45
C14: Growth (%) | G14: =IFERROR(G13/F13-1,"N/A") -> N/A | H14: =IFERROR(H13/G13-1,"N/A") -> -0.082024409 | I14: =IFERROR(I13/H13-1,"N/A") -> 0.11782075 | J14: =IFERROR(J13/I13-1,"N/A") -> 0.11264935 | K14: =IFERROR(K13/J13-1,"N/A") -> 0.08572159 | L14: =IFERROR(L13/K13-1,"N/A") -> 0.1264199 | M14: =IFERROR(M13/L13-1,"N/A") -> 0.10520343 | N14: 0.053 | O14: 0.072 | P14: 0.083 | Q14: 0.04 | R14: 0.088
C15: Gross Revenue [per Test] (LCA) | G15: 36 | H15: 38 | I15: 41 | J15: 45 | K15: 47 | L15: 52 | M15: 57 | N15: =M15*(1+N16) -> 60.192 | O15: =N15*(1+O16) -> 63.081216 | P15: =O15*(1+P16) -> 65.982952 | Q15: =P15*(1+Q16) -> 69.414065 | R15: =Q15*(1+R16) -> 73.440081
C16: Growth (%) | G16: =IFERROR(G15/F15-1,"N/A") -> N/A | H16: =IFERROR(H15/G15-1,"N/A") -> 0.055555556 | I16: =IFERROR(I15/H15-1,"N/A") -> 0.078947368 | J16: =IFERROR(J15/I15-1,"N/A") -> 0.097560976 | K16: =IFERROR(K15/J15-1,"N/A") -> 0.044444444 | L16: =IFERROR(L15/K15-1,"N/A") -> 0.10638298 | M16: =IFERROR(M15/L15-1,"N/A") -> 0.096153846 | N16: 0.056 | O16: 0.048 | P16: 0.046 | Q16: 0.052 | R16: 0.058
C17: Revenue | G17: =G13*G15 -> 2589912 | H17: =H13*H15 -> 2509558 | I17: =I13*I15 -> 3026702 | J17: =J13*J15 -> 3696210 | K17: =K13*K15 -> 4191413 | L17: =L13*L15 -> 5223556 | M17: =M13*M15 -> 6328197 | N17: =N13*N15 -> 7036752.6 | ... R17: =R13*R15 -> 11278520
C19: Radiology:
C20: # of Tests | G20: 18306 | H20: 16987 | I20: 18274 | J20: 19518 | K20: 21243 | L20: 22998 | M20: 24489 | N20: =M20*(1+N21) -> 26056.296 | O20: =N20*(1+O21) -> 27463.336 | P20: =O20*(1+P21) -> 28809.039 | Q20: =P20*(1+Q21) -> 30739.245 | R20: =Q20*(1+R21) -> 32214.729
C21: Growth (%) | G21: =IFERROR(G20/F20-1,"N/A") -> N/A | H21: =IFERROR(H20/G20-1,"N/A") -> -0.072052879 | I21: =IFERROR(I20/H20-1,"N/A") -> 0.075763819 | J21: =IFERROR(J20/I20-1,"N/A") -> 0.06807486 | K21: =IFERROR(K20/J20-1,"N/A") -> 0.088379957 | L21: =IFERROR(L20/K20-1,"N/A") -> 0.08261545 | M21: =IFERROR(M20/L20-1,"N/A") -> 0.064831724 | N21: 0.064 | O21: 0.054 | P21: 0.049 | Q21: 0.067 | R21: 0.048
C22: Gross Revenue [per Test] (LCA) | G22: 115 | H22: 117 | I22: 123 | J22: 126 | K22: 130 | L22: 140 | M22: 145 | N22: =M22*(1+N23) -> 150.8 | O22: =N22*(1+O23) -> 157.2844 | P22: =O22*(1+P23) -> 164.04763 | Q22: =P22*(1+Q23) -> 171.59382 | R22: =Q22*(1+R23) -> 183.2622
C23: Growth (%) | G23: =IFERROR(G22/F22-1,"N/A") -> N/A | H23: =IFERROR(H22/G22-1,"N/A") -> 0.017391304 | I23: =IFERROR(I22/H22-1,"N/A") -> 0.051282051 | J23: =IFERROR(J22/I22-1,"N/A") -> 0.024390244 | K23: =IFERROR(K22/J22-1,"N/A") -> 0.031746032 | L23: =IFERROR(L22/K22-1,"N/A") -> 0.076923077 | M23: =IFERROR(M22/L22-1,"N/A") -> 0.035714286 | N23: 0.04 | O23: 0.043 | P23: 0.043 | Q23: 0.046 | R23: 0.068
C24: Revenue | G24: =G20*G22 -> 2105190 | H24: =H20*H22 -> 1987479 | I24: =I20*I22 -> 2247702 | J24: =J20*J22 -> 2459268 | K24: =K20*K22 -> 2761590 | L24: =L20*L22 -> 3219720 | M24: =M20*M22 -> 3550905 | N24: =N20*N22 -> 3929289.4 | ... R24: =R20*R22 -> 5903742.1
C26: Endoscopy:
C27: # of Visits | G27: 1241 | H27: 1153 | I27: 1230 | J27: 1330 | K27: 1444 | L27: 1545 | M27: 1720 | N27: =M27*(1+N28) -> 1823.2 | O27: =N27*(1+O28) -> 1919.8296 | P27: =O27*(1+P28) -> 2040.7789 | Q27: =P27*(1+Q28) -> 2144.8586 | R27: =Q27*(1+R28) -> 2320.737
C28: Growth (%) | G28: =IFERROR(G27/F27-1,"N/A") -> N/A | H28: =IFERROR(H27/G27-1,"N/A") -> -0.070910556 | I28: =IFERROR(I27/H27-1,"N/A") -> 0.066782307 | J28: =IFERROR(J27/I27-1,"N/A") -> 0.081300813 | K28: =IFERROR(K27/J27-1,"N/A") -> 0.085714286 | L28: =IFERROR(L27/K27-1,"N/A") -> 0.069944598 | M28: =IFERROR(M27/L27-1,"N/A") -> 0.11326861 | N28: 0.06 | O28: 0.053 | P28: 0.063 | Q28: 0.051 | R28: 0.082
C29: Gross Revenue [per Visit] (LCA) | G29: 774 | H29: 802 | I29: 869 | J29: 897 | K29: 948 | L29: 985 | M29: 1073 | N29: =M29*(1+N30) -> 1123.431 | O29: =N29*(1+O30) -> 1175.1088 | P29: =O29*(1+P30) -> 1239.7398 | Q29: =P29*(1+Q30) -> 1289.3294 | R29: =Q29*(1+R30) -> 1377.0038
C30: Growth (%) | G30: =IFERROR(G29/F29-1,"N/A") -> N/A | H30: =IFERROR(H29/G29-1,"N/A") -> 0.036175711 | I30: =IFERROR(I29/H29-1,"N/A") -> 0.083541147 | J30: =IFERROR(J29/I29-1,"N/A") -> 0.032220944 | K30: =IFERROR(K29/J29-1,"N/A") -> 0.056856187 | L30: =IFERROR(L29/K29-1,"N/A") -> 0.039029536 | M30: =IFERROR(M29/L29-1,"N/A") -> 0.089340102 | N30: 0.047 | O30: 0.046 | P30: 0.055 | Q30: 0.04 | R30: 0.068
C31: Revenue | G31: =G27*G29 -> 960534 | H31: =H27*H29 -> 924706 | I31: =I27*I29 -> 1068870 | J31: =J27*J29 -> 1193010 | K31: =K27*K29 -> 1368912 | L31: =L27*L29 -> 1521825 | M31: =M27*M29 -> 1845560 | N31: =N27*N29 -> 2048239.4 | ... R31: =R27*R29 -> 3195663.7
C33: Physiotherapy:
C34: # of Patients | G34: 3784 | H34: 3468 | I34: 3841 | J34: 4183 | K34: 4642 | L34: 4960 | M34: 5529 | N34: =M34*(1+N35) -> 5910.501 | O34: =N34*(1+O35) -> 6430.6251 | P34: =O34*(1+P35) -> 6932.2138 | Q34: =P34*(1+Q35) -> 7459.0621 | R34: =Q34*(1+R35) -> 8055.7871
C35: Growth (%) | G35: =IFERROR(G34/F34-1,"N/A") -> N/A | H35: =IFERROR(H34/G34-1,"N/A") -> -0.083509514 | I35: =IFERROR(I34/H34-1,"N/A") -> 0.10755479 | J35: =IFERROR(J34/I34-1,"N/A") -> 0.089039313 | K35: =IFERROR(K34/J34-1,"N/A") -> 0.10972986 | L35: =IFERROR(L34/K34-1,"N/A") -> 0.068504955 | M35: =IFERROR(M34/L34-1,"N/A") -> 0.11471774 | N35: 0.069 | O35: 0.088 | P35: 0.078 | Q35: 0.076 | R35: 0.08
C36: Gross Revenue [per Patient] (LCA) | G36: 104 | H36: 106 | I36: 111 | J36: 118 | K36: 124 | L36: 128 | M36: 142 | N36: =M36*(1+N37) -> 151.372 | O36: =N36*(1+O37) -> 159.39472 | P36: =O36*(1+P37) -> 166.40808 | Q36: =P36*(1+Q37) -> 174.56208 | R36: =Q36*(1+R37) -> 185.55949
C37: Growth (%) | G37: =IFERROR(G36/F36-1,"N/A") -> N/A | H37: =IFERROR(H36/G36-1,"N/A") -> 0.019230769 | I37: =IFERROR(I36/H36-1,"N/A") -> 0.047169811 | J37: =IFERROR(J36/I36-1,"N/A") -> 0.063063063 | K37: =IFERROR(K36/J36-1,"N/A") -> 0.050847458 | L37: =IFERROR(L36/K36-1,"N/A") -> 0.032258065 | M37: =IFERROR(M36/L36-1,"N/A") -> 0.109375 | N37: 0.066 | O37: 0.053 | P37: 0.044 | Q37: 0.049 | R37: 0.063
C38: Revenue | G38: =G34*G36 -> 393536 | H38: =H34*H36 -> 367608 | I38: =I34*I36 -> 426351 | J38: =J34*J36 -> 493594 | K38: =K34*K36 -> 575608 | L38: =L34*L36 -> 634880 | M38: =M34*M36 -> 785118 | N38: =N34*N36 -> 894684.36 | ... R38: =R34*R36 -> 1494827.7
C40: IVF:
C41: # of Patients | G41: 0 | H41: 0 | I41: 0 | J41: 0 | K41: 0 | L41: 0 | M41: 0 | N41: =M41*(1+N42) -> 0 | O41: =N41*(1+O42) -> 0 | P41: =O41*(1+P42) -> 0 | Q41: =P41*(1+Q42) -> 0 | R41: =Q41*(1+R42) -> 0
C42: Growth (%) | G42: =IFERROR(G41/F41-1,"N/A") -> N/A | H42: =IFERROR(H41/G41-1,"N/A") -> N/A | I42: =IFERROR(I41/H41-1,"N/A") -> N/A | J42: =IFERROR(J41/I41-1,"N/A") -> N/A | K42: =IFERROR(K41/J41-1,"N/A") -> N/A | L42: =IFERROR(L41/K41-1,"N/A") -> N/A | M42: =IFERROR(M41/L41-1,"N/A") -> N/A | N42: 0 | O42: 0 | P42: 0 | Q42: 0 | R42: 0
C43: Gross Revenue [per Patient] (LCA) | G43: 3860 | H43: 3854 | I43: 4006 | J43: 4154 | K43: 4389 | L43: 4698 | M43: 5086 | N43: =M43*(1+N44) -> 5304.698 | O43: =N43*(1+O44) -> 5548.7141 | P43: =O43*(1+P44) -> 5815.0524 | Q43: =P43*(1+Q44) -> 6210.4759 | R43: =Q43*(1+R44) -> 6514.7893
C44: Growth (%) | G44: =IFERROR(G43/F43-1,"N/A") -> N/A | H44: =IFERROR(H43/G43-1,"N/A") -> -0.0015544041 | I44: =IFERROR(I43/H43-1,"N/A") -> 0.039439543 | J44: =IFERROR(J43/I43-1,"N/A") -> 0.036944583 | K44: =IFERROR(K43/J43-1,"N/A") -> 0.056571979 | L44: =IFERROR(L43/K43-1,"N/A") -> 0.070403281 | M44: =IFERROR(M43/L43-1,"N/A") -> 0.082588335 | N44: 0.043 | O44: 0.046 | P44: 0.048 | Q44: 0.068 | R44: 0.049
C45: Revenue | G45: =G41*G43 -> 0 | H45: =H41*H43 -> 0 | I45: =I41*I43 -> 0 | J45: =J41*J43 -> 0 | K45: =K41*K43 -> 0 | L45: =L41*L43 -> 0 | M45: =M41*M43 -> 0 | N45: =N41*N43 -> 0 | ... R45: =R41*R43 -> 0
C47: Anapath:
C48: # of Patients | G48: 5286 | H48: 4911 | I48: 5362 | J48: 5881 | K48: 6277 | L48: 6722 | M48: 7105 | N48: =M48*(1+N49) -> 7424.725 | O48: =N48*(1+O49) -> 8033.5525 | P48: =O48*(1+P49) -> 8395.0623 | Q48: =P48*(1+Q49) -> 8974.3216 | R48: =Q48*(1+R49) -> 9432.012
C49: Growth (%) | G49: =IFERROR(G48/F48-1,"N/A") -> N/A | H49: =IFERROR(H48/G48-1,"N/A") -> -0.070942111 | I49: =IFERROR(I48/H48-1,"N/A") -> 0.091834657 | J49: =IFERROR(J48/I48-1,"N/A") -> 0.096792242 | K49: =IFERROR(K48/J48-1,"N/A") -> 0.067335487 | L49: =IFERROR(L48/K48-1,"N/A") -> 0.070893739 | M49: =IFERROR(M48/L48-1,"N/A") -> 0.05697709 | N49: 0.045 | O49: 0.082 | P49: 0.045 | Q49: 0.069 | R49: 0.051
...

Sheet 3. AHG North
C3: =Cover!$C$3 -> Project Dunecrest | D3: Confidential
C4: AHG North – Operating Build
C6: Fiscal Year Ending | G6: 43830 | H6: 44196 | I6: 44561 | J6: 44926 | K6: =EOMONTH(J6,12) -> 45291 | L6: =EOMONTH(K6,12) -> 45657 | M6: =EOMONTH(L6,12) -> 46022 | N6: =EOMONTH(M6,12) -> 46387 | O6: =EOMONTH(N6,12) -> 46752 | P6: =EOMONTH(O6,12) -> 47118 | Q6: =EOMONTH(P6,12) -> 47483 | R6: =EOMONTH(Q6,12) -> 47848
C7: Fiscal Year | G7: =YEAR(G6) -> 2019 | H7: =YEAR(H6) -> 2020 | I7: =YEAR(I6) -> 2021 | J7: =YEAR(J6) -> 2022 | K7: =YEAR(K6) -> 2023 | L7: =YEAR(L6) -> 2024 | M7: =YEAR(M6) -> 2025 | N7: =YEAR(N6) -> 2026 | ... R7: =YEAR(R6) -> 2030
C8: Actual / Estimate | G8: =IF(G6<=Control!$E$11,"A","E") -> A | H8: =IF(H6<=Control!$E$11,"A","E") -> A | I8: =IF(I6<=Control!$E$11,"A","E") -> A | J8: =IF(J6<=Control!$E$11,"A","E") -> A | K8: =IF(K6<=Control!$E$11,"A","E") -> A | L8: =IF(L6<=Control!$E$11,"A","E") -> A | M8: =IF(M6<=Control!$E$11,"A","E") -> A | N8: =IF(N6<=Control!$E$11,"A","E") -> E | ... R8: =IF(R6<=Control!$E$11,"A","E") -> E
C10: Supporting Data
C11: A | D11: Revenue Build | E11: ="("&Control!$E$16&" in Actual)" -> (LCA in Actual)
C12: Laboratory:
C13: # of Tests | G13: 86794 | H13: 81290 | I13: 89725 | J13: 96714 | K13: 100874 | L13: 108543 | M13: 116434 | N13: =M13*(1+N14) -> 123070.74 | O13: =N13*(1+O14) -> 129347.35 | P13: =O13*(1+P14) -> 135426.67 | Q13: =P13*(1+Q14) -> 143687.7 | R13: =Q13*(1+R14) -> 156332.22
C14: Growth (%) | G14: =IFERROR(G13/F13-1,"N/A") -> N/A | H14: =IFERROR(H13/G13-1,"N/A") -> -0.063414522 | I14: =IFERROR(I13/H13-1,"N/A") -> 0.1037643 | J14: =IFERROR(J13/I13-1,"N/A") -> 0.077893564 | K14: =IFERROR(K13/J13-1,"N/A") -> 0.043013421 | L14: =IFERROR(L13/K13-1,"N/A") -> 0.076025537 | M14: =IFERROR(M13/L13-1,"N/A") -> 0.072699299 | N14: 0.057 | O14: 0.051 | P14: 0.047 | Q14: 0.061 | R14: 0.088
C15: Gross Revenue [per Test] (LCA) | G15: 35 | H15: 36 | I15: 39 | J15: 42 | K15: 47 | L15: 50 | M15: 54 | N15: =M15*(1+N16) -> 56.862 | O15: =N15*(1+O16) -> 59.7051 | P15: =O15*(1+P16) -> 63.765047 | Q15: =P15*(1+Q16) -> 66.825769 | R15: =Q15*(1+R16) -> 71.436747
C16: Growth (%) | G16: =IFERROR(G15/F15-1,"N/A") -> N/A | H16: =IFERROR(H15/G15-1,"N/A") -> 0.028571429 | I16: =IFERROR(I15/H15-1,"N/A") -> 0.083333333 | J16: =IFERROR(J15/I15-1,"N/A") -> 0.076923077 | K16: =IFERROR(K15/J15-1,"N/A") -> 0.11904762 | L16: =IFERROR(L15/K15-1,"N/A") -> 0.063829787 | M16: =IFERROR(M15/L15-1,"N/A") -> 0.08 | N16: 0.053 | O16: 0.05 | P16: 0.068 | Q16: 0.048 | R16: 0.069
C17: Revenue | G17: =G13*G15 -> 3037790 | H17: =H13*H15 -> 2926440 | I17: =I13*I15 -> 3499275 | J17: =J13*J15 -> 4061988 | K17: =K13*K15 -> 4741078 | L17: =L13*L15 -> 5427150 | M17: =M13*M15 -> 6287436 | N17: =N13*N15 -> 6998048.3 | ... R17: =R13*R15 -> 11167865
C19: Radiology:
C20: # of Tests | G20: 21800 | H20: 19729 | I20: 21601 | J20: 23313 | K20: 24821 | L20: 25868 | M20: 28657 | N20: =M20*(1+N21) -> 30548.362 | O20: =N20*(1+O21) -> 32503.457 | P20: =O20*(1+P21) -> 34161.133 | Q20: =P20*(1+Q21) -> 36996.508 | R20: =Q20*(1+R21) -> 39623.26
C21: Growth (%) | G21: =IFERROR(G20/F20-1,"N/A") -> N/A | H21: =IFERROR(H20/G20-1,"N/A") -> -0.095 | I21: =IFERROR(I20/H20-1,"N/A") -> 0.094885701 | J21: =IFERROR(J20/I20-1,"N/A") -> 0.07925559 | K21: =IFERROR(K20/J20-1,"N/A") -> 0.06468494 | L21: =IFERROR(L20/K20-1,"N/A") -> 0.042182023 | M21: =IFERROR(M20/L20-1,"N/A") -> 0.10781661 | N21: 0.066 | O21: 0.064 | P21: 0.051 | Q21: 0.083 | R21: 0.071
C22: Gross Revenue [per Test] (LCA) | G22: 116 | H22: 114 | I22: 121 | J22: 131 | K22: 143 | L22: 153 | M22: 162 | N22: =M22*(1+N23) -> 169.938 | O22: =N22*(1+O23) -> 180.64409 | P22: =O22*(1+P23) -> 188.59243 | Q22: =P22*(1+Q23) -> 196.70191 | R22: =Q22*(1+R23) -> 207.91392
C23: Growth (%) | G23: =IFERROR(G22/F22-1,"N/A") -> N/A | H23: =IFERROR(H22/G22-1,"N/A") -> -0.017241379 | I23: =IFERROR(I22/H22-1,"N/A") -> 0.061403509 | J23: =IFERROR(J22/I22-1,"N/A") -> 0.082644628 | K23: =IFERROR(K22/J22-1,"N/A") -> 0.091603053 | L23: =IFERROR(L22/K22-1,"N/A") -> 0.06993007 | M23: =IFERROR(M22/L22-1,"N/A") -> 0.058823529 | N23: 0.049 | O23: 0.063 | P23: 0.044 | Q23: 0.043 | R23: 0.057
C24: Revenue | G24: =G20*G22 -> 2528800 | H24: =H20*H22 -> 2249106 | I24: =I20*I22 -> 2613721 | J24: =J20*J22 -> 3054003 | K24: =K20*K22 -> 3549403 | L24: =L20*L22 -> 3957804 | M24: =M20*M22 -> 4642434 | N24: =N20*N22 -> 5191327.5 | ... R24: =R20*R22 -> 8238227.1
C26: Endoscopy:
C27: # of Visits | G27: 1542 | H27: 1451 | I27: 1582 | J27: 1670 | K27: 1843 | L27: 1952 | M27: 2089 | N27: =M27*(1+N28) -> 2210.162 | O27: =N27*(1+O28) -> 2364.8733 | P27: =O27*(1+P28) -> 2572.9822 | Q27: =P27*(1+Q28) -> 2704.2043 | R27: =Q27*(1+R28) -> 2820.4851
C28: Growth (%) | G28: =IFERROR(G27/F27-1,"N/A") -> N/A | H28: =IFERROR(H27/G27-1,"N/A") -> -0.059014267 | I28: =IFERROR(I27/H27-1,"N/A") -> 0.090282564 | J28: =IFERROR(J27/I27-1,"N/A") -> 0.05562579 | K28: =IFERROR(K27/J27-1,"N/A") -> 0.10359281 | L28: =IFERROR(L27/K27-1,"N/A") -> 0.059142702 | M28: =IFERROR(M27/L27-1,"N/A") -> 0.070184426 | N28: 0.058 | O28: 0.07 | P28: 0.088 | Q28: 0.051 | R28: 0.043
C29: Gross Revenue [per Visit] (LCA) | G29: 777 | H29: 791 | I29: 839 | J29: 898 | K29: 942 | L29: 984 | M29: 1077 | N29: =M29*(1+N30) -> 1139.466 | O29: =N29*(1+O30) -> 1219.2286 | P29: =O29*(1+P30) -> 1300.9169 | Q29: =P29*(1+Q30) -> 1368.5646 | R29: =Q29*(1+R30) -> 1446.5728
C30: Growth (%) | G30: =IFERROR(G29/F29-1,"N/A") -> N/A | H30: =IFERROR(H29/G29-1,"N/A") -> 0.018018018 | I30: =IFERROR(I29/H29-1,"N/A") -> 0.06068268 | J30: =IFERROR(J29/I29-1,"N/A") -> 0.070321812 | K30: =IFERROR(K29/J29-1,"N/A") -> 0.048997773 | L30: =IFERROR(L29/K29-1,"N/A") -> 0.044585987 | M30: =IFERROR(M29/L29-1,"N/A") -> 0.094512195 | N30: 0.058 | O30: 0.07 | P30: 0.067 | Q30: 0.052 | R30: 0.057
C31: Revenue | G31: =G27*G29 -> 1198134 | H31: =H27*H29 -> 1147741 | I31: =I27*I29 -> 1327298 | J31: =J27*J29 -> 1499660 | K31: =K27*K29 -> 1736106 | L31: =L27*L29 -> 1920768 | M31: =M27*M29 -> 2249853 | N31: =N27*N29 -> 2518404.5 | ... R31: =R27*R29 -> 4080037
C33: Physiotherapy:
C34: # of Patients | G34: 4412 | H34: 4102 | I34: 4506 | J34: 4959 | K34: 5512 | L34: 5798 | M34: 6293 | N34: =M34*(1+N35) -> 6582.478 | O34: =N34*(1+O35) -> 7062.9989 | P34: =O34*(1+P35) -> 7635.1018 | Q34: =P34*(1+Q35) -> 8177.194 | R34: =Q34*(1+R35) -> 8545.1678
C35: Growth (%) | G35: =IFERROR(G34/F34-1,"N/A") -> N/A | H35: =IFERROR(H34/G34-1,"N/A") -> -0.070262919 | I35: =IFERROR(I34/H34-1,"N/A") -> 0.098488542 | J35: =IFERROR(J34/I34-1,"N/A") -> 0.10053262 | K35: =IFERROR(K34/J34-1,"N/A") -> 0.11151442 | L35: =IFERROR(L34/K34-1,"N/A") -> 0.051886792 | M35: =IFERROR(M34/L34-1,"N/A") -> 0.085374267 | N35: 0.046 | O35: 0.073 | P35: 0.081 | Q35: 0.071 | R35: 0.045
C36: Gross Revenue [per Patient] (LCA) | G36: 105 | H36: 106 | I36: 111 | J36: 118 | K36: 128 | L36: 131 | M36: 138 | N36: =M36*(1+N37) -> 147.246 | O36: =N36*(1+O37) -> 154.90279 | P36: =O36*(1+P37) -> 164.97147 | Q36: =P36*(1+Q37) -> 173.38502 | R36: =Q36*(1+R37) -> 180.66719
C37: Growth (%) | G37: =IFERROR(G36/F36-1,"N/A") -> N/A | H37: =IFERROR(H36/G36-1,"N/A") -> 0.0095238095 | I37: =IFERROR(I36/H36-1,"N/A") -> 0.047169811 | J37: =IFERROR(J36/I36-1,"N/A") -> 0.063063063 | K37: =IFERROR(K36/J36-1,"N/A") -> 0.084745763 | L37: =IFERROR(L36/K36-1,"N/A") -> 0.0234375 | M37: =IFERROR(M36/L36-1,"N/A") -> 0.053435115 | N37: 0.067 | O37: 0.052 | P37: 0.065 | Q37: 0.051 | R37: 0.042
C38: Revenue | G38: =G34*G36 -> 463260 | H38: =H34*H36 -> 434812 | I38: =I34*I36 -> 500166 | J38: =J34*J36 -> 585162 | K38: =K34*K36 -> 705536 | L38: =L34*L36 -> 759538 | M38: =M34*M36 -> 868434 | N38: =N34*N36 -> 969243.56 | ... R38: =R34*R36 -> 1543831.4
C40: IVF:
C41: # of Patients | G41: 0 | H41: 0 | I41: 0 | J41: 0 | K41: 0 | L41: 0 | M41: 0 | N41: =M41*(1+N42) -> 0 | O41: =N41*(1+O42) -> 0 | P41: =O41*(1+P42) -> 0 | Q41: =P41*(1+Q42) -> 0 | R41: =Q41*(1+R42) -> 0
C42: Growth (%) | G42: =IFERROR(G41/F41-1,"N/A") -> N/A | H42: =IFERROR(H41/G41-1,"N/A") -> N/A | I42: =IFERROR(I41/H41-1,"N/A") -> N/A | J42: =IFERROR(J41/I41-1,"N/A") -> N/A | K42: =IFERROR(K41/J41-1,"N/A") -> N/A | L42: =IFERROR(L41/K41-1,"N/A") -> N/A | M42: =IFERROR(M41/L41-1,"N/A") -> N/A | N42: 0 | O42: 0 | P42: 0 | Q42: 0 | R42: 0
C43: Gross Revenue [per Patient] (LCA) | G43: 3933 | H43: 3970 | I43: 4128 | J43: 4401 | K43: 4681 | L43: 4864 | M43: 5008 | N43: =M43*(1+N44) -> 5308.48 | O43: =N43*(1+O44) -> 5642.9142 | P43: =O43*(1+P44) -> 5936.3458 | Q43: =P43*(1+Q44) -> 6298.4629 | R43: =Q43*(1+R44) -> 6644.8783
C44: Growth (%) | G44: =IFERROR(G43/F43-1,"N/A") -> N/A | H44: =IFERROR(H43/G43-1,"N/A") -> 0.0094075769 | I44: =IFERROR(I43/H43-1,"N/A") -> 0.039798489 | J44: =IFERROR(J43/I43-1,"N/A") -> 0.066133721 | K44: =IFERROR(K43/J43-1,"N/A") -> 0.063621904 | L44: =IFERROR(L43/K43-1,"N/A") -> 0.039094211 | M44: =IFERROR(M43/L43-1,"N/A") -> 0.029605263 | N44: 0.06 | O44: 0.063 | P44: 0.052 | Q44: 0.061 | R44: 0.055
C45: Revenue | G45: =G41*G43 -> 0 | H45: =H41*H43 -> 0 | I45: =I41*I43 -> 0 | J45: =J41*J43 -> 0 | K45: =K41*K43 -> 0 | L45: =L41*L43 -> 0 | M45: =M41*M43 -> 0 | N45: =N41*N43 -> 0 | ... R45: =R41*R43 -> 0
C47: Anapath:
C48: # of Patients | G48: 5969 | H48: 5421 | I48: 5896 | J48: 6412 | K48: 6919 | L48: 7639 | M48: 8207 | N48: =M48*(1+N49) -> 8904.595 | O48: =N48*(1+O49) -> 9563.535 | P48: =O48*(1+P49) -> 10051.275 | Q48: =P48*(1+Q49) -> 10573.942 | R48: =Q48*(1+R49) -> 11155.508
C49: Growth (%) | G49: =IFERROR(G48/F48-1,"N/A") -> N/A | H49: =IFERROR(H48/G48-1,"N/A") -> -0.091807673 | I49: =IFERROR(I48/H48-1,"N/A") -> 0.08762221 | J49: =IFERROR(J48/I48-1,"N/A") -> 0.087516961 | K49: =IFERROR(K48/J48-1,"N/A") -> 0.079070493 | L49: =IFERROR(L48/K48-1,"N/A") -> 0.10406128 | M49: =IFERROR(M48/L48-1,"N/A") -> 0.074355282 | N49: 0.085 | O49: 0.074 | P49: 0.051 | Q49: 0.052 | R49: 0.055
...

Sheet 4. AHG Park
C3: =Cover!$C$3 -> Project Dunecrest | D3: Confidential
C4: AHG Park – Operating Build
C6: Fiscal Year Ending | G6: 43830 | H6: 44196 | I6: 44561 | J6: 44926 | K6: =EOMONTH(J6,12) -> 45291 | L6: =EOMONTH(K6,12) -> 45657 | M6: =EOMONTH(L6,12) -> 46022 | N6: =EOMONTH(M6,12) -> 46387 | O6: =EOMONTH(N6,12) -> 46752 | P6: =EOMONTH(O6,12) -> 47118 | Q6: =EOMONTH(P6,12) -> 47483 | R6: =EOMONTH(Q6,12) -> 47848
C7: Fiscal Year | G7: =YEAR(G6) -> 2019 | H7: =YEAR(H6) -> 2020 | I7: =YEAR(I6) -> 2021 | J7: =YEAR(J6) -> 2022 | K7: =YEAR(K6) -> 2023 | L7: =YEAR(L6) -> 2024 | M7: =YEAR(M6) -> 2025 | N7: =YEAR(N6) -> 2026 | ... R7: =YEAR(R6) -> 2030
C8: Actual / Estimate | G8: =IF(G6<=Control!$E$11,"A","E") -> A | H8: =IF(H6<=Control!$E$11,"A","E") -> A | I8: =IF(I6<=Control!$E$11,"A","E") -> A | J8: =IF(J6<=Control!$E$11,"A","E") -> A | K8: =IF(K6<=Control!$E$11,"A","E") -> A | L8: =IF(L6<=Control!$E$11,"A","E") -> A | M8: =IF(M6<=Control!$E$11,"A","E") -> A | N8: =IF(N6<=Control!$E$11,"A","E") -> E | ... R8: =IF(R6<=Control!$E$11,"A","E") -> E
C10: Supporting Data
C11: A | D11: Revenue Build | E11: ="("&Control!$E$16&" in Actual)" -> (LCA in Actual)
C12: Laboratory:
C13: # of Tests | G13: 65182 | H13: 59935 | I13: 63531 | J13: 69282 | K13: 76441 | L13: 82362 | M13: 90213 | N13: =M13*(1+N14) -> 95084.502 | O13: =N13*(1+O14) -> 102881.43 | P13: =O13*(1+P14) -> 107305.33 | Q13: =P13*(1+Q14) -> 116962.81 | R13: =Q13*(1+R14) -> 124565.4
C14: Growth (%) | G14: =IFERROR(G13/F13-1,"N/A") -> N/A | H14: =IFERROR(H13/G13-1,"N/A") -> -0.080497683 | I14: =IFERROR(I13/H13-1,"N/A") -> 0.059998332 | J14: =IFERROR(J13/I13-1,"N/A") -> 0.090522737 | K14: =IFERROR(K13/J13-1,"N/A") -> 0.10333131 | L14: =IFERROR(L13/K13-1,"N/A") -> 0.077458432 | M14: =IFERROR(M13/L13-1,"N/A") -> 0.095323086 | N14: 0.054 | O14: 0.082 | P14: 0.043 | Q14: 0.09 | R14: 0.065
C15: Gross Revenue [per Test] (LCA) | G15: 36 | H15: 38 | I15: 42 | J15: 46 | K15: 48 | L15: 52 | M15: 55 | N15: =M15*(1+N16) -> 57.915 | O15: =N15*(1+O16) -> 61.3899 | P15: =O15*(1+P16) -> 64.213835 | Q15: =P15*(1+Q16) -> 66.910816 | R15: =Q15*(1+R16) -> 70.256357
C16: Growth (%) | G16: =IFERROR(G15/F15-1,"N/A") -> N/A | H16: =IFERROR(H15/G15-1,"N/A") -> 0.055555556 | I16: =IFERROR(I15/H15-1,"N/A") -> 0.10526316 | J16: =IFERROR(J15/I15-1,"N/A") -> 0.095238095 | K16: =IFERROR(K15/J15-1,"N/A") -> 0.043478261 | L16: =IFERROR(L15/K15-1,"N/A") -> 0.083333333 | M16: =IFERROR(M15/L15-1,"N/A") -> 0.057692308 | N16: 0.053 | O16: 0.06 | P16: 0.046 | Q16: 0.042 | R16: 0.05
C17: Revenue | G17: =G13*G15 -> 2346552 | H17: =H13*H15 -> 2277530 | I17: =I13*I15 -> 2668302 | J17: =J13*J15 -> 3186972 | K17: =K13*K15 -> 3669168 | L17: =L13*L15 -> 4282824 | M17: =M13*M15 -> 4961715 | N17: =N13*N15 -> 5506818.9 | ... R17: =R13*R15 -> 8751510.9
C19: Radiology:
C20: # of Tests | G20: 16802 | H20: 15984 | I20: 17340 | J20: 18721 | K20: 19759 | L20: 21541 | M20: 23467 | N20: =M20*(1+N21) -> 24616.883 | O20: =N20*(1+O21) -> 26020.045 | P20: =O20*(1+P21) -> 27269.008 | Q20: =P20*(1+Q21) -> 28986.955 | R20: =Q20*(1+R21) -> 31508.82
C21: Growth (%) | G21: =IFERROR(G20/F20-1,"N/A") -> N/A | H21: =IFERROR(H20/G20-1,"N/A") -> -0.04868468 | I21: =IFERROR(I20/H20-1,"N/A") -> 0.084834835 | J21: =IFERROR(J20/I20-1,"N/A") -> 0.079642445 | K21: =IFERROR(K20/J20-1,"N/A") -> 0.055445756 | L21: =IFERROR(L20/K20-1,"N/A") -> 0.09018675 | M21: =IFERROR(M20/L20-1,"N/A") -> 0.089410891 | N21: 0.049 | O21: 0.057 | P21: 0.048 | Q21: 0.063 | R21: 0.087
C22: Gross Revenue [per Test] (LCA) | G22: 116 | H22: 115 | I22: 125 | J22: 130 | K22: 137 | L22: 143 | M22: 152 | N22: =M22*(1+N23) -> 161.576 | O22: =N22*(1+O23) -> 169.6548 | P22: =O22*(1+P23) -> 178.47685 | Q22: =P22*(1+Q23) -> 188.29308 | R22: =Q22*(1+R23) -> 197.70773
C23: Growth (%) | G23: =IFERROR(G22/F22-1,"N/A") -> N/A | H23: =IFERROR(H22/G22-1,"N/A") -> -0.0086206897 | I23: =IFERROR(I22/H22-1,"N/A") -> 0.086956522 | J23: =IFERROR(J22/I22-1,"N/A") -> 0.04 | K23: =IFERROR(K22/J22-1,"N/A") -> 0.053846154 | L23: =IFERROR(L22/K22-1,"N/A") -> 0.04379562 | M23: =IFERROR(M22/L22-1,"N/A") -> 0.062937063 | N23: 0.063 | O23: 0.05 | P23: 0.052 | Q23: 0.055 | R23: 0.05
C24: Revenue | G24: =G20*G22 -> 1949032 | H24: =H20*H22 -> 1838160 | I24: =I20*I22 -> 2167500 | J24: =J20*J22 -> 2433730 | K24: =K20*K22 -> 2706983 | L24: =L20*L22 -> 3080363 | M24: =M20*M22 -> 3566984 | N24: =N20*N22 -> 3977497.5 | ... R24: =R20*R22 -> 6229537.3
C26: Endoscopy:
C27: # of Visits | G27: 0 | H27: 0 | I27: 0 | J27: 0 | K27: 0 | L27: 0 | M27: 0 | N27: =M27*(1+N28) -> 0 | O27: =N27*(1+O28) -> 0 | P27: =O27*(1+P28) -> 0 | Q27: =P27*(1+Q28) -> 0 | R27: =Q27*(1+R28) -> 0
C28: Growth (%) | G28: =IFERROR(G27/F27-1,"N/A") -> N/A | H28: =IFERROR(H27/G27-1,"N/A") -> N/A | I28: =IFERROR(I27/H27-1,"N/A") -> N/A | J28: =IFERROR(J27/I27-1,"N/A") -> N/A | K28: =IFERROR(K27/J27-1,"N/A") -> N/A | L28: =IFERROR(L27/K27-1,"N/A") -> N/A | M28: =IFERROR(M27/L27-1,"N/A") -> N/A | N28: 0 | O28: 0 | P28: 0 | Q28: 0 | R28: 0
C29: Gross Revenue [per Visit] (LCA) | G29: 745 | H29: 756 | I29: 808 | J29: 858 | K29: 943 | L29: 1034 | M29: 1087 | N29: =M29*(1+N30) -> 1147.872 | O29: =N29*(1+O30) -> 1193.7869 | P29: =O29*(1+P30) -> 1267.8017 | Q29: =P29*(1+Q30) -> 1323.5849 | R29: =Q29*(1+R30) -> 1412.2651
C30: Growth (%) | G30: =IFERROR(G29/F29-1,"N/A") -> N/A | H30: =IFERROR(H29/G29-1,"N/A") -> 0.014765101 | I30: =IFERROR(I29/H29-1,"N/A") -> 0.068783069 | J30: =IFERROR(J29/I29-1,"N/A") -> 0.061881188 | K30: =IFERROR(K29/J29-1,"N/A") -> 0.099067599 | L30: =IFERROR(L29/K29-1,"N/A") -> 0.09650053 | M30: =IFERROR(M29/L29-1,"N/A") -> 0.051257253 | N30: 0.056 | O30: 0.04 | P30: 0.062 | Q30: 0.044 | R30: 0.067
C31: Revenue | G31: =G27*G29 -> 0 | H31: =H27*H29 -> 0 | I31: =I27*I29 -> 0 | J31: =J27*J29 -> 0 | K31: =K27*K29 -> 0 | L31: =L27*L29 -> 0 | M31: =M27*M29 -> 0 | N31: =N27*N29 -> 0 | ... R31: =R27*R29 -> 0
C33: Physiotherapy:
C34: # of Patients | G34: 3334 | H34: 3048 | I34: 3317 | J34: 3728 | K34: 3975 | L34: 4373 | M34: 4931 | N34: =M34*(1+N35) -> 5310.687 | O34: =N34*(1+O35) -> 5756.7847 | P34: =O34*(1+P35) -> 5987.0561 | Q34: =P34*(1+Q35) -> 6507.93 | R34: =Q34*(1+R35) -> 6983.0089
C35: Growth (%) | G35: =IFERROR(G34/F34-1,"N/A") -> N/A | H35: =IFERROR(H34/G34-1,"N/A") -> -0.085782843 | I35: =IFERROR(I34/H34-1,"N/A") -> 0.088254593 | J35: =IFERROR(J34/I34-1,"N/A") -> 0.12390715 | K35: =IFERROR(K34/J34-1,"N/A") -> 0.066255365 | L35: =IFERROR(L34/K34-1,"N/A") -> 0.10012579 | M35: =IFERROR(M34/L34-1,"N/A") -> 0.12760119 | N35: 0.077 | O35: 0.084 | P35: 0.04 | Q35: 0.087 | R35: 0.073
C36: Gross Revenue [per Patient] (LCA) | G36: 104 | H36: 104 | I36: 109 | J36: 117 | K36: 129 | L36: 138 | M36: 143 | N36: =M36*(1+N37) -> 151.866 | O36: =N36*(1+O37) -> 161.43356 | P36: =O36*(1+P37) -> 172.41104 | Q36: =P36*(1+Q37) -> 180.68677 | R36: =Q36*(1+R37) -> 190.98592
C37: Growth (%) | G37: =IFERROR(G36/F36-1,"N/A") -> N/A | H37: =IFERROR(H36/G36-1,"N/A") -> 0 | I37: =IFERROR(I36/H36-1,"N/A") -> 0.048076923 | J37: =IFERROR(J36/I36-1,"N/A") -> 0.073394495 | K37: =IFERROR(K36/J36-1,"N/A") -> 0.1025641 | L37: =IFERROR(L36/K36-1,"N/A") -> 0.069767442 | M37: =IFERROR(M36/L36-1,"N/A") -> 0.036231884 | N37: 0.062 | O37: 0.063 | P37: 0.068 | Q37: 0.048 | R37: 0.057
C38: Revenue | G38: =G34*G36 -> 346736 | H38: =H34*H36 -> 316992 | I38: =I34*I36 -> 361553 | J38: =J34*J36 -> 436176 | K38: =K34*K36 -> 512775 | L38: =L34*L36 -> 603474 | M38: =M34*M36 -> 705133 | N38: =N34*N36 -> 806512.79 | ... R38: =R34*R36 -> 1333656.3
C40: IVF:
C41: # of Patients | G41: 150 | H41: 142 | I41: 158 | J41: 168 | K41: 187 | L41: 207 | M41: 219 | N41: =M41*(1+N42) -> 236.958 | O41: =N41*(1+O42) -> 248.09503 | P41: =O41*(1+P42) -> 267.94263 | Q41: =P41*(1+Q42) -> 285.62684 | R41: =Q41*(1+R42) -> 310.19075
C42: Growth (%) | G42: =IFERROR(G41/F41-1,"N/A") -> N/A | H42: =IFERROR(H41/G41-1,"N/A") -> -0.053333333 | I42: =IFERROR(I41/H41-1,"N/A") -> 0.11267606 | J42: =IFERROR(J41/I41-1,"N/A") -> 0.063291139 | K42: =IFERROR(K41/J41-1,"N/A") -> 0.11309524 | L42: =IFERROR(L41/K41-1,"N/A") -> 0.10695187 | M42: =IFERROR(M41/L41-1,"N/A") -> 0.057971014 | N42: 0.082 | O42: 0.047 | P42: 0.08 | Q42: 0.066 | R42: 0.086
C43: Gross Revenue [per Patient] (LCA) | G43: 3952 | H43: 3936 | I43: 4194 | J43: 4392 | K43: 4744 | L43: 4983 | M43: 5183 | N43: =M43*(1+N44) -> 5426.601 | O43: =N43*(1+O44) -> 5784.7567 | P43: =O43*(1+P44) -> 6091.3488 | Q43: =P43*(1+Q44) -> 6383.7335 | R43: =Q43*(1+R44) -> 6811.4437
C44: Growth (%) | G44: =IFERROR(G43/F43-1,"N/A") -> N/A | H44: =IFERROR(H43/G43-1,"N/A") -> -0.004048583 | I44: =IFERROR(I43/H43-1,"N/A") -> 0.06554878 | J44: =IFERROR(J43/I43-1,"N/A") -> 0.0472103 | K44: =IFERROR(K43/J43-1,"N/A") -> 0.080145719 | L44: =IFERROR(L43/K43-1,"N/A") -> 0.050379427 | M44: =IFERROR(M43/L43-1,"N/A") -> 0.040136464 | N44: 0.047 | O44: 0.066 | P44: 0.053 | Q44: 0.048 | R44: 0.067
C45: Revenue | G45: =G41*G43 -> 592800 | H45: =H41*H43 -> 558912 | I45: =I41*I43 -> 662652 | J45: =J41*J43 -> 737856 | K45: =K41*K43 -> 887128 | L45: =L41*L43 -> 1031481 | M45: =M41*M43 -> 1135077 | N45: =N41*N43 -> 1285876.5 | ... R45: =R41*R43 -> 2112846.8
C47: Anapath:
C48: # of Patients | G48: 4428 | H48: 4204 | I48: 4465 | J48: 4686 | K48: 5080 | L48: 5552 | M48: 5957 | N48: =M48*(1+N49) -> 6373.99 | O48: =N48*(1+O49) -> 6711.8115 | P48: =O48*(1+P49) -> 7174.9265 | Q48: =P48*(1+Q49) -> 7648.4716 | R48: =Q48*(1+R49) -> 8267.9978
C49: Growth (%) | G49: =IFERROR(G48/F48-1,"N/A") -> N/A | H49: =IFERROR(H48/G48-1,"N/A") -> -0.050587173 | I49: =IFERROR(I48/H48-1,"N/A") -> 0.06208373 | J49: =IFERROR(J48/I48-1,"N/A") -> 0.049496081 | K49: =IFERROR(K48/J48-1,"N/A") -> 0.084080239 | L49: =IFERROR(L48/K48-1,"N/A") -> 0.092913386 | M49: =IFERROR(M48/L48-1,"N/A") -> 0.072946686 | N49: 0.07 | O49: 0.053 | P49: 0.069 | Q49: 0.066 | R49: 0.081
...

Sheet 5. AHG Diagnostics
C3: =Cover!$C$3 -> Project Dunecrest | D3: Confidential
C4: AHG Diagnostics – Simplified Build (lab & imaging)
C6: Fiscal Year Ending | G6: 43830 | H6: 44196 | I6: 44561 | J6: 44926 | K6: =EOMONTH(J6,12) -> 45291 | L6: =EOMONTH(K6,12) -> 45657 | M6: =EOMONTH(L6,12) -> 46022 | N6: =EOMONTH(M6,12) -> 46387 | O6: =EOMONTH(N6,12) -> 46752 | P6: =EOMONTH(O6,12) -> 47118 | Q6: =EOMONTH(P6,12) -> 47483 | R6: =EOMONTH(Q6,12) -> 47848
C7: Fiscal Year | G7: =YEAR(G6) -> 2019 | H7: =YEAR(H6) -> 2020 | I7: =YEAR(I6) -> 2021 | J7: =YEAR(J6) -> 2022 | K7: =YEAR(K6) -> 2023 | L7: =YEAR(L6) -> 2024 | M7: =YEAR(M6) -> 2025 | N7: =YEAR(N6) -> 2026 | ... R7: =YEAR(R6) -> 2030
C8: Actual / Estimate | G8: =IF(G6<=Control!$E$11,"A","E") -> A | H8: =IF(H6<=Control!$E$11,"A","E") -> A | I8: =IF(I6<=Control!$E$11,"A","E") -> A | J8: =IF(J6<=Control!$E$11,"A","E") -> A | K8: =IF(K6<=Control!$E$11,"A","E") -> A | L8: =IF(L6<=Control!$E$11,"A","E") -> A | M8: =IF(M6<=Control!$E$11,"A","E") -> A | N8: =IF(N6<=Control!$E$11,"A","E") -> E | ... R8: =IF(R6<=Control!$E$11,"A","E") -> E
C10: Supporting Data
C11: A | D11: Revenue & Cost Build | E11: ="("&Control!$E$16&" in Actual)" -> (LCA in Actual)
C12: Revenue (LCA) | G12: 4607000 | H12: 4570000 | I12: 5078000 | J12: 5705000 | K12: 6297000 | L12: 7180000 | M12: 8024000 | N12: =M12*(1+N13) -> 9059096 | O12: =N12*(1+O13) -> 10191483 | P12: =O12*(1+P13) -> 11465418 | Q12: =P12*(1+Q13) -> 12623426 | R12: =Q12*(1+R13) -> 14213977
C13: Growth (%) | G13: =IFERROR(G12/F12-1,"N/A") -> N/A | H13: =IFERROR(H12/G12-1,"N/A") -> -0.0080312568 | I13: =IFERROR(I12/H12-1,"N/A") -> 0.11115974 | J13: =IFERROR(J12/I12-1,"N/A") -> 0.12347381 | K13: =IFERROR(K12/J12-1,"N/A") -> 0.10376862 | L13: =IFERROR(L12/K12-1,"N/A") -> 0.1402255 | M13: =IFERROR(M12/L12-1,"N/A") -> 0.11754875 | N13: 0.129 | O13: 0.125 | P13: 0.125 | Q13: 0.101 | R13: 0.126
C15: Expenses:
C16: COGS – % of Sales (%) | G16: =IFERROR(G17/G12,"N/A") -> 0.36305622 | H16: =IFERROR(H17/H12,"N/A") -> 0.33715536 | I16: =IFERROR(I17/I12,"N/A") -> 0.3551792 | J16: =IFERROR(J17/J12,"N/A") -> 0.36394391 | K16: =IFERROR(K17/K12,"N/A") -> 0.3476735 | L16: =IFERROR(L17/L12,"N/A") -> 0.37551532 | M16: =IFERROR(M17/M12,"N/A") -> 0.37452642 | N16: 0.3655 | O16: 0.3616 | P16: 0.3501 | Q16: 0.3537 | R16: 0.3504
C17: COGS (LCA) | G17: 1672600 | H17: 1540800 | I17: 1803600 | J17: 2076300 | K17: 2189300 | L17: 2696200 | M17: 3005200 | N17: =N16*N12 -> 3311099.6 | O17: =O16*O12 -> 3685240.3 | P17: =P16*P12 -> 4014043 | Q17: =Q16*Q12 -> 4464905.6 | R17: =R16*R12 -> 4980577.6
C18: Payroll – % of Sales (%) | G18: =IFERROR(G19/G12,"N/A") -> 0.22821793 | H18: =IFERROR(H19/H12,"N/A") -> 0.23098468 | I18: =IFERROR(I19/I12,"N/A") -> 0.24202442 | J18: =IFERROR(J19/J12,"N/A") -> 0.23162138 | K18: =IFERROR(K19/K12,"N/A") -> 0.25202477 | L18: =IFERROR(L19/L12,"N/A") -> 0.24151811 | M18: =IFERROR(M19/M12,"N/A") -> 0.25021186 | N18: 0.237 | O18: 0.2358 | P18: 0.2422 | Q18: 0.2363 | R18: 0.2339
C19: Payroll (LCA) | G19: 1051400 | H19: 1055600 | I19: 1229000 | J19: 1321400 | K19: 1587000 | L19: 1734100 | M19: 2007700 | N19: =N18*N12 -> 2147005.8 | O19: =O18*O12 -> 2403151.7 | P19: =P18*P12 -> 2776924.3 | Q19: =Q18*Q12 -> 2982915.5 | R19: =R18*R12 -> 3324649.3
C20: OPEX – % of Sales (%) | G20: =IFERROR(G21/G12,"N/A") -> 0.10692425 | H20: =IFERROR(H21/H12,"N/A") -> 0.11207877 | I20: =IFERROR(I21/I12,"N/A") -> 0.10748326 | J20: =IFERROR(J21/J12,"N/A") -> 0.11905346 | K20: =IFERROR(K21/K12,"N/A") -> 0.113165 | L20: =IFERROR(L21/L12,"N/A") -> 0.10857939 | M20: =IFERROR(M21/M12,"N/A") -> 0.10595713 | N20: 0.1071 | O20: 0.1074 | P20: 0.1112 | Q20: 0.1105 | R20: 0.1076
C21: OPEX (LCA) | G21: 492600 | H21: 512200 | I21: 545800 | J21: 679200 | K21: 712600 | L21: 779600 | M21: 850200 | N21: =N20*N12 -> 970229.18 | O21: =O20*O12 -> 1094565.3 | P21: =P20*P12 -> 1274954.5 | Q21: =Q20*Q12 -> 1394888.5 | R21: =R20*R12 -> 1529424
C22: Provision – % of Sales (%) | G22: =IFERROR(G23/G12,"N/A") -> 0.0082266117 | H22: =IFERROR(H23/H12,"N/A") -> 0.0084901532 | I22: =IFERROR(I23/I12,"N/A") -> 0.0076211107 | J22: =IFERROR(J23/J12,"N/A") -> 0.0083260298 | K22: =IFERROR(K23/K12,"N/A") -> 0.0077338415 | L22: =IFERROR(L23/L12,"N/A") -> 0.0080640669 | M22: =IFERROR(M23/M12,"N/A") -> 0.0077642074 | N22: 0.0081 | O22: 0.0079 | P22: 0.0078 | Q22: 0.0081 | R22: 0.0078
C23: Provision (LCA) | G23: 37900 | H23: 38800 | I23: 38700 | J23: 47500 | K23: 48700 | L23: 57900 | M23: 62300 | N23: =N22*N12 -> 73378.678 | O23: =O22*O12 -> 80512.716 | P23: =P22*P12 -> 89430.263 | Q23: =Q22*Q12 -> 102249.75 | R23: =R22*R12 -> 110869.02
C24: Depreciation & Amortization – % of Sales (%) | G24: =IFERROR(G25/G12,"N/A") -> 0.052637291 | H24: =IFERROR(H25/H12,"N/A") -> 0.057833698 | I24: =IFERROR(I25/I12,"N/A") -> 0.054430878 | J24: =IFERROR(J25/J12,"N/A") -> 0.052988606 | K24: =IFERROR(K25/K12,"N/A") -> 0.051993013 | L24: =IFERROR(L25/L12,"N/A") -> 0.056114206 | M24: =IFERROR(M25/M12,"N/A") -> 0.055358923 | N24: 0.0541 | O24: 0.056 | P24: 0.0546 | Q24: 0.0541 | R24: 0.0546
C25: Depreciation & Amortization (LCA) | G25: 242500 | H25: 264300 | I25: 276400 | J25: 302300 | K25: 327400 | L25: 402900 | M25: 444200 | N25: =N24*N12 -> 490097.09 | O25: =O24*O12 -> 570723.05 | P25: =P24*P12 -> 626011.84 | Q25: =Q24*Q12 -> 682927.33 | R25: =R24*R12 -> 776083.16
C26: Goodwill, Trademark & PPA Amortization – % of Sales (%) | G26: =IFERROR(G27/G12,"N/A") -> 0 | H26: =IFERROR(H27/H12,"N/A") -> 0 | I26: =IFERROR(I27/I12,"N/A") -> 0 | J26: =IFERROR(J27/J12,"N/A") -> 0 | K26: =IFERROR(K27/K12,"N/A") -> 0 | L26: =IFERROR(L27/L12,"N/A") -> 0 | M26: =IFERROR(M27/M12,"N/A") -> 0 | N26: 0 | O26: 0 | P26: 0 | Q26: 0 | R26: 0
C27: Goodwill, Trademark & PPA Amortization (LCA) | G27: 0 | H27: 0 | I27: 0 | J27: 0 | K27: 0 | L27: 0 | M27: 0 | N27: =N26*N12 -> 0 | O27: =O26*O12 -> 0 | P27: =P26*P12 -> 0 | Q27: =Q26*Q12 -> 0 | R27: =R26*R12 -> 0
C29: Financial Statements
C30: B | D30: Income Statement
E31: ="("&Control!$E$18&" in Actual)" -> (USD in Actual)
C32: Revenue | G32: =G12*Control!$E$17 -> 1082645 | H32: =H12*Control!$E$17 -> 1073950 | I32: =I12*Control!$E$17 -> 1193330 | J32: =J12*Control!$E$17 -> 1340675 | K32: =K12*Control!$E$17 -> 1479795 | L32: =L12*Control!$E$17 -> 1687300 | M32: =M12*Control!$E$17 -> 1885640 | N32: =N12*Control!$E$17 -> 2128887.6 | ... R32: =R12*Control!$E$17 -> 3340284.7
C33: Growth (%) | G33: =IFERROR(G32/F32-1,"N/A") -> N/A | H33: =IFERROR(H32/G32-1,"N/A") -> -0.0080312568 | I33: =IFERROR(I32/H32-1,"N/A") -> 0.11115974 | J33: =IFERROR(J32/I32-1,"N/A") -> 0.12347381 | K33: =IFERROR(K32/J32-1,"N/A") -> 0.10376862 | L33: =IFERROR(L32/K32-1,"N/A") -> 0.1402255 | M33: =IFERROR(M32/L32-1,"N/A") -> 0.11754875 | N33: =IFERROR(N32/M32-1,"N/A") -> 0.129 | ... R33: =IFERROR(R32/Q32-1,"N/A") -> 0.126
C34: (-) COGS | G34: =-G17*Control!$E$17 -> -393061 | H34: =-H17*Control!$E$17 -> -362088 | I34: =-I17*Control!$E$17 -> -423846 | J34: =-J17*Control!$E$17 -> -487930.5 | K34: =-K17*Control!$E$17 -> -514485.5 | L34: =-L17*Control!$E$17 -> -633607 | M34: =-M17*Control!$E$17 -> -706222 | N34: =-N17*Control!$E$17 -> -778108.4 | ... R34: =-R17*Control!$E$17 -> -1170435.7
C35: Gross Margin | G35: =G32+G34 -> 689584 | H35: =H32+H34 -> 711862 | I35: =I32+I34 -> 769484 | J35: =J32+J34 -> 852744.5 | K35: =K32+K34 -> 965309.5 | L35: =L32+L34 -> 1053693 | M35: =M32+M34 -> 1179418 | N35: =N32+N34 -> 1350779.2 | ... R35: =R32+R34 -> 2169848.9
C36: Margin (%) | G36: =IFERROR(G35/G$32,"N/A") -> 0.63694378 | H36: =IFERROR(H35/H$32,"N/A") -> 0.66284464 | I36: =IFERROR(I35/I$32,"N/A") -> 0.6448208 | J36: =IFERROR(J35/J$32,"N/A") -> 0.63605609 | K36: =IFERROR(K35/K$32,"N/A") -> 0.6523265 | L36: =IFERROR(L35/L$32,"N/A") -> 0.62448468 | M36: =IFERROR(M35/M$32,"N/A") -> 0.62547358 | N36: =IFERROR(N35/N$32,"N/A") -> 0.6345 | ... R36: =IFERROR(R35/R$32,"N/A") -> 0.6496
C37: (-) Payroll | G37: =-G19*Control!$E$17 -> -247079 | H37: =-H19*Control!$E$17 -> -248066 | I37: =-I19*Control!$E$17 -> -288815 | J37: =-J19*Control!$E$17 -> -310529 | K37: =-K19*Control!$E$17 -> -372945 | L37: =-L19*Control!$E$17 -> -407513.5 | M37: =-M19*Control!$E$17 -> -471809.5 | N37: =-N19*Control!$E$17 -> -504546.35 | ... R37: =-R19*Control!$E$17 -> -781292.58
C38: (-) OPEX | G38: =-G21*Control!$E$17 -> -115761 | H38: =-H21*Control!$E$17 -> -120367 | I38: =-I21*Control!$E$17 -> -128263 | J38: =-J21*Control!$E$17 -> -159612 | K38: =-K21*Control!$E$17 -> -167461 | L38: =-L21*Control!$E$17 -> -183206 | M38: =-M21*Control!$E$17 -> -199797 | N38: =-N21*Control!$E$17 -> -228003.86 | ... R38: =-R21*Control!$E$17 -> -359414.63
C39: (-) Provision | G39: =-G23*Control!$E$17 -> -8906.5 | H39: =-H23*Control!$E$17 -> -9118 | I39: =-I23*Control!$E$17 -> -9094.5 | J39: =-J23*Control!$E$17 -> -11162.5 | K39: =-K23*Control!$E$17 -> -11444.5 | L39: =-L23*Control!$E$17 -> -13606.5 | M39: =-M23*Control!$E$17 -> -14640.5 | N39: =-N23*Control!$E$17 -> -17243.989 | ... R39: =-R23*Control!$E$17 -> -26054.22
C40: EBITDA | G40: =G35+G37+G38+G39 -> 317837.5 | H40: =H35+H37+H38+H39 -> 334311 | I40: =I35+I37+I38+I39 -> 343311.5 | J40: =J35+J37+J38+J39 -> 371441 | K40: =K35+K37+K38+K39 -> 413459 | L40: =L35+L37+L38+L39 -> 449367 | M40: =M35+M37+M38+M39 -> 493171 | N40: =N35+N37+N38+N39 -> 600984.96 | ... R40: =R35+R37+R38+R39 -> 1003087.5
C41: Margin (%) | G41: =IFERROR(G40/G$32,"N/A") -> 0.29357499 | H41: =IFERROR(H40/H$32,"N/A") -> 0.31129103 | I41: =IFERROR(I40/I$32,"N/A") -> 0.287692 | J41: =IFERROR(J40/J$32,"N/A") -> 0.27705521 | K41: =IFERROR(K40/K$32,"N/A") -> 0.27940289 | L41: =IFERROR(L40/L$32,"N/A") -> 0.26632312 | M41: =IFERROR(M40/M$32,"N/A") -> 0.26154038 | N41: =IFERROR(N40/N$32,"N/A") -> 0.2823 | ... R41: =IFERROR(R40/R$32,"N/A") -> 0.3003
C42: (-) D&A | G42: =-G25*Control!$E$17 -> -56987.5 | H42: =-H25*Control!$E$17 -> -62110.5 | I42: =-I25*Control!$E$17 -> -64954 | J42: =-J25*Control!$E$17 -> -71040.5 | K42: =-K25*Control!$E$17 -> -76939 | L42: =-L25*Control!$E$17 -> -94681.5 | M42: =-M25*Control!$E$17 -> -104387 | N42: =-N25*Control!$E$17 -> -115172.82 | ... R42: =-R25*Control!$E$17 -> -182379.54
C43: (-) Goodwill, Trademark & PPA Amortization | G43: =-G27*Control!$E$17 -> 0 | H43: =-H27*Control!$E$17 -> 0 | I43: =-I27*Control!$E$17 -> 0 | J43: =-J27*Control!$E$17 -> 0 | K43: =-K27*Control!$E$17 -> 0 | L43: =-L27*Control!$E$17 -> 0 | M43: =-M27*Control!$E$17 -> 0 | N43: =-N27*Control!$E$17 -> 0 | ... R43: =-R27*Control!$E$17 -> 0
C44: EBIT | G44: =G40+G42+G43 -> 260850 | H44: =H40+H42+H43 -> 272200.5 | I44: =I40+I42+I43 -> 278357.5 | J44: =J40+J42+J43 -> 300400.5 | K44: =K40+K42+K43 -> 336520 | L44: =L40+L42+L43 -> 354685.5 | M44: =M40+M42+M43 -> 388784 | N44: =N40+N42+N43 -> 485812.14 | ... R44: =R40+R42+R43 -> 820707.94
C45: Margin (%) | G45: =IFERROR(G44/G$32,"N/A") -> 0.2409377 | H45: =IFERROR(H44/H$32,"N/A") -> 0.25345733 | I45: =IFERROR(I44/I$32,"N/A") -> 0.23326113 | J45: =IFERROR(J44/J$32,"N/A") -> 0.22406661 | K45: =IFERROR(K44/K$32,"N/A") -> 0.22740988 | L45: =IFERROR(L44/L$32,"N/A") -> 0.21020891 | M45: =IFERROR(M44/M$32,"N/A") -> 0.20618146 | N45: =IFERROR(N44/N$32,"N/A") -> 0.2282 | ... R45: =IFERROR(R44/R$32,"N/A") -> 0.2457

Sheet 6. AHG (Combined Entity)
C3: =Cover!$C$3 -> Project Dunecrest | D3: Confidential
C4: Arvenna Health Group – Combined Entity (USD)
C6: Fiscal Year Ending | G6: 43830 | H6: 44196 | I6: 44561 | J6: 44926 | K6: =EOMONTH(J6,12) -> 45291 | L6: =EOMONTH(K6,12) -> 45657 | M6: =EOMONTH(L6,12) -> 46022 | N6: =EOMONTH(M6,12) -> 46387 | O6: =EOMONTH(N6,12) -> 46752 | P6: =EOMONTH(O6,12) -> 47118 | Q6: =EOMONTH(P6,12) -> 47483 | R6: =EOMONTH(Q6,12) -> 47848
C7: Fiscal Year | G7: =YEAR(G6) -> 2019 | H7: =YEAR(H6) -> 2020 | I7: =YEAR(I6) -> 2021 | J7: =YEAR(J6) -> 2022 | K7: =YEAR(K6) -> 2023 | L7: =YEAR(L6) -> 2024 | M7: =YEAR(M6) -> 2025 | N7: =YEAR(N6) -> 2026 | ... R7: =YEAR(R6) -> 2030
C8: Actual / Estimate | G8: =IF(G6<=Control!$E$11,"A","E") -> A | H8: =IF(H6<=Control!$E$11,"A","E") -> A | I8: =IF(I6<=Control!$E$11,"A","E") -> A | J8: =IF(J6<=Control!$E$11,"A","E") -> A | K8: =IF(K6<=Control!$E$11,"A","E") -> A | L8: =IF(L6<=Control!$E$11,"A","E") -> A | M8: =IF(M6<=Control!$E$11,"A","E") -> A | N8: =IF(N6<=Control!$E$11,"A","E") -> E | ... R8: =IF(R6<=Control!$E$11,"A","E") -> E
C10: Supporting Assumptions
C11: A | D11: Supporting Assumptions | E11: ="("&Control!$E$18&" in Actual)" -> (USD in Actual)
C12: Tax Rate (%) | G12: 0.211 | H12: 0.23 | I12: 0.219 | J12: 0.234 | K12: 0.228 | L12: 0.221 | M12: 0.228 | N12: 0.225 | O12: 0.225 | P12: 0.225 | Q12: 0.225 | R12: 0.225
C13: Non-Current Assets:
C14: Goodwill – % of Gross Goodwill Amortised / Impaired (%) | G14: N/A | H14: =IFERROR(-H216/G228,"N/A") -> 0.013962364 | I14: =IFERROR(-I216/H228,"N/A") -> 0.016597192 | J14: =IFERROR(-J216/I228,"N/A") -> 0.017893026 | K14: =IFERROR(-K216/J228,"N/A") -> 0.020468365 | L14: =IFERROR(-L216/K228,"N/A") -> 0.022056027 | M14: =IFERROR(-M216/L228,"N/A") -> 0.025866906 | N14: =IFERROR(-N216/M228,"N/A") -> 0.028745314 | O14: =IFERROR(-O216/N228,"N/A") -> 0.032220595 | ... R14: =IFERROR(-R216/Q228,"N/A") -> 0.014807205
C15: Goodwill – Accumulated Provisions (memo) | G15: =G229 -> -700000 | H15: =H229 -> -940000 | I15: =I229 -> -1140000 | J15: =J229 -> -1422000 | K15: =K229 -> -1586000 | L15: =L229 -> -1853000 | M15: =M229 -> -2067000 | N15: =N229 -> -2344018.6 | ... R15: =R229 -> -3807334.3
C16: Intangible Assets – Growth (%) | G16: N/A | H16: =IFERROR(H231/G231-1,"N/A") -> 0.088867501 | I16: =IFERROR(I231/H231-1,"N/A") -> 0.016499705 | J16: =IFERROR(J231/I231-1,"N/A") -> 0.069855072 | K16: =IFERROR(K231/J231-1,"N/A") -> 0.050934706 | L16: =IFERROR(L231/K231-1,"N/A") -> 0.025006445 | M16: =IFERROR(M231/L231-1,"N/A") -> 0.048038229 | N16: 0.02 | O16: 0.02 | P16: 0.02 | Q16: 0.02 | R16: 0.02
C17: Intangible Assets – % of Gross Depreciated (%) | G17: N/A | H17: =IFERROR(-(H232-G232)/G231,"N/A") -> 0.061918511 | I17: =IFERROR(-(I232-H232)/H231,"N/A") -> 0.034472599 | J17: =IFERROR(-(J232-I232)/I231,"N/A") -> 0.062028986 | K17: =IFERROR(-(K232-J232)/J231,"N/A") -> 0.04199404 | L17: =IFERROR(-(L232-K232)/K231,"N/A") -> 0.033513792 | M17: =IFERROR(-(M232-L232)/L231,"N/A") -> 0.054074447 | N17: 0.08 | O17: 0.08 | P17: 0.08 | Q17: 0.08 | R17: 0.08
C18: Intangible Assets – Accumulated Depreciation (memo) | G18: =G232 -> -881000 | H18: =H232 -> -1074000 | I18: =I232 -> -1191000 | J18: =J232 -> -1405000 | K18: =K232 -> -1560000 | L18: =L232 -> -1690000 | M18: =M232 -> -1905000 | N18: =N232 -> -2238360 | ... R18: =R232 -> -3639818.8
